2025-07-23 00:26:47,372 - outbound-caller - INFO - Outbound Agent script démarre, args: ['C:\\Users\\y.djemai\\pam-testdrive\\MARK_I\\backend_python\\agents\\outbound_agent.py', 'start']
2025-07-23 00:26:47,372 - outbound-caller - INFO - Python version: 3.12.3 (tags/v3.12.3:f6650f9, Apr  9 2024, 14:05:25) [MSC v.1938 64 bit (AMD64)]
2025-07-23 00:26:47,372 - outbound-caller - INFO - Répertoire courant: C:\Users\y.djemai\pam-testdrive\MARK_I\backend_python\agents
2025-07-23 00:26:47,372 - outbound-caller - INFO - Encodage par défaut: utf-8
2025-07-23 00:26:47,372 - outbound-caller - INFO - Locale système: ('fr_FR', 'UTF-8')
2025-07-23 00:26:47,377 - outbound-caller - INFO - PATIENT_NAME: Jayden
2025-07-23 00:26:47,377 - outbound-caller - INFO - APPOINTMENT_TIME: next Tuesday at 3pm
2025-07-23 00:26:47,377 - outbound-caller - INFO - LK_ROOM_NAME: agent-call-294
2025-07-23 00:26:47,377 - outbound-caller - INFO - LK_JOB_METADATA: {"firstName": "Valued Customer", "lastName": "", "dial_info": {"agent_id": 11, "call_direction": "outbound", "room_name": "agent-call-294", "supabase_call_id": 294, "telnyx_call_control_id": null, "default_pathway_id": "d5fc510b-7635-4715-9066-e522daa2336d", "user_id": "b55837c4-270f-4f1f-8023-7ab09ee5f44d", "phone_number": "+33661329235", "sip_trunk_id": "ST_6CYLZwTLMCe2", "agent_caller_id_number": "+33189311209"}, "system_prompt": null, "initial_greeting": null, "wait_for_greeting": false, "pam_tier": "core", "interruption_threshold": 100, "ai_models": {"vad": {"provider": "silero"}, "stt": {"provider": "deepgram", "language": "en", "model": "nova-2"}, "tts": {"provider": "cartesia", "model": "sonic-2", "voice_id": "f9836c6e-a0bd-460e-9d3c-f7299fa60f94"}, "llm": {"provider": "openai", "model": "gpt-4o-mini"}}}
2025-07-23 00:26:47,377 - outbound-caller - INFO - LIVEKIT_URL: wss://pamtestdrive-euxn3osq.livekit.cloud
2025-07-23 00:26:47,377 - outbound-caller - INFO - LIVEKIT_API_KEY présent: Oui
App actions not available: No module named 'cryptography'
API modules not available: attempted relative import with no known parent package
2025-07-23 00:26:49,313 - outbound-caller - INFO - Pathway integration loaded successfully
2025-07-23 00:26:49,313 - root - INFO - Starting LiveKit Worker 'outbound-caller' on port 53153
2025-07-23 00:26:49,320 - livekit.agents - INFO - starting worker
2025-07-23 00:26:49,336 - livekit.agents - INFO - initializing job runner
2025-07-23 00:26:49,336 - livekit.agents - INFO - initializing job runner
2025-07-23 00:26:49,337 - livekit.agents - INFO - initializing job runner
2025-07-23 00:26:49,337 - livekit.agents - INFO - initializing job runner
2025-07-23 00:26:49,338 - livekit.agents - INFO - initializing job runner
2025-07-23 00:26:49,338 - livekit.agents - INFO - initializing job runner
2025-07-23 00:26:49,338 - livekit.agents - INFO - initializing job runner
2025-07-23 00:26:49,338 - livekit.agents - INFO - initializing job runner
2025-07-23 00:26:49,338 - livekit.agents - INFO - initializing job runner
2025-07-23 00:26:49,339 - livekit.agents - INFO - initializing job runner
2025-07-23 00:26:49,339 - livekit.agents - INFO - initializing job runner
2025-07-23 00:26:49,339 - livekit.agents - INFO - initializing job runner
2025-07-23 00:26:49,354 - livekit.agents - INFO - job runner initialized
2025-07-23 00:26:49,355 - livekit.agents - INFO - job runner initialized
2025-07-23 00:26:49,356 - livekit.agents - INFO - job runner initialized
2025-07-23 00:26:49,356 - livekit.agents - INFO - job runner initialized
2025-07-23 00:26:49,356 - livekit.agents - INFO - job runner initialized
2025-07-23 00:26:49,357 - livekit.agents - INFO - job runner initialized
2025-07-23 00:26:49,357 - livekit.agents - INFO - job runner initialized
2025-07-23 00:26:49,357 - livekit.agents - INFO - job runner initialized
2025-07-23 00:26:49,357 - livekit.agents - INFO - job runner initialized
2025-07-23 00:26:49,358 - livekit.agents - INFO - job runner initialized
2025-07-23 00:26:49,358 - livekit.agents - INFO - job runner initialized
2025-07-23 00:26:49,358 - livekit.agents - INFO - job runner initialized
2025-07-23 00:26:49,358 - livekit.agents - INFO - see tracing information at http://localhost:53153/debug
2025-07-23 00:26:49,459 - livekit.agents - INFO - registered worker
2025-07-23 01:13:16,804 - livekit.agents - WARNING - failed to connect to livekit, retrying in 0s
Traceback (most recent call last):
  File "C:\Users\y.djemai\pam-testdrive\MARK_I\backend_python\agents\venv\Lib\site-packages\livekit\agents\worker.py", line 692, in _connection_task
    await self._run_ws(ws)
  File "C:\Users\y.djemai\pam-testdrive\MARK_I\backend_python\agents\venv\Lib\site-packages\livekit\agents\worker.py", line 773, in _run_ws
    await asyncio.gather(*tasks)
  File "C:\Users\y.djemai\pam-testdrive\MARK_I\backend_python\agents\venv\Lib\site-packages\livekit\agents\worker.py", line 736, in _recv_task
    msg = await ws.receive()
          ^^^^^^^^^^^^^^^^^^
  File "C:\Users\y.djemai\pam-testdrive\MARK_I\backend_python\agents\venv\Lib\site-packages\aiohttp\client_ws.py", line 378, in receive
    await self.pong(msg.data)
  File "C:\Users\y.djemai\pam-testdrive\MARK_I\backend_python\agents\venv\Lib\site-packages\aiohttp\client_ws.py", line 234, in pong
    await self._writer.send_frame(message, WSMsgType.PONG)
  File "C:\Users\y.djemai\pam-testdrive\MARK_I\backend_python\agents\venv\Lib\site-packages\aiohttp\_websocket\writer.py", line 126, in send_frame
    raise ClientConnectionResetError("Cannot write to closing transport")
aiohttp.client_exceptions.ClientConnectionResetError: Cannot write to closing transport
2025-07-23 01:13:16,985 - livekit.agents - WARNING - failed to connect to livekit, retrying in 2s
Traceback (most recent call last):
  File "C:\Users\y.djemai\pam-testdrive\MARK_I\backend_python\agents\venv\Lib\site-packages\aiohttp\connector.py", line 1532, in _create_direct_connection
    hosts = await self._resolve_host(host, port, traces=traces)
            ^^^^^^^^^^^^^^^^^^^^^^^^^^^^^^^^^^^^^^^^^^^^^^^^^^^
  File "C:\Users\y.djemai\pam-testdrive\MARK_I\backend_python\agents\venv\Lib\site-packages\aiohttp\connector.py", line 1148, in _resolve_host
    return await asyncio.shield(resolved_host_task)
           ^^^^^^^^^^^^^^^^^^^^^^^^^^^^^^^^^^^^^^^^
  File "C:\Users\y.djemai\pam-testdrive\MARK_I\backend_python\agents\venv\Lib\site-packages\aiohttp\connector.py", line 1179, in _resolve_host_with_throttle
    addrs = await self._resolver.resolve(host, port, family=self._family)
            ^^^^^^^^^^^^^^^^^^^^^^^^^^^^^^^^^^^^^^^^^^^^^^^^^^^^^^^^^^^^^
  File "C:\Users\y.djemai\pam-testdrive\MARK_I\backend_python\agents\venv\Lib\site-packages\aiohttp\resolver.py", line 40, in resolve
    infos = await self._loop.getaddrinfo(
            ^^^^^^^^^^^^^^^^^^^^^^^^^^^^^
  File "C:\Program Files\Python312\Lib\asyncio\base_events.py", line 901, in getaddrinfo
    return await self.run_in_executor(
           ^^^^^^^^^^^^^^^^^^^^^^^^^^^
  File "C:\Program Files\Python312\Lib\concurrent\futures\thread.py", line 58, in run
    result = self.fn(*self.args, **self.kwargs)
             ^^^^^^^^^^^^^^^^^^^^^^^^^^^^^^^^^^
  File "C:\Program Files\Python312\Lib\socket.py", line 963, in getaddrinfo
    for res in _socket.getaddrinfo(host, port, family, type, proto, flags):
               ^^^^^^^^^^^^^^^^^^^^^^^^^^^^^^^^^^^^^^^^^^^^^^^^^^^^^^^^^^^
socket.gaierror: [Errno 11001] getaddrinfo failed

The above exception was the direct cause of the following exception:

Traceback (most recent call last):
  File "C:\Users\y.djemai\pam-testdrive\MARK_I\backend_python\agents\venv\Lib\site-packages\livekit\agents\worker.py", line 653, in _connection_task
    ws = await self._http_session.ws_connect(
         ^^^^^^^^^^^^^^^^^^^^^^^^^^^^^^^^^^^^
  File "C:\Users\y.djemai\pam-testdrive\MARK_I\backend_python\agents\venv\Lib\site-packages\aiohttp\client.py", line 1067, in _ws_connect
    resp = await self.request(
           ^^^^^^^^^^^^^^^^^^^
  File "C:\Users\y.djemai\pam-testdrive\MARK_I\backend_python\agents\venv\Lib\site-packages\aiohttp\client.py", line 770, in _request
    resp = await handler(req)
           ^^^^^^^^^^^^^^^^^^
  File "C:\Users\y.djemai\pam-testdrive\MARK_I\backend_python\agents\venv\Lib\site-packages\aiohttp\client.py", line 725, in _connect_and_send_request
    conn = await self._connector.connect(
           ^^^^^^^^^^^^^^^^^^^^^^^^^^^^^^
  File "C:\Users\y.djemai\pam-testdrive\MARK_I\backend_python\agents\venv\Lib\site-packages\aiohttp\connector.py", line 642, in connect
    proto = await self._create_connection(req, traces, timeout)
            ^^^^^^^^^^^^^^^^^^^^^^^^^^^^^^^^^^^^^^^^^^^^^^^^^^^
  File "C:\Users\y.djemai\pam-testdrive\MARK_I\backend_python\agents\venv\Lib\site-packages\aiohttp\connector.py", line 1209, in _create_connection
    _, proto = await self._create_direct_connection(req, traces, timeout)
               ^^^^^^^^^^^^^^^^^^^^^^^^^^^^^^^^^^^^^^^^^^^^^^^^^^^^^^^^^^
  File "C:\Users\y.djemai\pam-testdrive\MARK_I\backend_python\agents\venv\Lib\site-packages\aiohttp\connector.py", line 1538, in _create_direct_connection
    raise ClientConnectorDNSError(req.connection_key, exc) from exc
aiohttp.client_exceptions.ClientConnectorDNSError: Cannot connect to host pamtestdrive-euxn3osq.livekit.cloud:443 ssl:default [getaddrinfo failed]
2025-07-23 01:13:19,030 - livekit.agents - WARNING - failed to connect to livekit, retrying in 4s
Traceback (most recent call last):
  File "C:\Users\y.djemai\pam-testdrive\MARK_I\backend_python\agents\venv\Lib\site-packages\aiohttp\connector.py", line 1532, in _create_direct_connection
    hosts = await self._resolve_host(host, port, traces=traces)
            ^^^^^^^^^^^^^^^^^^^^^^^^^^^^^^^^^^^^^^^^^^^^^^^^^^^
  File "C:\Users\y.djemai\pam-testdrive\MARK_I\backend_python\agents\venv\Lib\site-packages\aiohttp\connector.py", line 1148, in _resolve_host
    return await asyncio.shield(resolved_host_task)
           ^^^^^^^^^^^^^^^^^^^^^^^^^^^^^^^^^^^^^^^^
  File "C:\Users\y.djemai\pam-testdrive\MARK_I\backend_python\agents\venv\Lib\site-packages\aiohttp\connector.py", line 1179, in _resolve_host_with_throttle
    addrs = await self._resolver.resolve(host, port, family=self._family)
            ^^^^^^^^^^^^^^^^^^^^^^^^^^^^^^^^^^^^^^^^^^^^^^^^^^^^^^^^^^^^^
  File "C:\Users\y.djemai\pam-testdrive\MARK_I\backend_python\agents\venv\Lib\site-packages\aiohttp\resolver.py", line 40, in resolve
    infos = await self._loop.getaddrinfo(
            ^^^^^^^^^^^^^^^^^^^^^^^^^^^^^
  File "C:\Program Files\Python312\Lib\asyncio\base_events.py", line 901, in getaddrinfo
    return await self.run_in_executor(
           ^^^^^^^^^^^^^^^^^^^^^^^^^^^
  File "C:\Program Files\Python312\Lib\concurrent\futures\thread.py", line 58, in run
    result = self.fn(*self.args, **self.kwargs)
             ^^^^^^^^^^^^^^^^^^^^^^^^^^^^^^^^^^
  File "C:\Program Files\Python312\Lib\socket.py", line 963, in getaddrinfo
    for res in _socket.getaddrinfo(host, port, family, type, proto, flags):
               ^^^^^^^^^^^^^^^^^^^^^^^^^^^^^^^^^^^^^^^^^^^^^^^^^^^^^^^^^^^
socket.gaierror: [Errno 11001] getaddrinfo failed

The above exception was the direct cause of the following exception:

Traceback (most recent call last):
  File "C:\Users\y.djemai\pam-testdrive\MARK_I\backend_python\agents\venv\Lib\site-packages\livekit\agents\worker.py", line 653, in _connection_task
    ws = await self._http_session.ws_connect(
         ^^^^^^^^^^^^^^^^^^^^^^^^^^^^^^^^^^^^
  File "C:\Users\y.djemai\pam-testdrive\MARK_I\backend_python\agents\venv\Lib\site-packages\aiohttp\client.py", line 1067, in _ws_connect
    resp = await self.request(
           ^^^^^^^^^^^^^^^^^^^
  File "C:\Users\y.djemai\pam-testdrive\MARK_I\backend_python\agents\venv\Lib\site-packages\aiohttp\client.py", line 770, in _request
    resp = await handler(req)
           ^^^^^^^^^^^^^^^^^^
  File "C:\Users\y.djemai\pam-testdrive\MARK_I\backend_python\agents\venv\Lib\site-packages\aiohttp\client.py", line 725, in _connect_and_send_request
    conn = await self._connector.connect(
           ^^^^^^^^^^^^^^^^^^^^^^^^^^^^^^
  File "C:\Users\y.djemai\pam-testdrive\MARK_I\backend_python\agents\venv\Lib\site-packages\aiohttp\connector.py", line 642, in connect
    proto = await self._create_connection(req, traces, timeout)
            ^^^^^^^^^^^^^^^^^^^^^^^^^^^^^^^^^^^^^^^^^^^^^^^^^^^
  File "C:\Users\y.djemai\pam-testdrive\MARK_I\backend_python\agents\venv\Lib\site-packages\aiohttp\connector.py", line 1209, in _create_connection
    _, proto = await self._create_direct_connection(req, traces, timeout)
               ^^^^^^^^^^^^^^^^^^^^^^^^^^^^^^^^^^^^^^^^^^^^^^^^^^^^^^^^^^
  File "C:\Users\y.djemai\pam-testdrive\MARK_I\backend_python\agents\venv\Lib\site-packages\aiohttp\connector.py", line 1538, in _create_direct_connection
    raise ClientConnectorDNSError(req.connection_key, exc) from exc
aiohttp.client_exceptions.ClientConnectorDNSError: Cannot connect to host pamtestdrive-euxn3osq.livekit.cloud:443 ssl:default [getaddrinfo failed]
2025-07-23 03:46:00,500 - livekit.agents - WARNING - failed to connect to livekit, retrying in 6s
Traceback (most recent call last):
  File "C:\Users\y.djemai\pam-testdrive\MARK_I\backend_python\agents\venv\Lib\site-packages\aiohttp\connector.py", line 1532, in _create_direct_connection
    hosts = await self._resolve_host(host, port, traces=traces)
            ^^^^^^^^^^^^^^^^^^^^^^^^^^^^^^^^^^^^^^^^^^^^^^^^^^^
  File "C:\Users\y.djemai\pam-testdrive\MARK_I\backend_python\agents\venv\Lib\site-packages\aiohttp\connector.py", line 1148, in _resolve_host
    return await asyncio.shield(resolved_host_task)
           ^^^^^^^^^^^^^^^^^^^^^^^^^^^^^^^^^^^^^^^^
  File "C:\Users\y.djemai\pam-testdrive\MARK_I\backend_python\agents\venv\Lib\site-packages\aiohttp\connector.py", line 1179, in _resolve_host_with_throttle
    addrs = await self._resolver.resolve(host, port, family=self._family)
            ^^^^^^^^^^^^^^^^^^^^^^^^^^^^^^^^^^^^^^^^^^^^^^^^^^^^^^^^^^^^^
  File "C:\Users\y.djemai\pam-testdrive\MARK_I\backend_python\agents\venv\Lib\site-packages\aiohttp\resolver.py", line 40, in resolve
    infos = await self._loop.getaddrinfo(
            ^^^^^^^^^^^^^^^^^^^^^^^^^^^^^
  File "C:\Program Files\Python312\Lib\asyncio\base_events.py", line 901, in getaddrinfo
    return await self.run_in_executor(
           ^^^^^^^^^^^^^^^^^^^^^^^^^^^
  File "C:\Program Files\Python312\Lib\concurrent\futures\thread.py", line 58, in run
    result = self.fn(*self.args, **self.kwargs)
             ^^^^^^^^^^^^^^^^^^^^^^^^^^^^^^^^^^
  File "C:\Program Files\Python312\Lib\socket.py", line 963, in getaddrinfo
    for res in _socket.getaddrinfo(host, port, family, type, proto, flags):
               ^^^^^^^^^^^^^^^^^^^^^^^^^^^^^^^^^^^^^^^^^^^^^^^^^^^^^^^^^^^
socket.gaierror: [Errno 11001] getaddrinfo failed

The above exception was the direct cause of the following exception:

Traceback (most recent call last):
  File "C:\Users\y.djemai\pam-testdrive\MARK_I\backend_python\agents\venv\Lib\site-packages\livekit\agents\worker.py", line 653, in _connection_task
    ws = await self._http_session.ws_connect(
         ^^^^^^^^^^^^^^^^^^^^^^^^^^^^^^^^^^^^
  File "C:\Users\y.djemai\pam-testdrive\MARK_I\backend_python\agents\venv\Lib\site-packages\aiohttp\client.py", line 1067, in _ws_connect
    resp = await self.request(
           ^^^^^^^^^^^^^^^^^^^
  File "C:\Users\y.djemai\pam-testdrive\MARK_I\backend_python\agents\venv\Lib\site-packages\aiohttp\client.py", line 770, in _request
    resp = await handler(req)
           ^^^^^^^^^^^^^^^^^^
  File "C:\Users\y.djemai\pam-testdrive\MARK_I\backend_python\agents\venv\Lib\site-packages\aiohttp\client.py", line 725, in _connect_and_send_request
    conn = await self._connector.connect(
           ^^^^^^^^^^^^^^^^^^^^^^^^^^^^^^
  File "C:\Users\y.djemai\pam-testdrive\MARK_I\backend_python\agents\venv\Lib\site-packages\aiohttp\connector.py", line 642, in connect
    proto = await self._create_connection(req, traces, timeout)
            ^^^^^^^^^^^^^^^^^^^^^^^^^^^^^^^^^^^^^^^^^^^^^^^^^^^
  File "C:\Users\y.djemai\pam-testdrive\MARK_I\backend_python\agents\venv\Lib\site-packages\aiohttp\connector.py", line 1209, in _create_connection
    _, proto = await self._create_direct_connection(req, traces, timeout)
               ^^^^^^^^^^^^^^^^^^^^^^^^^^^^^^^^^^^^^^^^^^^^^^^^^^^^^^^^^^
  File "C:\Users\y.djemai\pam-testdrive\MARK_I\backend_python\agents\venv\Lib\site-packages\aiohttp\connector.py", line 1538, in _create_direct_connection
    raise ClientConnectorDNSError(req.connection_key, exc) from exc
aiohttp.client_exceptions.ClientConnectorDNSError: Cannot connect to host pamtestdrive-euxn3osq.livekit.cloud:443 ssl:default [getaddrinfo failed]
2025-07-23 03:46:07,716 - livekit.agents - INFO - registered worker
2025-07-23 03:46:07,717 - livekit.agents - INFO - worker is at full capacity, marking as unavailable
2025-07-23 03:46:35,258 - livekit.agents - WARNING - failed to connect to livekit, retrying in 0s
Traceback (most recent call last):
  File "C:\Users\y.djemai\pam-testdrive\MARK_I\backend_python\agents\venv\Lib\site-packages\livekit\agents\worker.py", line 692, in _connection_task
    await self._run_ws(ws)
  File "C:\Users\y.djemai\pam-testdrive\MARK_I\backend_python\agents\venv\Lib\site-packages\livekit\agents\worker.py", line 773, in _run_ws
    await asyncio.gather(*tasks)
  File "C:\Users\y.djemai\pam-testdrive\MARK_I\backend_python\agents\venv\Lib\site-packages\livekit\agents\worker.py", line 745, in _recv_task
    raise Exception("worker connection closed unexpectedly")
Exception: worker connection closed unexpectedly
2025-07-23 03:46:35,431 - livekit.agents - WARNING - failed to connect to livekit, retrying in 2s
Traceback (most recent call last):
  File "C:\Users\y.djemai\pam-testdrive\MARK_I\backend_python\agents\venv\Lib\site-packages\aiohttp\connector.py", line 1532, in _create_direct_connection
    hosts = await self._resolve_host(host, port, traces=traces)
            ^^^^^^^^^^^^^^^^^^^^^^^^^^^^^^^^^^^^^^^^^^^^^^^^^^^
  File "C:\Users\y.djemai\pam-testdrive\MARK_I\backend_python\agents\venv\Lib\site-packages\aiohttp\connector.py", line 1148, in _resolve_host
    return await asyncio.shield(resolved_host_task)
           ^^^^^^^^^^^^^^^^^^^^^^^^^^^^^^^^^^^^^^^^
  File "C:\Users\y.djemai\pam-testdrive\MARK_I\backend_python\agents\venv\Lib\site-packages\aiohttp\connector.py", line 1179, in _resolve_host_with_throttle
    addrs = await self._resolver.resolve(host, port, family=self._family)
            ^^^^^^^^^^^^^^^^^^^^^^^^^^^^^^^^^^^^^^^^^^^^^^^^^^^^^^^^^^^^^
  File "C:\Users\y.djemai\pam-testdrive\MARK_I\backend_python\agents\venv\Lib\site-packages\aiohttp\resolver.py", line 40, in resolve
    infos = await self._loop.getaddrinfo(
            ^^^^^^^^^^^^^^^^^^^^^^^^^^^^^
  File "C:\Program Files\Python312\Lib\asyncio\base_events.py", line 901, in getaddrinfo
    return await self.run_in_executor(
           ^^^^^^^^^^^^^^^^^^^^^^^^^^^
  File "C:\Program Files\Python312\Lib\concurrent\futures\thread.py", line 58, in run
    result = self.fn(*self.args, **self.kwargs)
             ^^^^^^^^^^^^^^^^^^^^^^^^^^^^^^^^^^
  File "C:\Program Files\Python312\Lib\socket.py", line 963, in getaddrinfo
    for res in _socket.getaddrinfo(host, port, family, type, proto, flags):
               ^^^^^^^^^^^^^^^^^^^^^^^^^^^^^^^^^^^^^^^^^^^^^^^^^^^^^^^^^^^
socket.gaierror: [Errno 11001] getaddrinfo failed

The above exception was the direct cause of the following exception:

Traceback (most recent call last):
  File "C:\Users\y.djemai\pam-testdrive\MARK_I\backend_python\agents\venv\Lib\site-packages\livekit\agents\worker.py", line 653, in _connection_task
    ws = await self._http_session.ws_connect(
         ^^^^^^^^^^^^^^^^^^^^^^^^^^^^^^^^^^^^
  File "C:\Users\y.djemai\pam-testdrive\MARK_I\backend_python\agents\venv\Lib\site-packages\aiohttp\client.py", line 1067, in _ws_connect
    resp = await self.request(
           ^^^^^^^^^^^^^^^^^^^
  File "C:\Users\y.djemai\pam-testdrive\MARK_I\backend_python\agents\venv\Lib\site-packages\aiohttp\client.py", line 770, in _request
    resp = await handler(req)
           ^^^^^^^^^^^^^^^^^^
  File "C:\Users\y.djemai\pam-testdrive\MARK_I\backend_python\agents\venv\Lib\site-packages\aiohttp\client.py", line 725, in _connect_and_send_request
    conn = await self._connector.connect(
           ^^^^^^^^^^^^^^^^^^^^^^^^^^^^^^
  File "C:\Users\y.djemai\pam-testdrive\MARK_I\backend_python\agents\venv\Lib\site-packages\aiohttp\connector.py", line 642, in connect
    proto = await self._create_connection(req, traces, timeout)
            ^^^^^^^^^^^^^^^^^^^^^^^^^^^^^^^^^^^^^^^^^^^^^^^^^^^
  File "C:\Users\y.djemai\pam-testdrive\MARK_I\backend_python\agents\venv\Lib\site-packages\aiohttp\connector.py", line 1209, in _create_connection
    _, proto = await self._create_direct_connection(req, traces, timeout)
               ^^^^^^^^^^^^^^^^^^^^^^^^^^^^^^^^^^^^^^^^^^^^^^^^^^^^^^^^^^
  File "C:\Users\y.djemai\pam-testdrive\MARK_I\backend_python\agents\venv\Lib\site-packages\aiohttp\connector.py", line 1538, in _create_direct_connection
    raise ClientConnectorDNSError(req.connection_key, exc) from exc
aiohttp.client_exceptions.ClientConnectorDNSError: Cannot connect to host pamtestdrive-euxn3osq.livekit.cloud:443 ssl:default [getaddrinfo failed]
2025-07-23 09:54:43,606 - livekit.agents - WARNING - failed to connect to livekit, retrying in 4s
Traceback (most recent call last):
  File "C:\Users\y.djemai\pam-testdrive\MARK_I\backend_python\agents\venv\Lib\site-packages\aiohttp\connector.py", line 1532, in _create_direct_connection
    hosts = await self._resolve_host(host, port, traces=traces)
            ^^^^^^^^^^^^^^^^^^^^^^^^^^^^^^^^^^^^^^^^^^^^^^^^^^^
  File "C:\Users\y.djemai\pam-testdrive\MARK_I\backend_python\agents\venv\Lib\site-packages\aiohttp\connector.py", line 1148, in _resolve_host
    return await asyncio.shield(resolved_host_task)
           ^^^^^^^^^^^^^^^^^^^^^^^^^^^^^^^^^^^^^^^^
  File "C:\Users\y.djemai\pam-testdrive\MARK_I\backend_python\agents\venv\Lib\site-packages\aiohttp\connector.py", line 1179, in _resolve_host_with_throttle
    addrs = await self._resolver.resolve(host, port, family=self._family)
            ^^^^^^^^^^^^^^^^^^^^^^^^^^^^^^^^^^^^^^^^^^^^^^^^^^^^^^^^^^^^^
  File "C:\Users\y.djemai\pam-testdrive\MARK_I\backend_python\agents\venv\Lib\site-packages\aiohttp\resolver.py", line 40, in resolve
    infos = await self._loop.getaddrinfo(
            ^^^^^^^^^^^^^^^^^^^^^^^^^^^^^
  File "C:\Program Files\Python312\Lib\asyncio\base_events.py", line 901, in getaddrinfo
    return await self.run_in_executor(
           ^^^^^^^^^^^^^^^^^^^^^^^^^^^
  File "C:\Program Files\Python312\Lib\concurrent\futures\thread.py", line 58, in run
    result = self.fn(*self.args, **self.kwargs)
             ^^^^^^^^^^^^^^^^^^^^^^^^^^^^^^^^^^
  File "C:\Program Files\Python312\Lib\socket.py", line 963, in getaddrinfo
    for res in _socket.getaddrinfo(host, port, family, type, proto, flags):
               ^^^^^^^^^^^^^^^^^^^^^^^^^^^^^^^^^^^^^^^^^^^^^^^^^^^^^^^^^^^
socket.gaierror: [Errno 11001] getaddrinfo failed

The above exception was the direct cause of the following exception:

Traceback (most recent call last):
  File "C:\Users\y.djemai\pam-testdrive\MARK_I\backend_python\agents\venv\Lib\site-packages\livekit\agents\worker.py", line 653, in _connection_task
    ws = await self._http_session.ws_connect(
         ^^^^^^^^^^^^^^^^^^^^^^^^^^^^^^^^^^^^
  File "C:\Users\y.djemai\pam-testdrive\MARK_I\backend_python\agents\venv\Lib\site-packages\aiohttp\client.py", line 1067, in _ws_connect
    resp = await self.request(
           ^^^^^^^^^^^^^^^^^^^
  File "C:\Users\y.djemai\pam-testdrive\MARK_I\backend_python\agents\venv\Lib\site-packages\aiohttp\client.py", line 770, in _request
    resp = await handler(req)
           ^^^^^^^^^^^^^^^^^^
  File "C:\Users\y.djemai\pam-testdrive\MARK_I\backend_python\agents\venv\Lib\site-packages\aiohttp\client.py", line 725, in _connect_and_send_request
    conn = await self._connector.connect(
           ^^^^^^^^^^^^^^^^^^^^^^^^^^^^^^
  File "C:\Users\y.djemai\pam-testdrive\MARK_I\backend_python\agents\venv\Lib\site-packages\aiohttp\connector.py", line 642, in connect
    proto = await self._create_connection(req, traces, timeout)
            ^^^^^^^^^^^^^^^^^^^^^^^^^^^^^^^^^^^^^^^^^^^^^^^^^^^
  File "C:\Users\y.djemai\pam-testdrive\MARK_I\backend_python\agents\venv\Lib\site-packages\aiohttp\connector.py", line 1209, in _create_connection
    _, proto = await self._create_direct_connection(req, traces, timeout)
               ^^^^^^^^^^^^^^^^^^^^^^^^^^^^^^^^^^^^^^^^^^^^^^^^^^^^^^^^^^
  File "C:\Users\y.djemai\pam-testdrive\MARK_I\backend_python\agents\venv\Lib\site-packages\aiohttp\connector.py", line 1538, in _create_direct_connection
    raise ClientConnectorDNSError(req.connection_key, exc) from exc
aiohttp.client_exceptions.ClientConnectorDNSError: Cannot connect to host pamtestdrive-euxn3osq.livekit.cloud:443 ssl:default [getaddrinfo failed]
2025-07-23 09:54:48,437 - livekit.agents - WARNING - failed to connect to livekit, retrying in 6s
Traceback (most recent call last):
  File "C:\Users\y.djemai\pam-testdrive\MARK_I\backend_python\agents\venv\Lib\site-packages\aiohttp\connector.py", line 1532, in _create_direct_connection
    hosts = await self._resolve_host(host, port, traces=traces)
            ^^^^^^^^^^^^^^^^^^^^^^^^^^^^^^^^^^^^^^^^^^^^^^^^^^^
  File "C:\Users\y.djemai\pam-testdrive\MARK_I\backend_python\agents\venv\Lib\site-packages\aiohttp\connector.py", line 1148, in _resolve_host
    return await asyncio.shield(resolved_host_task)
           ^^^^^^^^^^^^^^^^^^^^^^^^^^^^^^^^^^^^^^^^
  File "C:\Users\y.djemai\pam-testdrive\MARK_I\backend_python\agents\venv\Lib\site-packages\aiohttp\connector.py", line 1179, in _resolve_host_with_throttle
    addrs = await self._resolver.resolve(host, port, family=self._family)
            ^^^^^^^^^^^^^^^^^^^^^^^^^^^^^^^^^^^^^^^^^^^^^^^^^^^^^^^^^^^^^
  File "C:\Users\y.djemai\pam-testdrive\MARK_I\backend_python\agents\venv\Lib\site-packages\aiohttp\resolver.py", line 40, in resolve
    infos = await self._loop.getaddrinfo(
            ^^^^^^^^^^^^^^^^^^^^^^^^^^^^^
  File "C:\Program Files\Python312\Lib\asyncio\base_events.py", line 901, in getaddrinfo
    return await self.run_in_executor(
           ^^^^^^^^^^^^^^^^^^^^^^^^^^^
  File "C:\Program Files\Python312\Lib\concurrent\futures\thread.py", line 58, in run
    result = self.fn(*self.args, **self.kwargs)
             ^^^^^^^^^^^^^^^^^^^^^^^^^^^^^^^^^^
  File "C:\Program Files\Python312\Lib\socket.py", line 963, in getaddrinfo
    for res in _socket.getaddrinfo(host, port, family, type, proto, flags):
               ^^^^^^^^^^^^^^^^^^^^^^^^^^^^^^^^^^^^^^^^^^^^^^^^^^^^^^^^^^^
socket.gaierror: [Errno 11001] getaddrinfo failed

The above exception was the direct cause of the following exception:

Traceback (most recent call last):
  File "C:\Users\y.djemai\pam-testdrive\MARK_I\backend_python\agents\venv\Lib\site-packages\livekit\agents\worker.py", line 653, in _connection_task
    ws = await self._http_session.ws_connect(
         ^^^^^^^^^^^^^^^^^^^^^^^^^^^^^^^^^^^^
  File "C:\Users\y.djemai\pam-testdrive\MARK_I\backend_python\agents\venv\Lib\site-packages\aiohttp\client.py", line 1067, in _ws_connect
    resp = await self.request(
           ^^^^^^^^^^^^^^^^^^^
  File "C:\Users\y.djemai\pam-testdrive\MARK_I\backend_python\agents\venv\Lib\site-packages\aiohttp\client.py", line 770, in _request
    resp = await handler(req)
           ^^^^^^^^^^^^^^^^^^
  File "C:\Users\y.djemai\pam-testdrive\MARK_I\backend_python\agents\venv\Lib\site-packages\aiohttp\client.py", line 725, in _connect_and_send_request
    conn = await self._connector.connect(
           ^^^^^^^^^^^^^^^^^^^^^^^^^^^^^^
  File "C:\Users\y.djemai\pam-testdrive\MARK_I\backend_python\agents\venv\Lib\site-packages\aiohttp\connector.py", line 642, in connect
    proto = await self._create_connection(req, traces, timeout)
            ^^^^^^^^^^^^^^^^^^^^^^^^^^^^^^^^^^^^^^^^^^^^^^^^^^^
  File "C:\Users\y.djemai\pam-testdrive\MARK_I\backend_python\agents\venv\Lib\site-packages\aiohttp\connector.py", line 1209, in _create_connection
    _, proto = await self._create_direct_connection(req, traces, timeout)
               ^^^^^^^^^^^^^^^^^^^^^^^^^^^^^^^^^^^^^^^^^^^^^^^^^^^^^^^^^^
  File "C:\Users\y.djemai\pam-testdrive\MARK_I\backend_python\agents\venv\Lib\site-packages\aiohttp\connector.py", line 1538, in _create_direct_connection
    raise ClientConnectorDNSError(req.connection_key, exc) from exc
aiohttp.client_exceptions.ClientConnectorDNSError: Cannot connect to host pamtestdrive-euxn3osq.livekit.cloud:443 ssl:default [getaddrinfo failed]
2025-07-23 09:54:54,720 - livekit.agents - WARNING - failed to connect to livekit, retrying in 8s
Traceback (most recent call last):
  File "C:\Users\y.djemai\pam-testdrive\MARK_I\backend_python\agents\venv\Lib\site-packages\aiohttp\connector.py", line 1532, in _create_direct_connection
    hosts = await self._resolve_host(host, port, traces=traces)
            ^^^^^^^^^^^^^^^^^^^^^^^^^^^^^^^^^^^^^^^^^^^^^^^^^^^
  File "C:\Users\y.djemai\pam-testdrive\MARK_I\backend_python\agents\venv\Lib\site-packages\aiohttp\connector.py", line 1148, in _resolve_host
    return await asyncio.shield(resolved_host_task)
           ^^^^^^^^^^^^^^^^^^^^^^^^^^^^^^^^^^^^^^^^
  File "C:\Users\y.djemai\pam-testdrive\MARK_I\backend_python\agents\venv\Lib\site-packages\aiohttp\connector.py", line 1179, in _resolve_host_with_throttle
    addrs = await self._resolver.resolve(host, port, family=self._family)
            ^^^^^^^^^^^^^^^^^^^^^^^^^^^^^^^^^^^^^^^^^^^^^^^^^^^^^^^^^^^^^
  File "C:\Users\y.djemai\pam-testdrive\MARK_I\backend_python\agents\venv\Lib\site-packages\aiohttp\resolver.py", line 40, in resolve
    infos = await self._loop.getaddrinfo(
            ^^^^^^^^^^^^^^^^^^^^^^^^^^^^^
  File "C:\Program Files\Python312\Lib\asyncio\base_events.py", line 901, in getaddrinfo
    return await self.run_in_executor(
           ^^^^^^^^^^^^^^^^^^^^^^^^^^^
  File "C:\Program Files\Python312\Lib\concurrent\futures\thread.py", line 58, in run
    result = self.fn(*self.args, **self.kwargs)
             ^^^^^^^^^^^^^^^^^^^^^^^^^^^^^^^^^^
  File "C:\Program Files\Python312\Lib\socket.py", line 963, in getaddrinfo
    for res in _socket.getaddrinfo(host, port, family, type, proto, flags):
               ^^^^^^^^^^^^^^^^^^^^^^^^^^^^^^^^^^^^^^^^^^^^^^^^^^^^^^^^^^^
socket.gaierror: [Errno 11001] getaddrinfo failed

The above exception was the direct cause of the following exception:

Traceback (most recent call last):
  File "C:\Users\y.djemai\pam-testdrive\MARK_I\backend_python\agents\venv\Lib\site-packages\livekit\agents\worker.py", line 653, in _connection_task
    ws = await self._http_session.ws_connect(
         ^^^^^^^^^^^^^^^^^^^^^^^^^^^^^^^^^^^^
  File "C:\Users\y.djemai\pam-testdrive\MARK_I\backend_python\agents\venv\Lib\site-packages\aiohttp\client.py", line 1067, in _ws_connect
    resp = await self.request(
           ^^^^^^^^^^^^^^^^^^^
  File "C:\Users\y.djemai\pam-testdrive\MARK_I\backend_python\agents\venv\Lib\site-packages\aiohttp\client.py", line 770, in _request
    resp = await handler(req)
           ^^^^^^^^^^^^^^^^^^
  File "C:\Users\y.djemai\pam-testdrive\MARK_I\backend_python\agents\venv\Lib\site-packages\aiohttp\client.py", line 725, in _connect_and_send_request
    conn = await self._connector.connect(
           ^^^^^^^^^^^^^^^^^^^^^^^^^^^^^^
  File "C:\Users\y.djemai\pam-testdrive\MARK_I\backend_python\agents\venv\Lib\site-packages\aiohttp\connector.py", line 642, in connect
    proto = await self._create_connection(req, traces, timeout)
            ^^^^^^^^^^^^^^^^^^^^^^^^^^^^^^^^^^^^^^^^^^^^^^^^^^^
  File "C:\Users\y.djemai\pam-testdrive\MARK_I\backend_python\agents\venv\Lib\site-packages\aiohttp\connector.py", line 1209, in _create_connection
    _, proto = await self._create_direct_connection(req, traces, timeout)
               ^^^^^^^^^^^^^^^^^^^^^^^^^^^^^^^^^^^^^^^^^^^^^^^^^^^^^^^^^^
  File "C:\Users\y.djemai\pam-testdrive\MARK_I\backend_python\agents\venv\Lib\site-packages\aiohttp\connector.py", line 1538, in _create_direct_connection
    raise ClientConnectorDNSError(req.connection_key, exc) from exc
aiohttp.client_exceptions.ClientConnectorDNSError: Cannot connect to host pamtestdrive-euxn3osq.livekit.cloud:443 ssl:default [getaddrinfo failed]
2025-07-23 09:55:05,801 - livekit.agents - INFO - registered worker
2025-07-23 09:55:28,365 - livekit.agents - INFO - worker is below capacity, marking as available
2025-07-23 09:55:33,361 - livekit.agents - INFO - worker is at full capacity, marking as unavailable
2025-07-23 09:55:50,888 - livekit.agents - INFO - worker is below capacity, marking as available
2025-07-23 10:56:17,567 - livekit.agents - INFO - draining worker
2025-07-23 10:56:17,568 - livekit.agents - INFO - shutting down worker
