2025-08-03 21:09:35,876 - outbound-caller - INFO - Outbound Agent script d√©marre, args: ['C:\\Users\\y.djemai\\pam-testdrive\\MARK_I\\backend_python\\agents\\outbound_agent.py', 'start']
2025-08-03 21:09:35,876 - outbound-caller - INFO - Python version: 3.12.3 (tags/v3.12.3:f6650f9, Apr  9 2024, 14:05:25) [MSC v.1938 64 bit (AMD64)]
2025-08-03 21:09:35,876 - outbound-caller - INFO - R√©pertoire courant: C:\Users\y.djemai\pam-testdrive\MARK_I\backend_python\agents
2025-08-03 21:09:35,876 - outbound-caller - INFO - Encodage par d√©faut: utf-8
2025-08-03 21:09:35,879 - outbound-caller - INFO - Locale syst√®me: ('fr_FR', 'UTF-8')
2025-08-03 21:09:35,882 - outbound-caller - INFO - PATIENT_NAME: Jayden
2025-08-03 21:09:35,882 - outbound-caller - INFO - APPOINTMENT_TIME: next Tuesday at 3pm
2025-08-03 21:09:35,882 - outbound-caller - INFO - LK_ROOM_NAME: agent-call-461
2025-08-03 21:09:35,882 - outbound-caller - INFO - LK_JOB_METADATA: {"firstName": "Valued Customer", "lastName": "", "dial_info": {"agent_id": 11, "call_direction": "outbound", "room_name": "agent-call-461", "supabase_call_id": 461, "telnyx_call_control_id": null, "default_pathway_id": "d5fc510b-7635-4715-9066-e522daa2336d", "user_id": "b55837c4-270f-4f1f-8023-7ab09ee5f44d", "phone_number": "+33661329235", "sip_trunk_id": "ST_6CYLZwTLMCe2", "agent_caller_id_number": "+33189311209"}, "system_prompt": "test", "initial_greeting": "test", "wait_for_greeting": false, "pam_tier": "core", "interruption_threshold": 100, "ai_models": {"vad": {"provider": "silero"}, "stt": {"provider": "deepgram", "language": "en", "model": "nova-2"}, "tts": {"provider": "cartesia", "model": "sonic-2", "voice_id": "f9836c6e-a0bd-460e-9d3c-f7299fa60f94"}, "llm": {"provider": "openai", "model": "gpt-4o-mini"}}}
2025-08-03 21:09:35,882 - outbound-caller - INFO - LIVEKIT_URL: wss://pamtestdrive-euxn3osq.livekit.cloud
2025-08-03 21:09:35,882 - outbound-caller - INFO - LIVEKIT_API_KEY pr√©sent: Oui
2025-08-03 21:09:36,311 - outbound-caller - INFO - ‚úÖ Supabase client imported successfully
2025-08-03 21:09:37,618 - outbound-caller - INFO - Pathway integration loaded successfully
2025-08-03 21:09:39,310 - outbound-caller - INFO - üìû Outbound Agent entrypoint called
2025-08-03 21:09:39,311 - outbound-caller - INFO - Starting entrypoint for supabase_call_id: 461
2025-08-03 21:09:39,314 - outbound-caller - INFO - üìã Extracted dial_info: {'agent_id': 11, 'call_direction': 'outbound', 'room_name': 'agent-call-461', 'supabase_call_id': 461, 'telnyx_call_control_id': None, 'default_pathway_id': 'd5fc510b-7635-4715-9066-e522daa2336d', 'user_id': 'b55837c4-270f-4f1f-8023-7ab09ee5f44d', 'auth_token': None, 'phone_number': '+33661329235', 'sip_trunk_id': 'ST_6CYLZwTLMCe2', 'agent_caller_id_number': '+33189311209'}
2025-08-03 21:09:39,855 - outbound-caller - INFO - ‚úÖ Connected to LiveKit room
2025-08-03 21:09:39,855 - outbound-caller - INFO - Configuring AI models from job metadata...
2025-08-03 21:09:40,164 - outbound-caller - INFO - ‚úÖ AI Models configured successfully
2025-08-03 21:09:40,653 - outbound-caller - INFO - ‚úÖ Auto-started pathway execution: 5460060e-5d84-4891-ba60-e7593b2b881c
2025-08-03 21:09:40,653 - outbound-caller - INFO - Placeholder: Fetching pathway config for call_id 461 from backend...
2025-08-03 21:09:40,654 - outbound-caller - INFO - üîç Fetching call details for call_id: 461
2025-08-03 21:09:40,694 - outbound-caller - INFO - üìû Call 461 found with pathway_execution_id: 5460060e-5d84-4891-ba60-e7593b2b881c
2025-08-03 21:09:40,735 - outbound-caller - INFO - üìã Pathway execution found with pathway_id: d5fc510b-7635-4715-9066-e522daa2336d
2025-08-03 21:09:40,777 - outbound-caller - INFO - ‚úÖ Found pathway 'B2B Sales- Pathway' with config
2025-08-03 21:09:40,778 - outbound-caller - INFO - Fetched pathway config for call_id 461: {'edges': [{'id': 'xy-edge__conversation-1752584446694-condition-1752585419519', 'key': 'xy-edge__conversation-1752584446694-condition-1752585419519', 'source': 'conversation-1752584446694', 'target': 'condition-1752585419519'}, {'id': 'xy-edge__condition-1752585419519true-conversation-1752585487904', 'key': 'xy-edge__condition-1752585419519true-conversation-1752585487904', 'source': 'condition-1752585419519', 'target': 'conversation-1752585487904'}, {'id': 'xy-edge__conversation-1752585487904-condition-1752585515969', 'key': 'xy-edge__conversation-1752585487904-condition-1752585515969', 'source': 'conversation-1752585487904', 'target': 'condition-1752585515969'}, {'id': 'xy-edge__conversation-1752585487904-condition-1752585517385', 'key': 'xy-edge__conversation-1752585487904-condition-1752585517385', 'source': 'conversation-1752585487904', 'target': 'condition-1752585517385'}, {'id': 'xy-edge__conversation-1752585487904-condition-1752585513967', 'key': 'xy-edge__conversation-1752585487904-condition-1752585513967', 'source': 'conversation-1752585487904', 'target': 'condition-1752585513967'}, {'id': 'xy-edge__conversation-1752584446694-condition-1752585422872', 'key': 'xy-edge__conversation-1752584446694-condition-1752585422872', 'source': 'conversation-1752584446694', 'target': 'condition-1752585422872'}, {'id': 'xy-edge__conversation-1752584446694-condition-1752585421207', 'key': 'xy-edge__conversation-1752584446694-condition-1752585421207', 'source': 'conversation-1752584446694', 'target': 'condition-1752585421207'}, {'id': 'xy-edge__condition-1752585421207true-conversation-1752585570818', 'key': 'xy-edge__condition-1752585421207true-conversation-1752585570818', 'source': 'condition-1752585421207', 'target': 'conversation-1752585570818'}, {'id': 'xy-edge__conversation-1752585570818-condition-1752585591007', 'key': 'xy-edge__conversation-1752585570818-condition-1752585591007', 'source': 'conversation-1752585570818', 'target': 'condition-1752585591007'}, {'id': 'xy-edge__conversation-1752585570818-condition-1752585592634', 'key': 'xy-edge__conversation-1752585570818-condition-1752585592634', 'source': 'conversation-1752585570818', 'target': 'condition-1752585592634'}, {'id': 'xy-edge__condition-1752585515969true-conversation-1752585662522', 'key': 'xy-edge__condition-1752585515969true-conversation-1752585662522', 'source': 'condition-1752585515969', 'target': 'conversation-1752585662522'}, {'id': 'xy-edge__condition-1752585517385true-conversation-1752585818106', 'key': 'xy-edge__condition-1752585517385true-conversation-1752585818106', 'source': 'condition-1752585517385', 'target': 'conversation-1752585818106'}, {'id': 'xy-edge__condition-1752585513967true-conversation-1752585761728', 'key': 'xy-edge__condition-1752585513967true-conversation-1752585761728', 'source': 'condition-1752585513967', 'target': 'conversation-1752585761728'}, {'id': 'xy-edge__conversation-1752585761728-end_call-1752586102371', 'key': 'xy-edge__conversation-1752585761728-end_call-1752586102371', 'source': 'conversation-1752585761728', 'target': 'end_call-1752586102371'}, {'id': 'xy-edge__conversation-1752585662522-condition-1752585685583', 'key': 'xy-edge__conversation-1752585662522-condition-1752585685583', 'source': 'conversation-1752585662522', 'target': 'condition-1752585685583'}, {'id': 'xy-edge__conversation-1752585662522-condition-1752585687002', 'key': 'xy-edge__conversation-1752585662522-condition-1752585687002', 'source': 'conversation-1752585662522', 'target': 'condition-1752585687002'}, {'id': 'xy-edge__conversation-1752585662522-condition-1752585684024', 'key': 'xy-edge__conversation-1752585662522-condition-1752585684024', 'source': 'conversation-1752585662522', 'target': 'condition-1752585684024'}, {'id': 'xy-edge__condition-1752585685583true-app_action-1752586209057', 'key': 'xy-edge__condition-1752585685583true-app_action-1752586209057', 'source': 'condition-1752585685583', 'target': 'app_action-1752586209057'}, {'id': 'xy-edge__condition-1752585687002true-conversation-1752585818106', 'key': 'xy-edge__condition-1752585687002true-conversation-1752585818106', 'source': 'condition-1752585687002', 'target': 'conversation-1752585818106'}, {'id': 'xy-edge__condition-1752585684024true-conversation-1752585761728', 'key': 'xy-edge__condition-1752585684024true-conversation-1752585761728', 'source': 'condition-1752585684024', 'target': 'conversation-1752585761728'}, {'id': 'xy-edge__condition-1752586789213false-conversation-1752585818106', 'key': 'xy-edge__condition-1752586789213false-conversation-1752585818106', 'source': 'condition-1752586789213', 'target': 'conversation-1752585818106'}, {'id': 'xy-edge__app_action-1752586209057-condition-1752586789213', 'key': 'xy-edge__app_action-1752586209057-condition-1752586789213', 'source': 'app_action-1752586209057', 'target': 'condition-1752586789213'}, {'id': 'xy-edge__condition-1752585848810true-tools-1752586942596', 'key': 'xy-edge__condition-1752585848810true-tools-1752586942596', 'source': 'condition-1752585848810', 'target': 'tools-1752586942596'}, {'id': 'xy-edge__conversation-1752585818106-condition-1752585848810', 'key': 'xy-edge__conversation-1752585818106-condition-1752585848810', 'source': 'conversation-1752585818106', 'target': 'condition-1752585848810'}, {'id': 'xy-edge__conversation-1752585818106-condition-1752585852282', 'key': 'xy-edge__conversation-1752585818106-condition-1752585852282', 'source': 'conversation-1752585818106', 'target': 'condition-1752585852282'}, {'id': 'xy-edge__condition-1752585852282true-end_call-1752587058511', 'key': 'xy-edge__condition-1752585852282true-end_call-1752587058511', 'source': 'condition-1752585852282', 'target': 'end_call-1752587058511'}, {'id': 'xy-edge__condition-1752585591007true-end_call-1752586097416', 'key': 'xy-edge__condition-1752585591007true-end_call-1752586097416', 'source': 'condition-1752585591007', 'target': 'end_call-1752586097416'}, {'id': 'xy-edge__condition-1752585592634true-tools-1752587100122', 'key': 'xy-edge__condition-1752585592634true-tools-1752587100122', 'source': 'condition-1752585592634', 'target': 'tools-1752587100122'}, {'id': 'xy-edge__tools-1752587100122-end_call-1752586097416', 'key': 'xy-edge__tools-1752587100122-end_call-1752586097416', 'source': 'tools-1752587100122', 'target': 'end_call-1752586097416'}, {'id': 'xy-edge__condition-1752587369230true-conversation-1752586729436', 'key': 'xy-edge__condition-1752587369230true-conversation-1752586729436', 'source': 'condition-1752587369230', 'target': 'conversation-1752586729436'}, {'id': 'xy-edge__app_action-1752586209057-condition-1752587369230', 'key': 'xy-edge__app_action-1752586209057-condition-1752587369230', 'source': 'app_action-1752586209057', 'target': 'condition-1752587369230'}, {'id': 'xy-edge__conversation-1752586729436-condition-1752586879584', 'key': 'xy-edge__conversation-1752586729436-condition-1752586879584', 'source': 'conversation-1752586729436', 'target': 'condition-1752586879584'}, {'id': 'xy-edge__condition-1752586879584true-end_call-1752586890630', 'key': 'xy-edge__condition-1752586879584true-end_call-1752586890630', 'source': 'condition-1752586879584', 'target': 'end_call-1752586890630'}, {'id': 'xy-edge__tools-1752586942596-condition-1752586959602', 'key': 'xy-edge__tools-1752586942596-condition-1752586959602', 'source': 'tools-1752586942596', 'target': 'condition-1752586959602'}, {'id': 'xy-edge__condition-1752586959602true-end_call-1752586990804', 'key': 'xy-edge__condition-1752586959602true-end_call-1752586990804', 'source': 'condition-1752586959602', 'target': 'end_call-1752586990804'}, {'id': 'xy-edge__condition-1752585422872true-end_call-1753698161049', 'key': 'xy-edge__condition-1752585422872true-end_call-1753698161049', 'source': 'condition-1752585422872', 'target': 'end_call-1753698161049'}], 'nodes': [{'id': 'conversation-1752584446694', 'name': 'Greeting', 'type': 'conversation', 'config': {'id': 'greeting', 'prompt': 'You are Pam from Dunder Mifflin. You are making an outbound sales call to someone who previously inquired about your services. Your goal is to determine if this is a good time to talk. Be friendly and professional. Start by introducing yourself and your company, mention that you are following up on their inquiry, then ask if they have a few minutes to talk. Listen carefully to their response to gauge their availability and interest level. Extract any information about their current situation or needs they mention.', 'greeting': 'Hi this is Pam from Dunder Mifflin', 'language': 'en', 'temperature': 0.7, 'global_access': False, 'silence_timeout': 10, 'extracted_variables': [{'name': 'conversation_started', 'type': 'boolean', 'description': 'Conversation has started', 'extraction_prompt': 'Conversation has started'}, {'name': 'call_start_time', 'type': 'string', 'description': 'Timestamp when call started', 'extraction_prompt': 'Timestamp when call started'}], 'interruption_enabled': True, 'transition_condition': '', 'transcription_enabled': True, 'transition_condition_enabled': False}, 'position': {'x': 159.19974474711404, 'y': -406.435592953321}}, {'id': 'condition-1752585419519', 'name': 'Greeting Condition 1', 'type': 'condition', 'config': {'id': 'greeting_condition_1', 'prompt': '', 'condition': {'type': 'ai', 'prompt': 'Person is available to talk now and shows interest in the conversation', 'next_node': 'qualify_lead', 'confidence_threshold': 0.7}, 'source_node': 'greeting'}, 'position': {'x': 112.72206178621366, 'y': 127.8578385636643}}, {'id': 'condition-1752585421207', 'name': 'Schedule Callback Condition', 'type': 'condition', 'config': {'id': 'greeting_condition_2', 'prompt': '', 'condition': {'type': 'ai', 'prompt': 'Person is busy or wants to be called back later', 'next_node': 'schedule_callback', 'confidence_threshold': 0.7}, 'source_node': 'greeting', 'routing_style': 'livekit', 'routing_targets': [{'name': 'Schedule Callback', 'node_id': 'conversation-1752585570818', 'description': 'Route to Schedule Callback', 'confidence_threshold': 0.7}]}, 'position': {'x': -313.0080598768747, 'y': -162.41507420188168}}, {'id': 'condition-1752585422872', 'name': 'Greeting Condition 3', 'type': 'condition', 'config': {'id': 'greeting_condition_3', 'prompt': '', 'condition': {'type': 'ai', 'prompt': 'Person seems uninterested, hostile, or wants to end the call', 'next_node': 'polite_decline', 'confidence_threshold': 0.8}, 'source_node': 'greeting'}, 'position': {'x': -541.3518080512141, 'y': 374.79123495864394}}, {'id': 'conversation-1752585487904', 'name': 'Qualify Lead', 'type': 'conversation', 'config': {'id': 'qualify_lead', 'prompt': "The person is willing to talk. Now you need to qualify them as a potential customer. Ask about their current situation, what specific services they're looking for, their timeline, and any challenges they're facing. Be conversational but focused on gathering key qualifying information: budget range, decision-making authority, urgency of need, and fit for your services. Listen for buying signals and pain points. Ask open-ended questions to understand their needs deeply.", 'language': 'en', 'temperature': 0.7, 'global_access': False, 'system_prompt': '', 'silence_timeout': 10, 'extracted_variables': [{'name': 'qualification_started', 'type': 'boolean', 'description': 'Lead qualification process started', 'extraction_prompt': 'Lead qualification process started'}], 'interruption_enabled': True, 'transition_condition': '', 'transcription_enabled': True, 'transition_condition_enabled': False}, 'position': {'x': 163.4402281365625, 'y': 311.3499021877407}}, {'id': 'condition-1752585513967', 'name': 'Qualify Lead Condition 3', 'type': 'condition', 'config': {'id': 'qualify_lead_condition_3', 'prompt': '', 'condition': {'type': 'ai', 'prompt': 'Person seems like a poor fit with no budget, no authority, no genuine need, or timing issues', 'next_node': 'polite_decline', 'confidence_threshold': 0.8}, 'source_node': 'qualify_lead'}, 'position': {'x': 573.7084072411365, 'y': 459.684096539979}}, {'id': 'condition-1752585515969', 'name': 'Qualify Lead Condition 1', 'type': 'condition', 'config': {'id': 'qualify_lead_condition_1', 'prompt': '', 'condition': {'type': 'ai', 'prompt': 'Person is a qualified lead with genuine interest and potential budget for our services', 'next_node': 'book_appointment', 'confidence_threshold': 0.7}, 'source_node': 'qualify_lead'}, 'position': {'x': -191.31874774110742, 'y': 458.6868230734692}}, {'id': 'condition-1752585517385', 'name': 'Qualify Lead Condition 2', 'type': 'condition', 'config': {'id': 'qualify_lead_condition_2', 'prompt': '', 'condition': {'type': 'ai', 'prompt': 'Person expressed interest but wants more information before scheduling anything', 'next_node': 'send_information', 'confidence_threshold': 0.7}, 'source_node': 'qualify_lead'}, 'position': {'x': 202.90168708178726, 'y': 488.9489925914291}}, {'id': 'conversation-1752585570818', 'name': 'Schedule Callback', 'type': 'conversation', 'config': {'id': 'schedule_callback', 'prompt': "The person indicated they're busy or want to be called back later. Be understanding and accommodating. Ask for their preferred time for a callback - offer specific options like 'tomorrow afternoon' or 'later this week'. Try to get a specific day and time range. Also ask if there's any particular information they'd like you to have ready for the callback. Be flexible and work around their schedule.", 'language': 'en', 'temperature': 0.7, 'global_access': False, 'system_prompt': '', 'silence_timeout': 10, 'extracted_variables': [{'name': 'callback_requested', 'type': 'boolean', 'description': 'Customer requested a callback', 'extraction_prompt': 'Customer requested a callback'}], 'interruption_enabled': True, 'transition_condition': '', 'transcription_enabled': True, 'transition_condition_enabled': False}, 'position': {'x': -824.9743648175192, 'y': 117.32593048536444}}, {'id': 'condition-1752585591007', 'name': 'Schedule Callback Condition 2', 'type': 'condition', 'config': {'id': 'schedule_callback_condition_2', 'prompt': '', 'condition': {'type': 'ai', 'prompt': 'Person is politely trying to end the call without genuine interest in a callback', 'next_node': 'end_callback', 'confidence_threshold': 0.8}, 'source_node': 'schedule_callback'}, 'position': {'x': -952.3200684413032, 'y': 282.70220411280184}}, {'id': 'condition-1752585592634', 'name': 'Schedule Callback Condition 1', 'type': 'condition', 'config': {'id': 'schedule_callback_condition_1', 'prompt': '', 'condition': {'type': 'ai', 'prompt': 'Person provided a specific time or preference for the callback', 'next_node': 'schedule_callback_tool', 'confidence_threshold': 0.7}, 'source_node': 'schedule_callback'}, 'position': {'x': -1310.484446829189, 'y': 285.194202724594}}, {'id': 'conversation-1752585662522', 'name': 'Book Appointment', 'type': 'conversation', 'config': {'id': 'book_appointment', 'prompt': "This is a qualified lead who has shown interest. Your goal is to schedule a consultation or appointment. Mention the value they'll get from the meeting and how it will help solve their specific needs you've identified. Offer specific time slots and be flexible with scheduling. Try to get their availability, preferred meeting type (phone, video, in-person), and contact details for scheduling. If they hesitate, address their concerns and offer to send more information first.", 'language': 'en', 'temperature': 0.7, 'global_access': False, 'system_prompt': '', 'silence_timeout': 10, 'extracted_variables': [{'name': 'booking_started', 'type': 'boolean', 'description': 'Appointment booking process started', 'extraction_prompt': 'Appointment booking process started'}, {'name': 'qualified_lead', 'type': 'boolean', 'description': 'Lead is qualified for appointment', 'extraction_prompt': 'Lead is qualified for appointment'}], 'interruption_enabled': True, 'transition_condition': '', 'transcription_enabled': True, 'transition_condition_enabled': False}, 'position': {'x': -157.01338060119002, 'y': 676.3166837636757}}, {'id': 'condition-1752585684024', 'name': 'Book Appointment Condition 3', 'type': 'condition', 'config': {'id': 'book_appointment_condition_3', 'prompt': '', 'condition': {'type': 'ai', 'prompt': 'Person declined to schedule or seems hesitant about moving forward', 'next_node': 'polite_decline', 'confidence_threshold': 0.8}, 'source_node': 'book_appointment'}, 'position': {'x': -273.7854306622481, 'y': 1041.96815487565}}, {'id': 'condition-1752585685583', 'name': 'Book Appointment Condition 1', 'type': 'condition', 'config': {'id': 'book_appointment_condition_1', 'prompt': '', 'condition': {'type': 'ai', 'prompt': 'Person agreed to schedule an appointment and provided their availability or preferred time', 'next_node': 'create_calendar_event', 'confidence_threshold': 0.7}, 'source_node': 'book_appointment'}, 'position': {'x': -943.9017843724146, 'y': 1044.3504442101917}}, {'id': 'condition-1752585687002', 'name': 'Book Appointment Condition 2', 'type': 'condition', 'config': {'id': 'book_appointment_condition_2', 'prompt': '', 'condition': {'type': 'ai', 'prompt': 'Person wants to schedule but asked for information to be sent first', 'next_node': 'send_information', 'confidence_threshold': 0.7}, 'source_node': 'book_appointment'}, 'position': {'x': -606.1989666079745, 'y': 1056.062258946693}}, {'id': 'conversation-1752585761728', 'name': 'Polite Decline', 'type': 'conversation', 'config': {'id': 'polite_decline', 'prompt': "This person doesn't seem like a good fit right now. Be polite and professional. Thank them for their time, acknowledge that the timing might not be right, and offer to send them information for future reference. Ask if they'd like to receive updates or if there's a better time to reach out in the future. End on a positive note and leave the door open for future contact.", 'language': 'en', 'temperature': 0.7, 'global_access': False, 'system_prompt': '', 'silence_timeout': 10, 'extracted_variables': [{'name': 'lead_declined', 'type': 'boolean', 'description': 'Lead was politely declined', 'extraction_prompt': 'Lead was politely declined'}], 'interruption_enabled': True, 'transition_condition': '', 'transcription_enabled': True, 'transition_condition_enabled': False}, 'position': {'x': 716.720968381256, 'y': 1115.8291479001427}}, {'id': 'conversation-1752585818106', 'name': 'Send Information', 'type': 'conversation', 'config': {'id': 'send_information', 'prompt': "The person wants more information before scheduling. Ask for their email address to send details about your services, pricing, case studies, or whatever information would be most relevant to their specific needs. Be specific about what you'll send and when they can expect it. Also ask if they have any specific questions you can address in the information packet. Make them feel comfortable that this isn't high-pressure follow-up.", 'language': 'en', 'temperature': 0.7, 'global_access': False, 'system_prompt': '', 'silence_timeout': 10, 'extracted_variables': [{'name': 'info_requested', 'type': 'boolean', 'description': 'Customer requested information packet', 'extraction_prompt': 'Customer requested information packet'}], 'interruption_enabled': True, 'transition_condition': '', 'transcription_enabled': True, 'transition_condition_enabled': False}, 'position': {'x': 378.9665058084346, 'y': 1507.51975168371}}, {'id': 'condition-1752585848810', 'name': 'Send Information Condition 1', 'type': 'condition', 'config': {'id': 'send_information_condition_1', 'prompt': '', 'condition': {'type': 'ai', 'prompt': 'Person provided their email address for sending information', 'next_node': 'capture_email', 'confidence_threshold': 0.7}, 'source_node': 'send_information'}, 'position': {'x': 165.51654504146074, 'y': 1635.6430622199036}}, {'id': 'condition-1752585852282', 'name': 'Send Information Condition 2', 'type': 'condition', 'config': {'id': 'send_information_condition_2', 'prompt': '', 'condition': {'type': 'ai', 'prompt': 'Person declined to provide their email or seems uninterested in receiving information', 'next_node': 'end_declined', 'confidence_threshold': 0.8}, 'source_node': 'send_information'}, 'position': {'x': 500.68393482997806, 'y': 1628.8051584512218}}, {'id': 'end_call-1752586097416', 'name': 'End Callback', 'type': 'end_call', 'config': {'id': 'end_callback', 'custom_data': {}, 'save_recording': False, 'email_recipient': '', 'goodbye_message': "Perfect! I'll call you back at {callback_time}. Have a great day!", 'save_transcript': True, 'call_disposition': 'completed', 'send_summary_email': False, 'extracted_variables': [{'name': 'call_outcome', 'type': 'string', 'description': 'Final call outcome', 'extraction_prompt': 'Final call outcome'}, {'name': 'callback_scheduled_for', 'type': 'string', 'description': 'Scheduled callback time', 'extraction_prompt': 'Scheduled callback time'}]}, 'position': {'x': -1059.0542799629145, 'y': 741.924119385108}}, {'id': 'end_call-1752586102371', 'name': 'End Declined', 'type': 'end_call', 'config': {'id': 'end_declined', 'custom_data': {}, 'save_recording': False, 'email_recipient': '', 'goodbye_message': 'Thank you for your time. Have a great day!', 'save_transcript': True, 'call_disposition': 'completed', 'send_summary_email': False, 'extracted_variables': [{'name': 'call_outcome', 'type': 'string', 'description': 'Final call outcome', 'extraction_prompt': 'Final call outcome'}, {'name': 'decline_reason', 'type': 'string', 'description': 'Reason for declining', 'extraction_prompt': 'Reason for declining'}]}, 'position': {'x': 667.7410507582531, 'y': 1363.7408872996832}}, {'id': 'app_action-1752586209057', 'name': 'Create Calendar Event', 'type': 'app_action', 'config': {'id': 'create_calendar_event', 'data': {'app_name': 'google_calendar', 'action_type': 'create_event', 'action_config': {'calendar_id': 'primary', 'duration_minutes': 60}, 'field_mappings': {'summary': 'Consultation with {contact_name}', 'attendees': ['{contact_email}'], 'start_time': '{selected_appointment_time}', 'description': 'Sales consultation scheduled via PAM'}}, 'app_name': '', 'action_type': '', 'action_config': {}, 'field_mappings': {}, 'user_connection_id': '', 'extracted_variables': [{'name': 'appointment_booked', 'type': 'boolean', 'description': 'Appointment successfully booked', 'extraction_prompt': 'Appointment successfully booked'}]}, 'position': {'x': -931.7621809606596, 'y': 1347.8657791544829}}, {'id': 'conversation-1752586729436', 'name': 'Confirm Appointment', 'type': 'conversation', 'config': {'id': 'confirm_appointment', 'prompt': "The calendar event has been successfully created. Confirm the appointment details with enthusiasm. Mention the date, time, and format of the meeting. Let them know they'll receive a calendar invite shortly. Ask if they have any specific topics they'd like to discuss or questions they want addressed during the consultation. Set clear expectations for what the meeting will cover and how long it will take.", 'language': 'en', 'temperature': 0.7, 'global_access': False, 'system_prompt': '', 'silence_timeout': 10, 'extracted_variables': [{'name': 'appointment_confirmed', 'type': 'boolean', 'description': 'Appointment details confirmed with customer', 'extraction_prompt': 'Appointment details confirmed with customer'}], 'interruption_enabled': True, 'transition_condition': '', 'transcription_enabled': True, 'transition_condition_enabled': False}, 'position': {'x': -981.7639769305733, 'y': 1813.2009923352334}}, {'id': 'condition-1752586789213', 'name': 'Create Calendar Event Condition 2', 'type': 'condition', 'config': {'id': 'create_calendar_event_condition_2', 'prompt': 'Calendar event creation failed or encountered an error', 'source_node': 'create_calendar_event'}, 'position': {'x': -764.0953358329234, 'y': 1530.225098242719}}, {'id': 'condition-1752586879584', 'name': 'Confirm Appointment Condition 1', 'type': 'condition', 'config': {'id': 'confirm_appointment_condition_1', 'prompt': 'Appointment has been confirmed and conversation wrapped up successfully', 'source_node': 'confirm_appointment'}, 'position': {'x': -1011.2849335976309, 'y': 1938.9218754961776}}, {'id': 'end_call-1752586890630', 'name': 'End Success', 'type': 'end_call', 'config': {'id': 'end_success', 'custom_data': {}, 'save_recording': False, 'email_recipient': '', 'goodbye_message': 'Thank you! Looking forward to speaking with you on {appointment_date}. Have a great day!', 'save_transcript': True, 'call_disposition': 'completed', 'send_summary_email': False, 'extracted_variables': [{'name': 'call_outcome', 'type': 'string', 'description': 'Final call outcome', 'extraction_prompt': 'Final call outcome'}, {'name': 'success', 'type': 'boolean', 'description': 'Call was successful', 'extraction_prompt': 'Call was successful'}, {'name': 'appointment_date', 'type': 'string', 'description': 'Scheduled appointment date', 'extraction_prompt': 'Scheduled appointment date'}, {'name': 'appointment_time', 'type': 'string', 'description': 'Scheduled appointment time', 'extraction_prompt': 'Scheduled appointment time'}]}, 'position': {'x': -1000.4160641634687, 'y': 2109.1766822906798}}, {'id': 'tools-1752586942596', 'name': 'Capture Email', 'type': 'tools', 'config': {'id': 'capture_email', 'app_name': 'google_calendar', 'parameters': {'email': '{contact_email}', 'notes': '{conversation_summary}', 'source': 'phone_call', 'status': 'info_requested', 'contact_name': '{contact_name}', 'phone_number': '{phone_number}', 'interest_level': '{interest_level}', 'qualification_score': '{qualification_score}'}, 'webhook_url': 'https://hook.us1.make.com/abc123def456', 'selected_app_id': 'ebce972a-6206-4708-8557-90bfd816ad14', 'selected_app_name': 'Google Calendar', 'variable_mappings': {}, 'selected_action_id': '', 'extracted_variables': [{'name': 'email_captured', 'type': 'boolean', 'description': 'Customer email address captured', 'extraction_prompt': 'Customer email address captured'}], 'selected_action_name': '', 'selected_action_description': ''}, 'position': {'x': 212.10097682093254, 'y': 1877.1337109778142}}, {'id': 'condition-1752586959602', 'name': 'Condition Node', 'type': 'condition', 'config': {'prompt': 'email captured'}, 'position': {'x': 207.1067512553629, 'y': 2061.4359900186564}}, {'id': 'end_call-1752586990804', 'name': 'End Info Sent', 'type': 'end_call', 'config': {'id': 'end_info_sent', 'custom_data': {}, 'save_recording': False, 'email_recipient': '', 'goodbye_message': "Great! I'll send that information right over. Feel free to call us with any questions. Have a wonderful day!", 'save_transcript': True, 'call_disposition': 'completed', 'send_summary_email': False, 'extracted_variables': [{'name': 'call_outcome', 'type': 'string', 'description': 'Final call outcome', 'extraction_prompt': 'Final call outcome'}, {'name': 'follow_up_required', 'type': 'boolean', 'description': 'Follow-up is required', 'extraction_prompt': 'Follow-up is required'}]}, 'position': {'x': 201.81395080636105, 'y': 2189.0828212015595}}, {'id': 'end_call-1752587058511', 'name': 'End Declined', 'type': 'end_call', 'config': {'id': 'end_declined', 'custom_data': {}, 'save_recording': False, 'email_recipient': '', 'goodbye_message': 'Thank you for your time. Have a great day!', 'save_transcript': True, 'call_disposition': 'completed', 'send_summary_email': False, 'extracted_variables': [{'name': 'call_outcome', 'type': 'string', 'description': 'Final call outcome', 'extraction_prompt': 'Final call outcome'}, {'name': 'decline_reason', 'type': 'string', 'description': 'Reason for declining', 'extraction_prompt': 'Reason for declining'}]}, 'position': {'x': 860.3817328453051, 'y': 1807.0939093564982}}, {'id': 'tools-1752587100122', 'name': 'Schedule Callback Tool', 'type': 'tools', 'config': {'id': 'schedule_callback_tool', 'parameters': {'priority': 'medium', 'agent_notes': '{conversation_summary}', 'contact_name': '{contact_name}', 'phone_number': '{phone_number}', 'callback_time': '{preferred_callback_time}', 'callback_reason': 'customer_requested'}, 'webhook_url': 'https://hook.us1.make.com/callback789xyz', 'selected_app_id': '', 'selected_app_name': '', 'variable_mappings': {}, 'selected_action_id': '', 'extracted_variables': [{'name': 'callback_scheduled', 'type': 'boolean', 'description': 'Callback was successfully scheduled', 'extraction_prompt': 'Callback was successfully scheduled'}], 'selected_action_name': '', 'selected_action_description': ''}, 'position': {'x': -1299.6936738792808, 'y': 453.175693126387}}, {'id': 'condition-1752587369230', 'name': 'Create Calendar Event Condition 1', 'type': 'condition', 'config': {'id': 'create_calendar_event_condition_1', 'prompt': '', 'condition': {'type': 'ai', 'prompt': 'Calendar event was successfully created', 'next_node': 'confirm_appointment', 'confidence_threshold': 0.9}, 'source_node': 'create_calendar_event'}, 'position': {'x': -1149.0097523440525, 'y': 1584.6468586902927}}, {'id': 'end_call-1753698161049', 'name': 'End_call  Greeting', 'type': 'end_call', 'config': {'custom_data': {}, 'save_recording': False, 'email_recipient': '', 'goodbye_message': 'Thank you for your time. Have a great day!', 'save_transcript': True, 'call_disposition': 'completed', 'send_summary_email': False}, 'position': {'x': -517.2888315376458, 'y': 701.791880267355}}], 'variables': {}, 'entry_point': 'conversation-1752584446694'}
2025-08-03 21:09:40,779 - outbound-caller - INFO - ‚úÖ Fetched pathway config for call_id 461
2025-08-03 21:09:40,779 - outbound-caller - INFO - Pre-initialized PathwayNodeAgent for node: conversation-1752584446694
2025-08-03 21:09:40,780 - outbound-caller - INFO - Pre-initialized PathwayNodeAgent for node: conversation-1752585487904
2025-08-03 21:09:40,780 - outbound-caller - INFO - Pre-initialized PathwayNodeAgent for node: conversation-1752585570818
2025-08-03 21:09:40,780 - outbound-caller - INFO - Pre-initialized PathwayNodeAgent for node: conversation-1752585662522
2025-08-03 21:09:40,780 - outbound-caller - INFO - Pre-initialized PathwayNodeAgent for node: conversation-1752585761728
2025-08-03 21:09:40,782 - outbound-caller - INFO - Pre-initialized PathwayNodeAgent for node: conversation-1752585818106
2025-08-03 21:09:40,782 - outbound-caller - INFO - Pre-initialized PathwayNodeAgent for node: conversation-1752586729436
2025-08-03 21:09:40,782 - outbound-caller - INFO - ‚úÖ Creating session with PathwayNodeAgent for node: conversation-1752584446694
2025-08-03 21:09:40,782 - outbound-caller - INFO - Creating SIP participant to initiate outbound call...
2025-08-03 21:09:40,783 - outbound-caller - INFO - Dialing +33661329235 using SIP trunk ST_6CYLZwTLMCe2
2025-08-03 21:09:47,473 - outbound-caller - INFO - SIP call initiated to +33661329235. Waiting for participant to join...
2025-08-03 21:28:47,472 - livekit.agents - WARNING - job executor is unresponsive
2025-08-04 00:23:46,480 - livekit.agents - WARNING - failed to connect to livekit, retrying in 0s
Traceback (most recent call last):
  File "C:\Users\y.djemai\pam-testdrive\MARK_I\backend_python\agents\venv\Lib\site-packages\livekit\agents\worker.py", line 692, in _connection_task
    await self._run_ws(ws)
  File "C:\Users\y.djemai\pam-testdrive\MARK_I\backend_python\agents\venv\Lib\site-packages\livekit\agents\worker.py", line 773, in _run_ws
    await asyncio.gather(*tasks)
  File "C:\Users\y.djemai\pam-testdrive\MARK_I\backend_python\agents\venv\Lib\site-packages\livekit\agents\worker.py", line 745, in _recv_task
    raise Exception("worker connection closed unexpectedly")
Exception: worker connection closed unexpectedly
2025-08-04 02:06:34,400 - livekit.agents - WARNING - failed to connect to livekit, retrying in 0s
Traceback (most recent call last):
  File "C:\Users\y.djemai\pam-testdrive\MARK_I\backend_python\agents\venv\Lib\site-packages\livekit\agents\worker.py", line 692, in _connection_task
    await self._run_ws(ws)
  File "C:\Users\y.djemai\pam-testdrive\MARK_I\backend_python\agents\venv\Lib\site-packages\livekit\agents\worker.py", line 773, in _run_ws
    await asyncio.gather(*tasks)
  File "C:\Users\y.djemai\pam-testdrive\MARK_I\backend_python\agents\venv\Lib\site-packages\livekit\agents\worker.py", line 745, in _recv_task
    raise Exception("worker connection closed unexpectedly")
Exception: worker connection closed unexpectedly
2025-08-04 06:11:35,443 - livekit.agents - WARNING - failed to connect to livekit, retrying in 0s
Traceback (most recent call last):
  File "C:\Users\y.djemai\pam-testdrive\MARK_I\backend_python\agents\venv\Lib\site-packages\livekit\agents\worker.py", line 692, in _connection_task
    await self._run_ws(ws)
  File "C:\Users\y.djemai\pam-testdrive\MARK_I\backend_python\agents\venv\Lib\site-packages\livekit\agents\worker.py", line 773, in _run_ws
    await asyncio.gather(*tasks)
  File "C:\Users\y.djemai\pam-testdrive\MARK_I\backend_python\agents\venv\Lib\site-packages\livekit\agents\worker.py", line 745, in _recv_task
    raise Exception("worker connection closed unexpectedly")
Exception: worker connection closed unexpectedly
2025-08-04 06:11:35,443 - livekit.agents - WARNING - failed to connect to livekit, retrying in 2s
Traceback (most recent call last):
  File "C:\Users\y.djemai\pam-testdrive\MARK_I\backend_python\agents\venv\Lib\site-packages\aiohttp\connector.py", line 1532, in _create_direct_connection
    hosts = await self._resolve_host(host, port, traces=traces)
            ^^^^^^^^^^^^^^^^^^^^^^^^^^^^^^^^^^^^^^^^^^^^^^^^^^^
  File "C:\Users\y.djemai\pam-testdrive\MARK_I\backend_python\agents\venv\Lib\site-packages\aiohttp\connector.py", line 1148, in _resolve_host
    return await asyncio.shield(resolved_host_task)
           ^^^^^^^^^^^^^^^^^^^^^^^^^^^^^^^^^^^^^^^^
  File "C:\Users\y.djemai\pam-testdrive\MARK_I\backend_python\agents\venv\Lib\site-packages\aiohttp\connector.py", line 1179, in _resolve_host_with_throttle
    addrs = await self._resolver.resolve(host, port, family=self._family)
            ^^^^^^^^^^^^^^^^^^^^^^^^^^^^^^^^^^^^^^^^^^^^^^^^^^^^^^^^^^^^^
  File "C:\Users\y.djemai\pam-testdrive\MARK_I\backend_python\agents\venv\Lib\site-packages\aiohttp\resolver.py", line 40, in resolve
    infos = await self._loop.getaddrinfo(
            ^^^^^^^^^^^^^^^^^^^^^^^^^^^^^
  File "C:\Program Files\Python312\Lib\asyncio\base_events.py", line 901, in getaddrinfo
    return await self.run_in_executor(
           ^^^^^^^^^^^^^^^^^^^^^^^^^^^
  File "C:\Program Files\Python312\Lib\concurrent\futures\thread.py", line 58, in run
    result = self.fn(*self.args, **self.kwargs)
             ^^^^^^^^^^^^^^^^^^^^^^^^^^^^^^^^^^
  File "C:\Program Files\Python312\Lib\socket.py", line 963, in getaddrinfo
    for res in _socket.getaddrinfo(host, port, family, type, proto, flags):
               ^^^^^^^^^^^^^^^^^^^^^^^^^^^^^^^^^^^^^^^^^^^^^^^^^^^^^^^^^^^
socket.gaierror: [Errno 11001] getaddrinfo failed

The above exception was the direct cause of the following exception:

Traceback (most recent call last):
  File "C:\Users\y.djemai\pam-testdrive\MARK_I\backend_python\agents\venv\Lib\site-packages\livekit\agents\worker.py", line 653, in _connection_task
    ws = await self._http_session.ws_connect(
         ^^^^^^^^^^^^^^^^^^^^^^^^^^^^^^^^^^^^
  File "C:\Users\y.djemai\pam-testdrive\MARK_I\backend_python\agents\venv\Lib\site-packages\aiohttp\client.py", line 1067, in _ws_connect
    resp = await self.request(
           ^^^^^^^^^^^^^^^^^^^
  File "C:\Users\y.djemai\pam-testdrive\MARK_I\backend_python\agents\venv\Lib\site-packages\aiohttp\client.py", line 770, in _request
    resp = await handler(req)
           ^^^^^^^^^^^^^^^^^^
  File "C:\Users\y.djemai\pam-testdrive\MARK_I\backend_python\agents\venv\Lib\site-packages\aiohttp\client.py", line 725, in _connect_and_send_request
    conn = await self._connector.connect(
           ^^^^^^^^^^^^^^^^^^^^^^^^^^^^^^
  File "C:\Users\y.djemai\pam-testdrive\MARK_I\backend_python\agents\venv\Lib\site-packages\aiohttp\connector.py", line 642, in connect
    proto = await self._create_connection(req, traces, timeout)
            ^^^^^^^^^^^^^^^^^^^^^^^^^^^^^^^^^^^^^^^^^^^^^^^^^^^
  File "C:\Users\y.djemai\pam-testdrive\MARK_I\backend_python\agents\venv\Lib\site-packages\aiohttp\connector.py", line 1209, in _create_connection
    _, proto = await self._create_direct_connection(req, traces, timeout)
               ^^^^^^^^^^^^^^^^^^^^^^^^^^^^^^^^^^^^^^^^^^^^^^^^^^^^^^^^^^
  File "C:\Users\y.djemai\pam-testdrive\MARK_I\backend_python\agents\venv\Lib\site-packages\aiohttp\connector.py", line 1538, in _create_direct_connection
    raise ClientConnectorDNSError(req.connection_key, exc) from exc
aiohttp.client_exceptions.ClientConnectorDNSError: Cannot connect to host pamtestdrive-euxn3osq.livekit.cloud:443 ssl:default [getaddrinfo failed]
2025-08-04 06:11:37,463 - livekit.agents - WARNING - failed to connect to livekit, retrying in 4s
Traceback (most recent call last):
  File "C:\Users\y.djemai\pam-testdrive\MARK_I\backend_python\agents\venv\Lib\site-packages\aiohttp\connector.py", line 1532, in _create_direct_connection
    hosts = await self._resolve_host(host, port, traces=traces)
            ^^^^^^^^^^^^^^^^^^^^^^^^^^^^^^^^^^^^^^^^^^^^^^^^^^^
  File "C:\Users\y.djemai\pam-testdrive\MARK_I\backend_python\agents\venv\Lib\site-packages\aiohttp\connector.py", line 1148, in _resolve_host
    return await asyncio.shield(resolved_host_task)
           ^^^^^^^^^^^^^^^^^^^^^^^^^^^^^^^^^^^^^^^^
  File "C:\Users\y.djemai\pam-testdrive\MARK_I\backend_python\agents\venv\Lib\site-packages\aiohttp\connector.py", line 1179, in _resolve_host_with_throttle
    addrs = await self._resolver.resolve(host, port, family=self._family)
            ^^^^^^^^^^^^^^^^^^^^^^^^^^^^^^^^^^^^^^^^^^^^^^^^^^^^^^^^^^^^^
  File "C:\Users\y.djemai\pam-testdrive\MARK_I\backend_python\agents\venv\Lib\site-packages\aiohttp\resolver.py", line 40, in resolve
    infos = await self._loop.getaddrinfo(
            ^^^^^^^^^^^^^^^^^^^^^^^^^^^^^
  File "C:\Program Files\Python312\Lib\asyncio\base_events.py", line 901, in getaddrinfo
    return await self.run_in_executor(
           ^^^^^^^^^^^^^^^^^^^^^^^^^^^
  File "C:\Program Files\Python312\Lib\concurrent\futures\thread.py", line 58, in run
    result = self.fn(*self.args, **self.kwargs)
             ^^^^^^^^^^^^^^^^^^^^^^^^^^^^^^^^^^
  File "C:\Program Files\Python312\Lib\socket.py", line 963, in getaddrinfo
    for res in _socket.getaddrinfo(host, port, family, type, proto, flags):
               ^^^^^^^^^^^^^^^^^^^^^^^^^^^^^^^^^^^^^^^^^^^^^^^^^^^^^^^^^^^
socket.gaierror: [Errno 11001] getaddrinfo failed

The above exception was the direct cause of the following exception:

Traceback (most recent call last):
  File "C:\Users\y.djemai\pam-testdrive\MARK_I\backend_python\agents\venv\Lib\site-packages\livekit\agents\worker.py", line 653, in _connection_task
    ws = await self._http_session.ws_connect(
         ^^^^^^^^^^^^^^^^^^^^^^^^^^^^^^^^^^^^
  File "C:\Users\y.djemai\pam-testdrive\MARK_I\backend_python\agents\venv\Lib\site-packages\aiohttp\client.py", line 1067, in _ws_connect
    resp = await self.request(
           ^^^^^^^^^^^^^^^^^^^
  File "C:\Users\y.djemai\pam-testdrive\MARK_I\backend_python\agents\venv\Lib\site-packages\aiohttp\client.py", line 770, in _request
    resp = await handler(req)
           ^^^^^^^^^^^^^^^^^^
  File "C:\Users\y.djemai\pam-testdrive\MARK_I\backend_python\agents\venv\Lib\site-packages\aiohttp\client.py", line 725, in _connect_and_send_request
    conn = await self._connector.connect(
           ^^^^^^^^^^^^^^^^^^^^^^^^^^^^^^
  File "C:\Users\y.djemai\pam-testdrive\MARK_I\backend_python\agents\venv\Lib\site-packages\aiohttp\connector.py", line 642, in connect
    proto = await self._create_connection(req, traces, timeout)
            ^^^^^^^^^^^^^^^^^^^^^^^^^^^^^^^^^^^^^^^^^^^^^^^^^^^
  File "C:\Users\y.djemai\pam-testdrive\MARK_I\backend_python\agents\venv\Lib\site-packages\aiohttp\connector.py", line 1209, in _create_connection
    _, proto = await self._create_direct_connection(req, traces, timeout)
               ^^^^^^^^^^^^^^^^^^^^^^^^^^^^^^^^^^^^^^^^^^^^^^^^^^^^^^^^^^
  File "C:\Users\y.djemai\pam-testdrive\MARK_I\backend_python\agents\venv\Lib\site-packages\aiohttp\connector.py", line 1538, in _create_direct_connection
    raise ClientConnectorDNSError(req.connection_key, exc) from exc
aiohttp.client_exceptions.ClientConnectorDNSError: Cannot connect to host pamtestdrive-euxn3osq.livekit.cloud:443 ssl:default [getaddrinfo failed]
2025-08-04 09:06:29,502 - livekit.agents - WARNING - Running <TimerHandle when=551053.937 _finish_fut(<Future finished result=None>) at C:\Users\y.djemai\pam-testdrive\MARK_I\backend_python\agents\venv\Lib\site-packages\livekit\agents\utils\aio\interval.py:7> took too long: 10490.33 seconds
2025-08-04 09:06:29,504 - livekit.agents - WARNING - Running <TimerHandle when=551053.937 _finish_fut(<Future finished result=None>) at C:\Users\y.djemai\pam-testdrive\MARK_I\backend_python\agents\venv\Lib\site-packages\livekit\agents\utils\aio\interval.py:7> took too long: 10490.34 seconds
2025-08-04 09:06:29,504 - livekit.agents - WARNING - Running <TimerHandle when=551053.937 _finish_fut(<Future finished result=None>) at C:\Users\y.djemai\pam-testdrive\MARK_I\backend_python\agents\venv\Lib\site-packages\livekit\agents\utils\aio\interval.py:7> took too long: 10490.34 seconds
2025-08-04 09:06:29,608 - livekit.agents - WARNING - Running <TimerHandle when=551053.937 _finish_fut(<Future finished result=None>) at C:\Users\y.djemai\pam-testdrive\MARK_I\backend_python\agents\venv\Lib\site-packages\livekit\agents\utils\aio\interval.py:7> took too long: 10490.44 seconds
2025-08-04 09:06:29,609 - livekit.agents - WARNING - Running <TimerHandle when=551053.937 _finish_fut(<Future finished result=None>) at C:\Users\y.djemai\pam-testdrive\MARK_I\backend_python\agents\venv\Lib\site-packages\livekit\agents\utils\aio\interval.py:7> took too long: 10490.44 seconds
2025-08-04 09:06:29,609 - livekit.agents - WARNING - Running <TimerHandle when=551053.937 _finish_fut(<Future finished result=None>) at C:\Users\y.djemai\pam-testdrive\MARK_I\backend_python\agents\venv\Lib\site-packages\livekit\agents\utils\aio\interval.py:7> took too long: 10490.44 seconds
2025-08-04 09:06:29,622 - livekit.agents - WARNING - Running <TimerHandle when=551053.937 _finish_fut(<Future finished result=None>) at C:\Users\y.djemai\pam-testdrive\MARK_I\backend_python\agents\venv\Lib\site-packages\livekit\agents\utils\aio\interval.py:7> took too long: 10490.45 seconds
2025-08-04 09:06:29,622 - livekit.agents - WARNING - Running <TimerHandle when=551053.937 _finish_fut(<Future finished result=None>) at C:\Users\y.djemai\pam-testdrive\MARK_I\backend_python\agents\venv\Lib\site-packages\livekit\agents\utils\aio\interval.py:7> took too long: 10490.45 seconds
2025-08-04 09:06:29,624 - livekit.agents - WARNING - Running <TimerHandle when=551053.937 _finish_fut(<Future finished result=None>) at C:\Users\y.djemai\pam-testdrive\MARK_I\backend_python\agents\venv\Lib\site-packages\livekit\agents\utils\aio\interval.py:7> took too long: 10490.45 seconds
2025-08-04 09:06:29,627 - livekit.agents - WARNING - Running <TimerHandle when=551053.937 _finish_fut(<Future finished result=None>) at C:\Users\y.djemai\pam-testdrive\MARK_I\backend_python\agents\venv\Lib\site-packages\livekit\agents\utils\aio\interval.py:7> took too long: 10490.45 seconds
2025-08-04 09:06:29,627 - livekit.agents - WARNING - Running <TimerHandle when=551053.937 _finish_fut(<Future finished result=None>) at C:\Users\y.djemai\pam-testdrive\MARK_I\backend_python\agents\venv\Lib\site-packages\livekit\agents\utils\aio\interval.py:7> took too long: 10490.45 seconds
2025-08-04 09:06:29,627 - livekit.agents - WARNING - Running <TimerHandle when=551053.937 _finish_fut(<Future finished result=None>) at C:\Users\y.djemai\pam-testdrive\MARK_I\backend_python\agents\venv\Lib\site-packages\livekit\agents\utils\aio\interval.py:7> took too long: 10490.45 seconds
2025-08-04 09:06:29,628 - livekit.agents - WARNING - Running <TimerHandle when=551053.937 _finish_fut(<Future finished result=None>) at C:\Users\y.djemai\pam-testdrive\MARK_I\backend_python\agents\venv\Lib\site-packages\livekit\agents\utils\aio\interval.py:7> took too long: 10490.45 seconds
2025-08-04 09:06:29,628 - livekit.agents - WARNING - Running <TimerHandle when=551053.937 _finish_fut(<Future finished result=None>) at C:\Users\y.djemai\pam-testdrive\MARK_I\backend_python\agents\venv\Lib\site-packages\livekit\agents\utils\aio\interval.py:7> took too long: 10490.47 seconds
2025-08-04 09:06:29,645 - livekit.agents - WARNING - failed to connect to livekit, retrying in 6s
Traceback (most recent call last):
  File "C:\Users\y.djemai\pam-testdrive\MARK_I\backend_python\agents\venv\Lib\site-packages\aiohttp\connector.py", line 1532, in _create_direct_connection
    hosts = await self._resolve_host(host, port, traces=traces)
            ^^^^^^^^^^^^^^^^^^^^^^^^^^^^^^^^^^^^^^^^^^^^^^^^^^^
  File "C:\Users\y.djemai\pam-testdrive\MARK_I\backend_python\agents\venv\Lib\site-packages\aiohttp\connector.py", line 1148, in _resolve_host
    return await asyncio.shield(resolved_host_task)
           ^^^^^^^^^^^^^^^^^^^^^^^^^^^^^^^^^^^^^^^^
  File "C:\Users\y.djemai\pam-testdrive\MARK_I\backend_python\agents\venv\Lib\site-packages\aiohttp\connector.py", line 1179, in _resolve_host_with_throttle
    addrs = await self._resolver.resolve(host, port, family=self._family)
            ^^^^^^^^^^^^^^^^^^^^^^^^^^^^^^^^^^^^^^^^^^^^^^^^^^^^^^^^^^^^^
  File "C:\Users\y.djemai\pam-testdrive\MARK_I\backend_python\agents\venv\Lib\site-packages\aiohttp\resolver.py", line 40, in resolve
    infos = await self._loop.getaddrinfo(
            ^^^^^^^^^^^^^^^^^^^^^^^^^^^^^
  File "C:\Program Files\Python312\Lib\asyncio\base_events.py", line 901, in getaddrinfo
    return await self.run_in_executor(
           ^^^^^^^^^^^^^^^^^^^^^^^^^^^
  File "C:\Program Files\Python312\Lib\concurrent\futures\thread.py", line 58, in run
    result = self.fn(*self.args, **self.kwargs)
             ^^^^^^^^^^^^^^^^^^^^^^^^^^^^^^^^^^
  File "C:\Program Files\Python312\Lib\socket.py", line 963, in getaddrinfo
    for res in _socket.getaddrinfo(host, port, family, type, proto, flags):
               ^^^^^^^^^^^^^^^^^^^^^^^^^^^^^^^^^^^^^^^^^^^^^^^^^^^^^^^^^^^
socket.gaierror: [Errno 11001] getaddrinfo failed

The above exception was the direct cause of the following exception:

Traceback (most recent call last):
  File "C:\Users\y.djemai\pam-testdrive\MARK_I\backend_python\agents\venv\Lib\site-packages\livekit\agents\worker.py", line 653, in _connection_task
    ws = await self._http_session.ws_connect(
         ^^^^^^^^^^^^^^^^^^^^^^^^^^^^^^^^^^^^
  File "C:\Users\y.djemai\pam-testdrive\MARK_I\backend_python\agents\venv\Lib\site-packages\aiohttp\client.py", line 1067, in _ws_connect
    resp = await self.request(
           ^^^^^^^^^^^^^^^^^^^
  File "C:\Users\y.djemai\pam-testdrive\MARK_I\backend_python\agents\venv\Lib\site-packages\aiohttp\client.py", line 770, in _request
    resp = await handler(req)
           ^^^^^^^^^^^^^^^^^^
  File "C:\Users\y.djemai\pam-testdrive\MARK_I\backend_python\agents\venv\Lib\site-packages\aiohttp\client.py", line 725, in _connect_and_send_request
    conn = await self._connector.connect(
           ^^^^^^^^^^^^^^^^^^^^^^^^^^^^^^
  File "C:\Users\y.djemai\pam-testdrive\MARK_I\backend_python\agents\venv\Lib\site-packages\aiohttp\connector.py", line 642, in connect
    proto = await self._create_connection(req, traces, timeout)
            ^^^^^^^^^^^^^^^^^^^^^^^^^^^^^^^^^^^^^^^^^^^^^^^^^^^
  File "C:\Users\y.djemai\pam-testdrive\MARK_I\backend_python\agents\venv\Lib\site-packages\aiohttp\connector.py", line 1209, in _create_connection
    _, proto = await self._create_direct_connection(req, traces, timeout)
               ^^^^^^^^^^^^^^^^^^^^^^^^^^^^^^^^^^^^^^^^^^^^^^^^^^^^^^^^^^
  File "C:\Users\y.djemai\pam-testdrive\MARK_I\backend_python\agents\venv\Lib\site-packages\aiohttp\connector.py", line 1538, in _create_direct_connection
    raise ClientConnectorDNSError(req.connection_key, exc) from exc
aiohttp.client_exceptions.ClientConnectorDNSError: Cannot connect to host pamtestdrive-euxn3osq.livekit.cloud:443 ssl:default [getaddrinfo failed]
2025-08-04 09:06:36,482 - livekit.agents - WARNING - failed to connect to livekit, retrying in 8s
Traceback (most recent call last):
  File "C:\Users\y.djemai\pam-testdrive\MARK_I\backend_python\agents\venv\Lib\site-packages\aiohttp\connector.py", line 1532, in _create_direct_connection
    hosts = await self._resolve_host(host, port, traces=traces)
            ^^^^^^^^^^^^^^^^^^^^^^^^^^^^^^^^^^^^^^^^^^^^^^^^^^^
  File "C:\Users\y.djemai\pam-testdrive\MARK_I\backend_python\agents\venv\Lib\site-packages\aiohttp\connector.py", line 1148, in _resolve_host
    return await asyncio.shield(resolved_host_task)
           ^^^^^^^^^^^^^^^^^^^^^^^^^^^^^^^^^^^^^^^^
  File "C:\Users\y.djemai\pam-testdrive\MARK_I\backend_python\agents\venv\Lib\site-packages\aiohttp\connector.py", line 1179, in _resolve_host_with_throttle
    addrs = await self._resolver.resolve(host, port, family=self._family)
            ^^^^^^^^^^^^^^^^^^^^^^^^^^^^^^^^^^^^^^^^^^^^^^^^^^^^^^^^^^^^^
  File "C:\Users\y.djemai\pam-testdrive\MARK_I\backend_python\agents\venv\Lib\site-packages\aiohttp\resolver.py", line 40, in resolve
    infos = await self._loop.getaddrinfo(
            ^^^^^^^^^^^^^^^^^^^^^^^^^^^^^
  File "C:\Program Files\Python312\Lib\asyncio\base_events.py", line 901, in getaddrinfo
    return await self.run_in_executor(
           ^^^^^^^^^^^^^^^^^^^^^^^^^^^
  File "C:\Program Files\Python312\Lib\concurrent\futures\thread.py", line 58, in run
    result = self.fn(*self.args, **self.kwargs)
             ^^^^^^^^^^^^^^^^^^^^^^^^^^^^^^^^^^
  File "C:\Program Files\Python312\Lib\socket.py", line 963, in getaddrinfo
    for res in _socket.getaddrinfo(host, port, family, type, proto, flags):
               ^^^^^^^^^^^^^^^^^^^^^^^^^^^^^^^^^^^^^^^^^^^^^^^^^^^^^^^^^^^
socket.gaierror: [Errno 11001] getaddrinfo failed

The above exception was the direct cause of the following exception:

Traceback (most recent call last):
  File "C:\Users\y.djemai\pam-testdrive\MARK_I\backend_python\agents\venv\Lib\site-packages\livekit\agents\worker.py", line 653, in _connection_task
    ws = await self._http_session.ws_connect(
         ^^^^^^^^^^^^^^^^^^^^^^^^^^^^^^^^^^^^
  File "C:\Users\y.djemai\pam-testdrive\MARK_I\backend_python\agents\venv\Lib\site-packages\aiohttp\client.py", line 1067, in _ws_connect
    resp = await self.request(
           ^^^^^^^^^^^^^^^^^^^
  File "C:\Users\y.djemai\pam-testdrive\MARK_I\backend_python\agents\venv\Lib\site-packages\aiohttp\client.py", line 770, in _request
    resp = await handler(req)
           ^^^^^^^^^^^^^^^^^^
  File "C:\Users\y.djemai\pam-testdrive\MARK_I\backend_python\agents\venv\Lib\site-packages\aiohttp\client.py", line 725, in _connect_and_send_request
    conn = await self._connector.connect(
           ^^^^^^^^^^^^^^^^^^^^^^^^^^^^^^
  File "C:\Users\y.djemai\pam-testdrive\MARK_I\backend_python\agents\venv\Lib\site-packages\aiohttp\connector.py", line 642, in connect
    proto = await self._create_connection(req, traces, timeout)
            ^^^^^^^^^^^^^^^^^^^^^^^^^^^^^^^^^^^^^^^^^^^^^^^^^^^
  File "C:\Users\y.djemai\pam-testdrive\MARK_I\backend_python\agents\venv\Lib\site-packages\aiohttp\connector.py", line 1209, in _create_connection
    _, proto = await self._create_direct_connection(req, traces, timeout)
               ^^^^^^^^^^^^^^^^^^^^^^^^^^^^^^^^^^^^^^^^^^^^^^^^^^^^^^^^^^
  File "C:\Users\y.djemai\pam-testdrive\MARK_I\backend_python\agents\venv\Lib\site-packages\aiohttp\connector.py", line 1538, in _create_direct_connection
    raise ClientConnectorDNSError(req.connection_key, exc) from exc
aiohttp.client_exceptions.ClientConnectorDNSError: Cannot connect to host pamtestdrive-euxn3osq.livekit.cloud:443 ssl:default [getaddrinfo failed]
2025-08-04 09:06:38,856 - livekit.agents - WARNING - Running <Task pending name='worker_conn_task' coro=<Worker._connection_task() running at C:\Users\y.djemai\pam-testdrive\MARK_I\backend_python\agents\venv\Lib\site-packages\livekit\agents\utils\log.py:16> wait_for=<Future pending cb=[Task.task_wakeup()]> cb=[gather.<locals>._done_callback() at C:\Program Files\Python312\Lib\asyncio\tasks.py:767]> took too long: 2.38 seconds
2025-08-04 09:06:39,008 - livekit.agents - WARNING - Running <Task pending name='worker_conn_task' coro=<Worker._connection_task() running at C:\Users\y.djemai\pam-testdrive\MARK_I\backend_python\agents\venv\Lib\site-packages\livekit\agents\utils\log.py:16> wait_for=<Future pending cb=[Task.task_wakeup()]> cb=[gather.<locals>._done_callback() at C:\Program Files\Python312\Lib\asyncio\tasks.py:767]> took too long: 2.53 seconds
2025-08-04 09:06:39,010 - livekit.agents - WARNING - Running <Task pending name='worker_conn_task' coro=<Worker._connection_task() running at C:\Users\y.djemai\pam-testdrive\MARK_I\backend_python\agents\venv\Lib\site-packages\livekit\agents\utils\log.py:16> wait_for=<Future pending cb=[Task.task_wakeup()]> cb=[gather.<locals>._done_callback() at C:\Program Files\Python312\Lib\asyncio\tasks.py:767]> took too long: 2.53 seconds
2025-08-04 09:06:39,310 - livekit.agents - WARNING - Running <Task pending name='worker_conn_task' coro=<Worker._connection_task() running at C:\Users\y.djemai\pam-testdrive\MARK_I\backend_python\agents\venv\Lib\site-packages\livekit\agents\utils\log.py:16> wait_for=<Future pending cb=[Task.task_wakeup()]> cb=[gather.<locals>._done_callback() at C:\Program Files\Python312\Lib\asyncio\tasks.py:767]> took too long: 2.83 seconds
2025-08-04 09:06:39,554 - livekit.agents - WARNING - Running <Task pending name='worker_conn_task' coro=<Worker._connection_task() running at C:\Users\y.djemai\pam-testdrive\MARK_I\backend_python\agents\venv\Lib\site-packages\livekit\agents\utils\log.py:16> wait_for=<Future pending cb=[Task.task_wakeup()]> cb=[gather.<locals>._done_callback() at C:\Program Files\Python312\Lib\asyncio\tasks.py:767]> took too long: 3.08 seconds
2025-08-04 09:06:39,554 - livekit.agents - WARNING - Running <Task pending name='worker_conn_task' coro=<Worker._connection_task() running at C:\Users\y.djemai\pam-testdrive\MARK_I\backend_python\agents\venv\Lib\site-packages\livekit\agents\utils\log.py:16> wait_for=<Future pending cb=[Task.task_wakeup()]> cb=[gather.<locals>._done_callback() at C:\Program Files\Python312\Lib\asyncio\tasks.py:767]> took too long: 3.08 seconds
2025-08-04 09:06:39,990 - livekit.agents - WARNING - Running <Task pending name='worker_conn_task' coro=<Worker._connection_task() running at C:\Users\y.djemai\pam-testdrive\MARK_I\backend_python\agents\venv\Lib\site-packages\livekit\agents\utils\log.py:16> wait_for=<Future pending cb=[Task.task_wakeup()]> cb=[gather.<locals>._done_callback() at C:\Program Files\Python312\Lib\asyncio\tasks.py:767]> took too long: 3.33 seconds
2025-08-04 09:06:42,024 - livekit.agents - WARNING - Running <Task pending name='worker_conn_task' coro=<Worker._connection_task() running at C:\Users\y.djemai\pam-testdrive\MARK_I\backend_python\agents\venv\Lib\site-packages\livekit\agents\utils\log.py:16> wait_for=<Future pending cb=[Task.task_wakeup()]> cb=[gather.<locals>._done_callback() at C:\Program Files\Python312\Lib\asyncio\tasks.py:767]> took too long: 5.55 seconds
2025-08-04 09:06:42,025 - livekit.agents - WARNING - Running <Task pending name='worker_conn_task' coro=<Worker._connection_task() running at C:\Users\y.djemai\pam-testdrive\MARK_I\backend_python\agents\venv\Lib\site-packages\livekit\agents\utils\log.py:16> wait_for=<Future pending cb=[Task.task_wakeup()]> cb=[gather.<locals>._done_callback() at C:\Program Files\Python312\Lib\asyncio\tasks.py:767]> took too long: 5.55 seconds
2025-08-04 09:06:42,148 - livekit.agents - WARNING - Running <Task pending name='worker_conn_task' coro=<Worker._connection_task() running at C:\Users\y.djemai\pam-testdrive\MARK_I\backend_python\agents\venv\Lib\site-packages\livekit\agents\utils\log.py:16> wait_for=<Future pending cb=[Task.task_wakeup()]> cb=[gather.<locals>._done_callback() at C:\Program Files\Python312\Lib\asyncio\tasks.py:767]> took too long: 5.67 seconds
2025-08-04 09:06:42,235 - livekit.agents - WARNING - Running <Task pending name='worker_conn_task' coro=<Worker._connection_task() running at C:\Users\y.djemai\pam-testdrive\MARK_I\backend_python\agents\venv\Lib\site-packages\livekit\agents\utils\log.py:16> wait_for=<Future pending cb=[Task.task_wakeup()]> cb=[gather.<locals>._done_callback() at C:\Program Files\Python312\Lib\asyncio\tasks.py:767]> took too long: 5.75 seconds
2025-08-04 09:06:42,307 - livekit.agents - WARNING - Running <Task pending name='worker_conn_task' coro=<Worker._connection_task() running at C:\Users\y.djemai\pam-testdrive\MARK_I\backend_python\agents\venv\Lib\site-packages\livekit\agents\utils\log.py:16> wait_for=<Future pending cb=[Task.task_wakeup()]> cb=[gather.<locals>._done_callback() at C:\Program Files\Python312\Lib\asyncio\tasks.py:767]> took too long: 5.75 seconds
2025-08-04 09:06:42,394 - livekit.agents - WARNING - Running <Task pending name='worker_conn_task' coro=<Worker._connection_task() running at C:\Users\y.djemai\pam-testdrive\MARK_I\backend_python\agents\venv\Lib\site-packages\livekit\agents\utils\log.py:16> wait_for=<Future pending cb=[Task.task_wakeup()]> cb=[gather.<locals>._done_callback() at C:\Program Files\Python312\Lib\asyncio\tasks.py:767]> took too long: 5.83 seconds
2025-08-04 09:06:42,492 - livekit.agents - WARNING - Running <Task pending name='worker_conn_task' coro=<Worker._connection_task() running at C:\Users\y.djemai\pam-testdrive\MARK_I\backend_python\agents\venv\Lib\site-packages\livekit\agents\utils\log.py:16> wait_for=<Future pending cb=[Task.task_wakeup()]> cb=[gather.<locals>._done_callback() at C:\Program Files\Python312\Lib\asyncio\tasks.py:767]> took too long: 5.92 seconds
2025-08-04 09:06:44,723 - livekit.agents - WARNING - job executor is unresponsive
2025-08-04 09:06:44,831 - livekit.agents - WARNING - job executor is unresponsive
2025-08-04 09:06:44,900 - livekit.agents - WARNING - job executor is unresponsive
2025-08-04 09:06:44,903 - livekit.agents - WARNING - job executor is unresponsive
2025-08-04 09:06:46,252 - livekit.agents - WARNING - job executor is unresponsive
2025-08-04 09:06:46,415 - livekit.agents - WARNING - job executor is unresponsive
2025-08-04 09:06:46,525 - livekit.agents - WARNING - job executor is unresponsive
2025-08-04 09:06:46,624 - livekit.agents - WARNING - job executor is unresponsive
2025-08-04 09:06:46,729 - livekit.agents - WARNING - job executor is unresponsive
2025-08-04 09:06:46,934 - livekit.agents - WARNING - job executor is unresponsive
2025-08-04 09:06:47,905 - livekit.agents - WARNING - job executor is unresponsive
2025-08-04 09:06:48,278 - livekit.agents - WARNING - job executor is unresponsive
2025-08-04 09:06:49,246 - livekit.agents - WARNING - job executor is unresponsive
2025-08-04 09:06:49,323 - livekit.agents - WARNING - job executor is unresponsive
2025-08-04 09:06:49,323 - livekit.agents - WARNING - job executor is unresponsive
2025-08-04 09:06:49,463 - livekit.agents - WARNING - job executor is unresponsive
2025-08-04 09:06:49,467 - livekit.agents - WARNING - job executor is unresponsive
2025-08-04 09:06:49,521 - livekit.agents - WARNING - job executor is unresponsive
2025-08-04 09:06:49,564 - livekit.agents - WARNING - job executor is unresponsive
2025-08-04 09:06:49,602 - livekit.agents - WARNING - job executor is unresponsive
2025-08-04 09:06:49,642 - livekit.agents - WARNING - job executor is unresponsive
2025-08-04 09:06:49,687 - livekit.agents - WARNING - job executor is unresponsive
2025-08-04 09:06:49,722 - livekit.agents - WARNING - job executor is unresponsive
2025-08-04 09:06:49,800 - livekit.agents - WARNING - failed to connect to livekit, retrying in 10s
Traceback (most recent call last):
  File "C:\Users\y.djemai\pam-testdrive\MARK_I\backend_python\agents\venv\Lib\site-packages\aiohttp\connector.py", line 1532, in _create_direct_connection
    hosts = await self._resolve_host(host, port, traces=traces)
            ^^^^^^^^^^^^^^^^^^^^^^^^^^^^^^^^^^^^^^^^^^^^^^^^^^^
  File "C:\Users\y.djemai\pam-testdrive\MARK_I\backend_python\agents\venv\Lib\site-packages\aiohttp\connector.py", line 1148, in _resolve_host
    return await asyncio.shield(resolved_host_task)
           ^^^^^^^^^^^^^^^^^^^^^^^^^^^^^^^^^^^^^^^^
  File "C:\Users\y.djemai\pam-testdrive\MARK_I\backend_python\agents\venv\Lib\site-packages\aiohttp\connector.py", line 1179, in _resolve_host_with_throttle
    addrs = await self._resolver.resolve(host, port, family=self._family)
            ^^^^^^^^^^^^^^^^^^^^^^^^^^^^^^^^^^^^^^^^^^^^^^^^^^^^^^^^^^^^^
  File "C:\Users\y.djemai\pam-testdrive\MARK_I\backend_python\agents\venv\Lib\site-packages\aiohttp\resolver.py", line 40, in resolve
    infos = await self._loop.getaddrinfo(
            ^^^^^^^^^^^^^^^^^^^^^^^^^^^^^
  File "C:\Program Files\Python312\Lib\asyncio\base_events.py", line 901, in getaddrinfo
    return await self.run_in_executor(
           ^^^^^^^^^^^^^^^^^^^^^^^^^^^
  File "C:\Program Files\Python312\Lib\concurrent\futures\thread.py", line 58, in run
    result = self.fn(*self.args, **self.kwargs)
             ^^^^^^^^^^^^^^^^^^^^^^^^^^^^^^^^^^
  File "C:\Program Files\Python312\Lib\socket.py", line 963, in getaddrinfo
    for res in _socket.getaddrinfo(host, port, family, type, proto, flags):
               ^^^^^^^^^^^^^^^^^^^^^^^^^^^^^^^^^^^^^^^^^^^^^^^^^^^^^^^^^^^
socket.gaierror: [Errno 11001] getaddrinfo failed

The above exception was the direct cause of the following exception:

Traceback (most recent call last):
  File "C:\Users\y.djemai\pam-testdrive\MARK_I\backend_python\agents\venv\Lib\site-packages\livekit\agents\worker.py", line 653, in _connection_task
    ws = await self._http_session.ws_connect(
         ^^^^^^^^^^^^^^^^^^^^^^^^^^^^^^^^^^^^
  File "C:\Users\y.djemai\pam-testdrive\MARK_I\backend_python\agents\venv\Lib\site-packages\aiohttp\client.py", line 1067, in _ws_connect
    resp = await self.request(
           ^^^^^^^^^^^^^^^^^^^
  File "C:\Users\y.djemai\pam-testdrive\MARK_I\backend_python\agents\venv\Lib\site-packages\aiohttp\client.py", line 770, in _request
    resp = await handler(req)
           ^^^^^^^^^^^^^^^^^^
  File "C:\Users\y.djemai\pam-testdrive\MARK_I\backend_python\agents\venv\Lib\site-packages\aiohttp\client.py", line 725, in _connect_and_send_request
    conn = await self._connector.connect(
           ^^^^^^^^^^^^^^^^^^^^^^^^^^^^^^
  File "C:\Users\y.djemai\pam-testdrive\MARK_I\backend_python\agents\venv\Lib\site-packages\aiohttp\connector.py", line 642, in connect
    proto = await self._create_connection(req, traces, timeout)
            ^^^^^^^^^^^^^^^^^^^^^^^^^^^^^^^^^^^^^^^^^^^^^^^^^^^
  File "C:\Users\y.djemai\pam-testdrive\MARK_I\backend_python\agents\venv\Lib\site-packages\aiohttp\connector.py", line 1209, in _create_connection
    _, proto = await self._create_direct_connection(req, traces, timeout)
               ^^^^^^^^^^^^^^^^^^^^^^^^^^^^^^^^^^^^^^^^^^^^^^^^^^^^^^^^^^
  File "C:\Users\y.djemai\pam-testdrive\MARK_I\backend_python\agents\venv\Lib\site-packages\aiohttp\connector.py", line 1538, in _create_direct_connection
    raise ClientConnectorDNSError(req.connection_key, exc) from exc
aiohttp.client_exceptions.ClientConnectorDNSError: Cannot connect to host pamtestdrive-euxn3osq.livekit.cloud:443 ssl:default [getaddrinfo failed]
2025-08-04 09:06:51,955 - livekit.agents - WARNING - job executor is unresponsive
2025-08-04 09:06:51,960 - livekit.agents - WARNING - job executor is unresponsive
2025-08-04 09:06:52,003 - livekit.agents - WARNING - job executor is unresponsive
2025-08-04 09:06:52,005 - livekit.agents - WARNING - job executor is unresponsive
2025-08-04 09:06:52,034 - livekit.agents - WARNING - job executor is unresponsive
2025-08-04 09:06:52,155 - livekit.agents - WARNING - job executor is unresponsive
2025-08-04 09:06:52,190 - livekit.agents - WARNING - job executor is unresponsive
2025-08-04 09:06:52,277 - livekit.agents - WARNING - job executor is unresponsive
2025-08-04 09:06:52,279 - livekit.agents - WARNING - job executor is unresponsive
2025-08-04 09:06:52,280 - livekit.agents - WARNING - job executor is unresponsive
2025-08-04 09:06:52,302 - livekit.agents - WARNING - job executor is unresponsive
2025-08-04 09:06:52,345 - livekit.agents - WARNING - job executor is unresponsive
2025-08-04 18:09:40,608 - livekit.agents - WARNING - failed to connect to livekit, retrying in 0s
Traceback (most recent call last):
  File "C:\Users\y.djemai\pam-testdrive\MARK_I\backend_python\agents\venv\Lib\site-packages\livekit\agents\worker.py", line 692, in _connection_task
    await self._run_ws(ws)
  File "C:\Users\y.djemai\pam-testdrive\MARK_I\backend_python\agents\venv\Lib\site-packages\livekit\agents\worker.py", line 773, in _run_ws
    await asyncio.gather(*tasks)
  File "C:\Users\y.djemai\pam-testdrive\MARK_I\backend_python\agents\venv\Lib\site-packages\livekit\agents\worker.py", line 745, in _recv_task
    raise Exception("worker connection closed unexpectedly")
Exception: worker connection closed unexpectedly
2025-08-04 18:29:34,609 - livekit.agents - WARNING - Running <Task pending name='worker_conn_task' coro=<Worker._connection_task() running at C:\Users\y.djemai\pam-testdrive\MARK_I\backend_python\agents\venv\Lib\site-packages\livekit\agents\utils\log.py:16> cb=[gather.<locals>._done_callback() at C:\Program Files\Python312\Lib\asyncio\tasks.py:767]> took too long: 1194.00 seconds
2025-08-04 18:29:34,611 - livekit.agents - WARNING - Running <Task pending name='worker_conn_task' coro=<Worker._connection_task() running at C:\Users\y.djemai\pam-testdrive\MARK_I\backend_python\agents\venv\Lib\site-packages\livekit\agents\utils\log.py:16> cb=[gather.<locals>._done_callback() at C:\Program Files\Python312\Lib\asyncio\tasks.py:767]> took too long: 1194.00 seconds
2025-08-04 18:29:34,734 - livekit.agents - WARNING - Running <Task pending name='worker_conn_task' coro=<Worker._connection_task() running at C:\Users\y.djemai\pam-testdrive\MARK_I\backend_python\agents\venv\Lib\site-packages\livekit\agents\utils\log.py:16> cb=[gather.<locals>._done_callback() at C:\Program Files\Python312\Lib\asyncio\tasks.py:767]> took too long: 1194.11 seconds
2025-08-04 18:29:34,734 - livekit.agents - WARNING - Running <Task pending name='worker_conn_task' coro=<Worker._connection_task() running at C:\Users\y.djemai\pam-testdrive\MARK_I\backend_python\agents\venv\Lib\site-packages\livekit\agents\utils\log.py:16> cb=[gather.<locals>._done_callback() at C:\Program Files\Python312\Lib\asyncio\tasks.py:767]> took too long: 1194.12 seconds
2025-08-04 18:29:35,006 - livekit.agents - WARNING - Running <Task pending name='worker_conn_task' coro=<Worker._connection_task() running at C:\Users\y.djemai\pam-testdrive\MARK_I\backend_python\agents\venv\Lib\site-packages\livekit\agents\utils\log.py:16> cb=[gather.<locals>._done_callback() at C:\Program Files\Python312\Lib\asyncio\tasks.py:767]> took too long: 1194.39 seconds
2025-08-04 18:29:35,008 - livekit.agents - WARNING - Running <Task pending name='worker_conn_task' coro=<Worker._connection_task() running at C:\Users\y.djemai\pam-testdrive\MARK_I\backend_python\agents\venv\Lib\site-packages\livekit\agents\utils\log.py:16> cb=[gather.<locals>._done_callback() at C:\Program Files\Python312\Lib\asyncio\tasks.py:767]> took too long: 1194.39 seconds
2025-08-04 18:29:35,221 - livekit.agents - WARNING - Running <Task pending name='worker_conn_task' coro=<Worker._connection_task() running at C:\Users\y.djemai\pam-testdrive\MARK_I\backend_python\agents\venv\Lib\site-packages\livekit\agents\utils\log.py:16> cb=[gather.<locals>._done_callback() at C:\Program Files\Python312\Lib\asyncio\tasks.py:767]> took too long: 1194.61 seconds
2025-08-04 18:29:35,373 - livekit.agents - WARNING - Running <Task pending name='worker_conn_task' coro=<Worker._connection_task() running at C:\Users\y.djemai\pam-testdrive\MARK_I\backend_python\agents\venv\Lib\site-packages\livekit\agents\utils\log.py:16> cb=[gather.<locals>._done_callback() at C:\Program Files\Python312\Lib\asyncio\tasks.py:767]> took too long: 1194.75 seconds
2025-08-04 18:29:35,516 - livekit.agents - WARNING - Running <Task pending name='worker_conn_task' coro=<Worker._connection_task() running at C:\Users\y.djemai\pam-testdrive\MARK_I\backend_python\agents\venv\Lib\site-packages\livekit\agents\utils\log.py:16> cb=[gather.<locals>._done_callback() at C:\Program Files\Python312\Lib\asyncio\tasks.py:767]> took too long: 1194.91 seconds
2025-08-04 18:29:35,764 - livekit.agents - WARNING - Running <Task pending name='worker_conn_task' coro=<Worker._connection_task() running at C:\Users\y.djemai\pam-testdrive\MARK_I\backend_python\agents\venv\Lib\site-packages\livekit\agents\utils\log.py:16> cb=[gather.<locals>._done_callback() at C:\Program Files\Python312\Lib\asyncio\tasks.py:767]> took too long: 1195.16 seconds
2025-08-04 18:29:35,977 - livekit.agents - WARNING - Running <Task pending name='worker_conn_task' coro=<Worker._connection_task() running at C:\Users\y.djemai\pam-testdrive\MARK_I\backend_python\agents\venv\Lib\site-packages\livekit\agents\utils\log.py:16> cb=[gather.<locals>._done_callback() at C:\Program Files\Python312\Lib\asyncio\tasks.py:767]> took too long: 1195.36 seconds
2025-08-04 18:29:36,066 - livekit.agents - WARNING - Running <Task pending name='worker_conn_task' coro=<Worker._connection_task() running at C:\Users\y.djemai\pam-testdrive\MARK_I\backend_python\agents\venv\Lib\site-packages\livekit\agents\utils\log.py:16> cb=[gather.<locals>._done_callback() at C:\Program Files\Python312\Lib\asyncio\tasks.py:767]> took too long: 1195.45 seconds
2025-08-04 18:29:36,068 - livekit.agents - WARNING - Running <Task pending name='worker_conn_task' coro=<Worker._connection_task() running at C:\Users\y.djemai\pam-testdrive\MARK_I\backend_python\agents\venv\Lib\site-packages\livekit\agents\utils\log.py:16> cb=[gather.<locals>._done_callback() at C:\Program Files\Python312\Lib\asyncio\tasks.py:767]> took too long: 1195.45 seconds
2025-08-04 18:29:36,144 - livekit.agents - WARNING - Running <Task pending name='worker_conn_task' coro=<Worker._connection_task() running at C:\Users\y.djemai\pam-testdrive\MARK_I\backend_python\agents\venv\Lib\site-packages\livekit\agents\utils\log.py:16> cb=[gather.<locals>._done_callback() at C:\Program Files\Python312\Lib\asyncio\tasks.py:767]> took too long: 1195.53 seconds
2025-08-04 18:29:41,356 - livekit.agents - WARNING - failed to connect to livekit, retrying in 2s
Traceback (most recent call last):
  File "C:\Users\y.djemai\pam-testdrive\MARK_I\backend_python\agents\venv\Lib\site-packages\aiohttp\connector.py", line 1532, in _create_direct_connection
    hosts = await self._resolve_host(host, port, traces=traces)
            ^^^^^^^^^^^^^^^^^^^^^^^^^^^^^^^^^^^^^^^^^^^^^^^^^^^
  File "C:\Users\y.djemai\pam-testdrive\MARK_I\backend_python\agents\venv\Lib\site-packages\aiohttp\connector.py", line 1148, in _resolve_host
    return await asyncio.shield(resolved_host_task)
           ^^^^^^^^^^^^^^^^^^^^^^^^^^^^^^^^^^^^^^^^
  File "C:\Users\y.djemai\pam-testdrive\MARK_I\backend_python\agents\venv\Lib\site-packages\aiohttp\connector.py", line 1179, in _resolve_host_with_throttle
    addrs = await self._resolver.resolve(host, port, family=self._family)
            ^^^^^^^^^^^^^^^^^^^^^^^^^^^^^^^^^^^^^^^^^^^^^^^^^^^^^^^^^^^^^
  File "C:\Users\y.djemai\pam-testdrive\MARK_I\backend_python\agents\venv\Lib\site-packages\aiohttp\resolver.py", line 40, in resolve
    infos = await self._loop.getaddrinfo(
            ^^^^^^^^^^^^^^^^^^^^^^^^^^^^^
  File "C:\Program Files\Python312\Lib\asyncio\base_events.py", line 901, in getaddrinfo
    return await self.run_in_executor(
           ^^^^^^^^^^^^^^^^^^^^^^^^^^^
  File "C:\Program Files\Python312\Lib\concurrent\futures\thread.py", line 58, in run
    result = self.fn(*self.args, **self.kwargs)
             ^^^^^^^^^^^^^^^^^^^^^^^^^^^^^^^^^^
  File "C:\Program Files\Python312\Lib\socket.py", line 963, in getaddrinfo
    for res in _socket.getaddrinfo(host, port, family, type, proto, flags):
               ^^^^^^^^^^^^^^^^^^^^^^^^^^^^^^^^^^^^^^^^^^^^^^^^^^^^^^^^^^^
socket.gaierror: [Errno 11001] getaddrinfo failed

The above exception was the direct cause of the following exception:

Traceback (most recent call last):
  File "C:\Users\y.djemai\pam-testdrive\MARK_I\backend_python\agents\venv\Lib\site-packages\livekit\agents\worker.py", line 653, in _connection_task
    ws = await self._http_session.ws_connect(
         ^^^^^^^^^^^^^^^^^^^^^^^^^^^^^^^^^^^^
  File "C:\Users\y.djemai\pam-testdrive\MARK_I\backend_python\agents\venv\Lib\site-packages\aiohttp\client.py", line 1067, in _ws_connect
    resp = await self.request(
           ^^^^^^^^^^^^^^^^^^^
  File "C:\Users\y.djemai\pam-testdrive\MARK_I\backend_python\agents\venv\Lib\site-packages\aiohttp\client.py", line 770, in _request
    resp = await handler(req)
           ^^^^^^^^^^^^^^^^^^
  File "C:\Users\y.djemai\pam-testdrive\MARK_I\backend_python\agents\venv\Lib\site-packages\aiohttp\client.py", line 725, in _connect_and_send_request
    conn = await self._connector.connect(
           ^^^^^^^^^^^^^^^^^^^^^^^^^^^^^^
  File "C:\Users\y.djemai\pam-testdrive\MARK_I\backend_python\agents\venv\Lib\site-packages\aiohttp\connector.py", line 642, in connect
    proto = await self._create_connection(req, traces, timeout)
            ^^^^^^^^^^^^^^^^^^^^^^^^^^^^^^^^^^^^^^^^^^^^^^^^^^^
  File "C:\Users\y.djemai\pam-testdrive\MARK_I\backend_python\agents\venv\Lib\site-packages\aiohttp\connector.py", line 1209, in _create_connection
    _, proto = await self._create_direct_connection(req, traces, timeout)
               ^^^^^^^^^^^^^^^^^^^^^^^^^^^^^^^^^^^^^^^^^^^^^^^^^^^^^^^^^^
  File "C:\Users\y.djemai\pam-testdrive\MARK_I\backend_python\agents\venv\Lib\site-packages\aiohttp\connector.py", line 1538, in _create_direct_connection
    raise ClientConnectorDNSError(req.connection_key, exc) from exc
aiohttp.client_exceptions.ClientConnectorDNSError: Cannot connect to host pamtestdrive-euxn3osq.livekit.cloud:443 ssl:default [getaddrinfo failed]
2025-08-04 18:43:44,325 - livekit.agents - WARNING - failed to connect to livekit, retrying in 4s
Traceback (most recent call last):
  File "C:\Users\y.djemai\pam-testdrive\MARK_I\backend_python\agents\venv\Lib\site-packages\aiohttp\connector.py", line 1532, in _create_direct_connection
    hosts = await self._resolve_host(host, port, traces=traces)
            ^^^^^^^^^^^^^^^^^^^^^^^^^^^^^^^^^^^^^^^^^^^^^^^^^^^
  File "C:\Users\y.djemai\pam-testdrive\MARK_I\backend_python\agents\venv\Lib\site-packages\aiohttp\connector.py", line 1148, in _resolve_host
    return await asyncio.shield(resolved_host_task)
           ^^^^^^^^^^^^^^^^^^^^^^^^^^^^^^^^^^^^^^^^
  File "C:\Users\y.djemai\pam-testdrive\MARK_I\backend_python\agents\venv\Lib\site-packages\aiohttp\connector.py", line 1179, in _resolve_host_with_throttle
    addrs = await self._resolver.resolve(host, port, family=self._family)
            ^^^^^^^^^^^^^^^^^^^^^^^^^^^^^^^^^^^^^^^^^^^^^^^^^^^^^^^^^^^^^
  File "C:\Users\y.djemai\pam-testdrive\MARK_I\backend_python\agents\venv\Lib\site-packages\aiohttp\resolver.py", line 40, in resolve
    infos = await self._loop.getaddrinfo(
            ^^^^^^^^^^^^^^^^^^^^^^^^^^^^^
  File "C:\Program Files\Python312\Lib\asyncio\base_events.py", line 901, in getaddrinfo
    return await self.run_in_executor(
           ^^^^^^^^^^^^^^^^^^^^^^^^^^^
  File "C:\Program Files\Python312\Lib\concurrent\futures\thread.py", line 58, in run
    result = self.fn(*self.args, **self.kwargs)
             ^^^^^^^^^^^^^^^^^^^^^^^^^^^^^^^^^^
  File "C:\Program Files\Python312\Lib\socket.py", line 963, in getaddrinfo
    for res in _socket.getaddrinfo(host, port, family, type, proto, flags):
               ^^^^^^^^^^^^^^^^^^^^^^^^^^^^^^^^^^^^^^^^^^^^^^^^^^^^^^^^^^^
socket.gaierror: [Errno 11001] getaddrinfo failed

The above exception was the direct cause of the following exception:

Traceback (most recent call last):
  File "C:\Users\y.djemai\pam-testdrive\MARK_I\backend_python\agents\venv\Lib\site-packages\livekit\agents\worker.py", line 653, in _connection_task
    ws = await self._http_session.ws_connect(
         ^^^^^^^^^^^^^^^^^^^^^^^^^^^^^^^^^^^^
  File "C:\Users\y.djemai\pam-testdrive\MARK_I\backend_python\agents\venv\Lib\site-packages\aiohttp\client.py", line 1067, in _ws_connect
    resp = await self.request(
           ^^^^^^^^^^^^^^^^^^^
  File "C:\Users\y.djemai\pam-testdrive\MARK_I\backend_python\agents\venv\Lib\site-packages\aiohttp\client.py", line 770, in _request
    resp = await handler(req)
           ^^^^^^^^^^^^^^^^^^
  File "C:\Users\y.djemai\pam-testdrive\MARK_I\backend_python\agents\venv\Lib\site-packages\aiohttp\client.py", line 725, in _connect_and_send_request
    conn = await self._connector.connect(
           ^^^^^^^^^^^^^^^^^^^^^^^^^^^^^^
  File "C:\Users\y.djemai\pam-testdrive\MARK_I\backend_python\agents\venv\Lib\site-packages\aiohttp\connector.py", line 642, in connect
    proto = await self._create_connection(req, traces, timeout)
            ^^^^^^^^^^^^^^^^^^^^^^^^^^^^^^^^^^^^^^^^^^^^^^^^^^^
  File "C:\Users\y.djemai\pam-testdrive\MARK_I\backend_python\agents\venv\Lib\site-packages\aiohttp\connector.py", line 1209, in _create_connection
    _, proto = await self._create_direct_connection(req, traces, timeout)
               ^^^^^^^^^^^^^^^^^^^^^^^^^^^^^^^^^^^^^^^^^^^^^^^^^^^^^^^^^^
  File "C:\Users\y.djemai\pam-testdrive\MARK_I\backend_python\agents\venv\Lib\site-packages\aiohttp\connector.py", line 1538, in _create_direct_connection
    raise ClientConnectorDNSError(req.connection_key, exc) from exc
aiohttp.client_exceptions.ClientConnectorDNSError: Cannot connect to host pamtestdrive-euxn3osq.livekit.cloud:443 ssl:default [getaddrinfo failed]
2025-08-04 18:44:02,925 - livekit.agents - WARNING - failed to connect to livekit, retrying in 6s
Traceback (most recent call last):
  File "C:\Users\y.djemai\pam-testdrive\MARK_I\backend_python\agents\venv\Lib\site-packages\aiohttp\connector.py", line 1532, in _create_direct_connection
    hosts = await self._resolve_host(host, port, traces=traces)
            ^^^^^^^^^^^^^^^^^^^^^^^^^^^^^^^^^^^^^^^^^^^^^^^^^^^
  File "C:\Users\y.djemai\pam-testdrive\MARK_I\backend_python\agents\venv\Lib\site-packages\aiohttp\connector.py", line 1148, in _resolve_host
    return await asyncio.shield(resolved_host_task)
           ^^^^^^^^^^^^^^^^^^^^^^^^^^^^^^^^^^^^^^^^
  File "C:\Users\y.djemai\pam-testdrive\MARK_I\backend_python\agents\venv\Lib\site-packages\aiohttp\connector.py", line 1179, in _resolve_host_with_throttle
    addrs = await self._resolver.resolve(host, port, family=self._family)
            ^^^^^^^^^^^^^^^^^^^^^^^^^^^^^^^^^^^^^^^^^^^^^^^^^^^^^^^^^^^^^
  File "C:\Users\y.djemai\pam-testdrive\MARK_I\backend_python\agents\venv\Lib\site-packages\aiohttp\resolver.py", line 40, in resolve
    infos = await self._loop.getaddrinfo(
            ^^^^^^^^^^^^^^^^^^^^^^^^^^^^^
  File "C:\Program Files\Python312\Lib\asyncio\base_events.py", line 901, in getaddrinfo
    return await self.run_in_executor(
           ^^^^^^^^^^^^^^^^^^^^^^^^^^^
  File "C:\Program Files\Python312\Lib\concurrent\futures\thread.py", line 58, in run
    result = self.fn(*self.args, **self.kwargs)
             ^^^^^^^^^^^^^^^^^^^^^^^^^^^^^^^^^^
  File "C:\Program Files\Python312\Lib\socket.py", line 963, in getaddrinfo
    for res in _socket.getaddrinfo(host, port, family, type, proto, flags):
               ^^^^^^^^^^^^^^^^^^^^^^^^^^^^^^^^^^^^^^^^^^^^^^^^^^^^^^^^^^^
socket.gaierror: [Errno 11001] getaddrinfo failed

The above exception was the direct cause of the following exception:

Traceback (most recent call last):
  File "C:\Users\y.djemai\pam-testdrive\MARK_I\backend_python\agents\venv\Lib\site-packages\livekit\agents\worker.py", line 653, in _connection_task
    ws = await self._http_session.ws_connect(
         ^^^^^^^^^^^^^^^^^^^^^^^^^^^^^^^^^^^^
  File "C:\Users\y.djemai\pam-testdrive\MARK_I\backend_python\agents\venv\Lib\site-packages\aiohttp\client.py", line 1067, in _ws_connect
    resp = await self.request(
           ^^^^^^^^^^^^^^^^^^^
  File "C:\Users\y.djemai\pam-testdrive\MARK_I\backend_python\agents\venv\Lib\site-packages\aiohttp\client.py", line 770, in _request
    resp = await handler(req)
           ^^^^^^^^^^^^^^^^^^
  File "C:\Users\y.djemai\pam-testdrive\MARK_I\backend_python\agents\venv\Lib\site-packages\aiohttp\client.py", line 725, in _connect_and_send_request
    conn = await self._connector.connect(
           ^^^^^^^^^^^^^^^^^^^^^^^^^^^^^^
  File "C:\Users\y.djemai\pam-testdrive\MARK_I\backend_python\agents\venv\Lib\site-packages\aiohttp\connector.py", line 642, in connect
    proto = await self._create_connection(req, traces, timeout)
            ^^^^^^^^^^^^^^^^^^^^^^^^^^^^^^^^^^^^^^^^^^^^^^^^^^^
  File "C:\Users\y.djemai\pam-testdrive\MARK_I\backend_python\agents\venv\Lib\site-packages\aiohttp\connector.py", line 1209, in _create_connection
    _, proto = await self._create_direct_connection(req, traces, timeout)
               ^^^^^^^^^^^^^^^^^^^^^^^^^^^^^^^^^^^^^^^^^^^^^^^^^^^^^^^^^^
  File "C:\Users\y.djemai\pam-testdrive\MARK_I\backend_python\agents\venv\Lib\site-packages\aiohttp\connector.py", line 1538, in _create_direct_connection
    raise ClientConnectorDNSError(req.connection_key, exc) from exc
aiohttp.client_exceptions.ClientConnectorDNSError: Cannot connect to host pamtestdrive-euxn3osq.livekit.cloud:443 ssl:default [getaddrinfo failed]
2025-08-04 20:05:42,600 - livekit.agents - WARNING - failed to connect to livekit, retrying in 0s
Traceback (most recent call last):
  File "C:\Users\y.djemai\pam-testdrive\MARK_I\backend_python\agents\venv\Lib\site-packages\livekit\agents\worker.py", line 692, in _connection_task
    await self._run_ws(ws)
  File "C:\Users\y.djemai\pam-testdrive\MARK_I\backend_python\agents\venv\Lib\site-packages\livekit\agents\worker.py", line 773, in _run_ws
    await asyncio.gather(*tasks)
  File "C:\Users\y.djemai\pam-testdrive\MARK_I\backend_python\agents\venv\Lib\site-packages\livekit\agents\worker.py", line 728, in _send_task
    await ws.send_bytes(msg.SerializeToString())
  File "C:\Users\y.djemai\pam-testdrive\MARK_I\backend_python\agents\venv\Lib\site-packages\aiohttp\client_ws.py", line 252, in send_bytes
    await self._writer.send_frame(data, WSMsgType.BINARY, compress=compress)
  File "C:\Users\y.djemai\pam-testdrive\MARK_I\backend_python\agents\venv\Lib\site-packages\aiohttp\_websocket\writer.py", line 126, in send_frame
    raise ClientConnectionResetError("Cannot write to closing transport")
aiohttp.client_exceptions.ClientConnectionResetError: Cannot write to closing transport
2025-08-04 20:05:43,669 - livekit.agents - WARNING - failed to connect to livekit, retrying in 2s
Traceback (most recent call last):
  File "C:\Users\y.djemai\pam-testdrive\MARK_I\backend_python\agents\venv\Lib\site-packages\aiohttp\connector.py", line 1532, in _create_direct_connection
    hosts = await self._resolve_host(host, port, traces=traces)
            ^^^^^^^^^^^^^^^^^^^^^^^^^^^^^^^^^^^^^^^^^^^^^^^^^^^
  File "C:\Users\y.djemai\pam-testdrive\MARK_I\backend_python\agents\venv\Lib\site-packages\aiohttp\connector.py", line 1148, in _resolve_host
    return await asyncio.shield(resolved_host_task)
           ^^^^^^^^^^^^^^^^^^^^^^^^^^^^^^^^^^^^^^^^
  File "C:\Users\y.djemai\pam-testdrive\MARK_I\backend_python\agents\venv\Lib\site-packages\aiohttp\connector.py", line 1179, in _resolve_host_with_throttle
    addrs = await self._resolver.resolve(host, port, family=self._family)
            ^^^^^^^^^^^^^^^^^^^^^^^^^^^^^^^^^^^^^^^^^^^^^^^^^^^^^^^^^^^^^
  File "C:\Users\y.djemai\pam-testdrive\MARK_I\backend_python\agents\venv\Lib\site-packages\aiohttp\resolver.py", line 40, in resolve
    infos = await self._loop.getaddrinfo(
            ^^^^^^^^^^^^^^^^^^^^^^^^^^^^^
  File "C:\Program Files\Python312\Lib\asyncio\base_events.py", line 901, in getaddrinfo
    return await self.run_in_executor(
           ^^^^^^^^^^^^^^^^^^^^^^^^^^^
  File "C:\Program Files\Python312\Lib\concurrent\futures\thread.py", line 58, in run
    result = self.fn(*self.args, **self.kwargs)
             ^^^^^^^^^^^^^^^^^^^^^^^^^^^^^^^^^^
  File "C:\Program Files\Python312\Lib\socket.py", line 963, in getaddrinfo
    for res in _socket.getaddrinfo(host, port, family, type, proto, flags):
               ^^^^^^^^^^^^^^^^^^^^^^^^^^^^^^^^^^^^^^^^^^^^^^^^^^^^^^^^^^^
socket.gaierror: [Errno 11001] getaddrinfo failed

The above exception was the direct cause of the following exception:

Traceback (most recent call last):
  File "C:\Users\y.djemai\pam-testdrive\MARK_I\backend_python\agents\venv\Lib\site-packages\livekit\agents\worker.py", line 653, in _connection_task
    ws = await self._http_session.ws_connect(
         ^^^^^^^^^^^^^^^^^^^^^^^^^^^^^^^^^^^^
  File "C:\Users\y.djemai\pam-testdrive\MARK_I\backend_python\agents\venv\Lib\site-packages\aiohttp\client.py", line 1067, in _ws_connect
    resp = await self.request(
           ^^^^^^^^^^^^^^^^^^^
  File "C:\Users\y.djemai\pam-testdrive\MARK_I\backend_python\agents\venv\Lib\site-packages\aiohttp\client.py", line 770, in _request
    resp = await handler(req)
           ^^^^^^^^^^^^^^^^^^
  File "C:\Users\y.djemai\pam-testdrive\MARK_I\backend_python\agents\venv\Lib\site-packages\aiohttp\client.py", line 725, in _connect_and_send_request
    conn = await self._connector.connect(
           ^^^^^^^^^^^^^^^^^^^^^^^^^^^^^^
  File "C:\Users\y.djemai\pam-testdrive\MARK_I\backend_python\agents\venv\Lib\site-packages\aiohttp\connector.py", line 642, in connect
    proto = await self._create_connection(req, traces, timeout)
            ^^^^^^^^^^^^^^^^^^^^^^^^^^^^^^^^^^^^^^^^^^^^^^^^^^^
  File "C:\Users\y.djemai\pam-testdrive\MARK_I\backend_python\agents\venv\Lib\site-packages\aiohttp\connector.py", line 1209, in _create_connection
    _, proto = await self._create_direct_connection(req, traces, timeout)
               ^^^^^^^^^^^^^^^^^^^^^^^^^^^^^^^^^^^^^^^^^^^^^^^^^^^^^^^^^^
  File "C:\Users\y.djemai\pam-testdrive\MARK_I\backend_python\agents\venv\Lib\site-packages\aiohttp\connector.py", line 1538, in _create_direct_connection
    raise ClientConnectorDNSError(req.connection_key, exc) from exc
aiohttp.client_exceptions.ClientConnectorDNSError: Cannot connect to host pamtestdrive-euxn3osq.livekit.cloud:443 ssl:default [getaddrinfo failed]
2025-08-04 20:05:46,072 - livekit.agents - WARNING - failed to connect to livekit, retrying in 4s
Traceback (most recent call last):
  File "C:\Users\y.djemai\pam-testdrive\MARK_I\backend_python\agents\venv\Lib\site-packages\aiohttp\connector.py", line 1532, in _create_direct_connection
    hosts = await self._resolve_host(host, port, traces=traces)
            ^^^^^^^^^^^^^^^^^^^^^^^^^^^^^^^^^^^^^^^^^^^^^^^^^^^
  File "C:\Users\y.djemai\pam-testdrive\MARK_I\backend_python\agents\venv\Lib\site-packages\aiohttp\connector.py", line 1148, in _resolve_host
    return await asyncio.shield(resolved_host_task)
           ^^^^^^^^^^^^^^^^^^^^^^^^^^^^^^^^^^^^^^^^
  File "C:\Users\y.djemai\pam-testdrive\MARK_I\backend_python\agents\venv\Lib\site-packages\aiohttp\connector.py", line 1179, in _resolve_host_with_throttle
    addrs = await self._resolver.resolve(host, port, family=self._family)
            ^^^^^^^^^^^^^^^^^^^^^^^^^^^^^^^^^^^^^^^^^^^^^^^^^^^^^^^^^^^^^
  File "C:\Users\y.djemai\pam-testdrive\MARK_I\backend_python\agents\venv\Lib\site-packages\aiohttp\resolver.py", line 40, in resolve
    infos = await self._loop.getaddrinfo(
            ^^^^^^^^^^^^^^^^^^^^^^^^^^^^^
  File "C:\Program Files\Python312\Lib\asyncio\base_events.py", line 901, in getaddrinfo
    return await self.run_in_executor(
           ^^^^^^^^^^^^^^^^^^^^^^^^^^^
  File "C:\Program Files\Python312\Lib\concurrent\futures\thread.py", line 58, in run
    result = self.fn(*self.args, **self.kwargs)
             ^^^^^^^^^^^^^^^^^^^^^^^^^^^^^^^^^^
  File "C:\Program Files\Python312\Lib\socket.py", line 963, in getaddrinfo
    for res in _socket.getaddrinfo(host, port, family, type, proto, flags):
               ^^^^^^^^^^^^^^^^^^^^^^^^^^^^^^^^^^^^^^^^^^^^^^^^^^^^^^^^^^^
socket.gaierror: [Errno 11001] getaddrinfo failed

The above exception was the direct cause of the following exception:

Traceback (most recent call last):
  File "C:\Users\y.djemai\pam-testdrive\MARK_I\backend_python\agents\venv\Lib\site-packages\livekit\agents\worker.py", line 653, in _connection_task
    ws = await self._http_session.ws_connect(
         ^^^^^^^^^^^^^^^^^^^^^^^^^^^^^^^^^^^^
  File "C:\Users\y.djemai\pam-testdrive\MARK_I\backend_python\agents\venv\Lib\site-packages\aiohttp\client.py", line 1067, in _ws_connect
    resp = await self.request(
           ^^^^^^^^^^^^^^^^^^^
  File "C:\Users\y.djemai\pam-testdrive\MARK_I\backend_python\agents\venv\Lib\site-packages\aiohttp\client.py", line 770, in _request
    resp = await handler(req)
           ^^^^^^^^^^^^^^^^^^
  File "C:\Users\y.djemai\pam-testdrive\MARK_I\backend_python\agents\venv\Lib\site-packages\aiohttp\client.py", line 725, in _connect_and_send_request
    conn = await self._connector.connect(
           ^^^^^^^^^^^^^^^^^^^^^^^^^^^^^^
  File "C:\Users\y.djemai\pam-testdrive\MARK_I\backend_python\agents\venv\Lib\site-packages\aiohttp\connector.py", line 642, in connect
    proto = await self._create_connection(req, traces, timeout)
            ^^^^^^^^^^^^^^^^^^^^^^^^^^^^^^^^^^^^^^^^^^^^^^^^^^^
  File "C:\Users\y.djemai\pam-testdrive\MARK_I\backend_python\agents\venv\Lib\site-packages\aiohttp\connector.py", line 1209, in _create_connection
    _, proto = await self._create_direct_connection(req, traces, timeout)
               ^^^^^^^^^^^^^^^^^^^^^^^^^^^^^^^^^^^^^^^^^^^^^^^^^^^^^^^^^^
  File "C:\Users\y.djemai\pam-testdrive\MARK_I\backend_python\agents\venv\Lib\site-packages\aiohttp\connector.py", line 1538, in _create_direct_connection
    raise ClientConnectorDNSError(req.connection_key, exc) from exc
aiohttp.client_exceptions.ClientConnectorDNSError: Cannot connect to host pamtestdrive-euxn3osq.livekit.cloud:443 ssl:default [getaddrinfo failed]
2025-08-04 22:26:33,359 - livekit.agents - WARNING - job executor is unresponsive
2025-08-04 22:26:33,437 - livekit.agents - WARNING - job executor is unresponsive
2025-08-04 22:26:33,488 - livekit.agents - WARNING - job executor is unresponsive
2025-08-04 22:26:33,489 - livekit.agents - WARNING - job executor is unresponsive
2025-08-04 22:26:33,532 - livekit.agents - WARNING - job executor is unresponsive
2025-08-04 22:26:33,578 - livekit.agents - WARNING - job executor is unresponsive
2025-08-04 22:26:33,627 - livekit.agents - WARNING - job executor is unresponsive
2025-08-04 22:26:33,673 - livekit.agents - WARNING - job executor is unresponsive
2025-08-04 22:26:33,755 - livekit.agents - WARNING - job executor is unresponsive
2025-08-04 22:26:33,804 - livekit.agents - WARNING - job executor is unresponsive
2025-08-04 22:26:33,806 - livekit.agents - WARNING - job executor is unresponsive
2025-08-04 22:26:33,850 - livekit.agents - WARNING - job executor is unresponsive
2025-08-04 22:26:33,887 - livekit.agents - WARNING - failed to connect to livekit, retrying in 6s
Traceback (most recent call last):
  File "C:\Users\y.djemai\pam-testdrive\MARK_I\backend_python\agents\venv\Lib\site-packages\aiohttp\connector.py", line 1532, in _create_direct_connection
    hosts = await self._resolve_host(host, port, traces=traces)
            ^^^^^^^^^^^^^^^^^^^^^^^^^^^^^^^^^^^^^^^^^^^^^^^^^^^
  File "C:\Users\y.djemai\pam-testdrive\MARK_I\backend_python\agents\venv\Lib\site-packages\aiohttp\connector.py", line 1148, in _resolve_host
    return await asyncio.shield(resolved_host_task)
           ^^^^^^^^^^^^^^^^^^^^^^^^^^^^^^^^^^^^^^^^
  File "C:\Users\y.djemai\pam-testdrive\MARK_I\backend_python\agents\venv\Lib\site-packages\aiohttp\connector.py", line 1179, in _resolve_host_with_throttle
    addrs = await self._resolver.resolve(host, port, family=self._family)
            ^^^^^^^^^^^^^^^^^^^^^^^^^^^^^^^^^^^^^^^^^^^^^^^^^^^^^^^^^^^^^
  File "C:\Users\y.djemai\pam-testdrive\MARK_I\backend_python\agents\venv\Lib\site-packages\aiohttp\resolver.py", line 40, in resolve
    infos = await self._loop.getaddrinfo(
            ^^^^^^^^^^^^^^^^^^^^^^^^^^^^^
  File "C:\Program Files\Python312\Lib\asyncio\base_events.py", line 901, in getaddrinfo
    return await self.run_in_executor(
           ^^^^^^^^^^^^^^^^^^^^^^^^^^^
  File "C:\Program Files\Python312\Lib\concurrent\futures\thread.py", line 58, in run
    result = self.fn(*self.args, **self.kwargs)
             ^^^^^^^^^^^^^^^^^^^^^^^^^^^^^^^^^^
  File "C:\Program Files\Python312\Lib\socket.py", line 963, in getaddrinfo
    for res in _socket.getaddrinfo(host, port, family, type, proto, flags):
               ^^^^^^^^^^^^^^^^^^^^^^^^^^^^^^^^^^^^^^^^^^^^^^^^^^^^^^^^^^^
socket.gaierror: [Errno 11001] getaddrinfo failed

The above exception was the direct cause of the following exception:

Traceback (most recent call last):
  File "C:\Users\y.djemai\pam-testdrive\MARK_I\backend_python\agents\venv\Lib\site-packages\livekit\agents\worker.py", line 653, in _connection_task
    ws = await self._http_session.ws_connect(
         ^^^^^^^^^^^^^^^^^^^^^^^^^^^^^^^^^^^^
  File "C:\Users\y.djemai\pam-testdrive\MARK_I\backend_python\agents\venv\Lib\site-packages\aiohttp\client.py", line 1067, in _ws_connect
    resp = await self.request(
           ^^^^^^^^^^^^^^^^^^^
  File "C:\Users\y.djemai\pam-testdrive\MARK_I\backend_python\agents\venv\Lib\site-packages\aiohttp\client.py", line 770, in _request
    resp = await handler(req)
           ^^^^^^^^^^^^^^^^^^
  File "C:\Users\y.djemai\pam-testdrive\MARK_I\backend_python\agents\venv\Lib\site-packages\aiohttp\client.py", line 725, in _connect_and_send_request
    conn = await self._connector.connect(
           ^^^^^^^^^^^^^^^^^^^^^^^^^^^^^^
  File "C:\Users\y.djemai\pam-testdrive\MARK_I\backend_python\agents\venv\Lib\site-packages\aiohttp\connector.py", line 642, in connect
    proto = await self._create_connection(req, traces, timeout)
            ^^^^^^^^^^^^^^^^^^^^^^^^^^^^^^^^^^^^^^^^^^^^^^^^^^^
  File "C:\Users\y.djemai\pam-testdrive\MARK_I\backend_python\agents\venv\Lib\site-packages\aiohttp\connector.py", line 1209, in _create_connection
    _, proto = await self._create_direct_connection(req, traces, timeout)
               ^^^^^^^^^^^^^^^^^^^^^^^^^^^^^^^^^^^^^^^^^^^^^^^^^^^^^^^^^^
  File "C:\Users\y.djemai\pam-testdrive\MARK_I\backend_python\agents\venv\Lib\site-packages\aiohttp\connector.py", line 1538, in _create_direct_connection
    raise ClientConnectorDNSError(req.connection_key, exc) from exc
aiohttp.client_exceptions.ClientConnectorDNSError: Cannot connect to host pamtestdrive-euxn3osq.livekit.cloud:443 ssl:default [getaddrinfo failed]
2025-08-04 22:27:04,239 - livekit.agents - WARNING - failed to connect to livekit, retrying in 0s
Traceback (most recent call last):
  File "C:\Users\y.djemai\pam-testdrive\MARK_I\backend_python\agents\venv\Lib\site-packages\livekit\agents\worker.py", line 692, in _connection_task
    await self._run_ws(ws)
  File "C:\Users\y.djemai\pam-testdrive\MARK_I\backend_python\agents\venv\Lib\site-packages\livekit\agents\worker.py", line 773, in _run_ws
    await asyncio.gather(*tasks)
  File "C:\Users\y.djemai\pam-testdrive\MARK_I\backend_python\agents\venv\Lib\site-packages\livekit\agents\worker.py", line 745, in _recv_task
    raise Exception("worker connection closed unexpectedly")
Exception: worker connection closed unexpectedly
2025-08-04 22:27:04,257 - livekit.agents - WARNING - failed to connect to livekit, retrying in 2s
Traceback (most recent call last):
  File "C:\Users\y.djemai\pam-testdrive\MARK_I\backend_python\agents\venv\Lib\site-packages\aiohttp\connector.py", line 1532, in _create_direct_connection
    hosts = await self._resolve_host(host, port, traces=traces)
            ^^^^^^^^^^^^^^^^^^^^^^^^^^^^^^^^^^^^^^^^^^^^^^^^^^^
  File "C:\Users\y.djemai\pam-testdrive\MARK_I\backend_python\agents\venv\Lib\site-packages\aiohttp\connector.py", line 1148, in _resolve_host
    return await asyncio.shield(resolved_host_task)
           ^^^^^^^^^^^^^^^^^^^^^^^^^^^^^^^^^^^^^^^^
  File "C:\Users\y.djemai\pam-testdrive\MARK_I\backend_python\agents\venv\Lib\site-packages\aiohttp\connector.py", line 1179, in _resolve_host_with_throttle
    addrs = await self._resolver.resolve(host, port, family=self._family)
            ^^^^^^^^^^^^^^^^^^^^^^^^^^^^^^^^^^^^^^^^^^^^^^^^^^^^^^^^^^^^^
  File "C:\Users\y.djemai\pam-testdrive\MARK_I\backend_python\agents\venv\Lib\site-packages\aiohttp\resolver.py", line 40, in resolve
    infos = await self._loop.getaddrinfo(
            ^^^^^^^^^^^^^^^^^^^^^^^^^^^^^
  File "C:\Program Files\Python312\Lib\asyncio\base_events.py", line 901, in getaddrinfo
    return await self.run_in_executor(
           ^^^^^^^^^^^^^^^^^^^^^^^^^^^
  File "C:\Program Files\Python312\Lib\concurrent\futures\thread.py", line 58, in run
    result = self.fn(*self.args, **self.kwargs)
             ^^^^^^^^^^^^^^^^^^^^^^^^^^^^^^^^^^
  File "C:\Program Files\Python312\Lib\socket.py", line 963, in getaddrinfo
    for res in _socket.getaddrinfo(host, port, family, type, proto, flags):
               ^^^^^^^^^^^^^^^^^^^^^^^^^^^^^^^^^^^^^^^^^^^^^^^^^^^^^^^^^^^
socket.gaierror: [Errno 11001] getaddrinfo failed

The above exception was the direct cause of the following exception:

Traceback (most recent call last):
  File "C:\Users\y.djemai\pam-testdrive\MARK_I\backend_python\agents\venv\Lib\site-packages\livekit\agents\worker.py", line 653, in _connection_task
    ws = await self._http_session.ws_connect(
         ^^^^^^^^^^^^^^^^^^^^^^^^^^^^^^^^^^^^
  File "C:\Users\y.djemai\pam-testdrive\MARK_I\backend_python\agents\venv\Lib\site-packages\aiohttp\client.py", line 1067, in _ws_connect
    resp = await self.request(
           ^^^^^^^^^^^^^^^^^^^
  File "C:\Users\y.djemai\pam-testdrive\MARK_I\backend_python\agents\venv\Lib\site-packages\aiohttp\client.py", line 770, in _request
    resp = await handler(req)
           ^^^^^^^^^^^^^^^^^^
  File "C:\Users\y.djemai\pam-testdrive\MARK_I\backend_python\agents\venv\Lib\site-packages\aiohttp\client.py", line 725, in _connect_and_send_request
    conn = await self._connector.connect(
           ^^^^^^^^^^^^^^^^^^^^^^^^^^^^^^
  File "C:\Users\y.djemai\pam-testdrive\MARK_I\backend_python\agents\venv\Lib\site-packages\aiohttp\connector.py", line 642, in connect
    proto = await self._create_connection(req, traces, timeout)
            ^^^^^^^^^^^^^^^^^^^^^^^^^^^^^^^^^^^^^^^^^^^^^^^^^^^
  File "C:\Users\y.djemai\pam-testdrive\MARK_I\backend_python\agents\venv\Lib\site-packages\aiohttp\connector.py", line 1209, in _create_connection
    _, proto = await self._create_direct_connection(req, traces, timeout)
               ^^^^^^^^^^^^^^^^^^^^^^^^^^^^^^^^^^^^^^^^^^^^^^^^^^^^^^^^^^
  File "C:\Users\y.djemai\pam-testdrive\MARK_I\backend_python\agents\venv\Lib\site-packages\aiohttp\connector.py", line 1538, in _create_direct_connection
    raise ClientConnectorDNSError(req.connection_key, exc) from exc
aiohttp.client_exceptions.ClientConnectorDNSError: Cannot connect to host pamtestdrive-euxn3osq.livekit.cloud:443 ssl:default [getaddrinfo failed]
2025-08-05 09:00:10,744 - livekit.agents - WARNING - failed to connect to livekit, retrying in 4s
Traceback (most recent call last):
  File "C:\Users\y.djemai\pam-testdrive\MARK_I\backend_python\agents\venv\Lib\site-packages\aiohttp\connector.py", line 1532, in _create_direct_connection
    hosts = await self._resolve_host(host, port, traces=traces)
            ^^^^^^^^^^^^^^^^^^^^^^^^^^^^^^^^^^^^^^^^^^^^^^^^^^^
  File "C:\Users\y.djemai\pam-testdrive\MARK_I\backend_python\agents\venv\Lib\site-packages\aiohttp\connector.py", line 1148, in _resolve_host
    return await asyncio.shield(resolved_host_task)
           ^^^^^^^^^^^^^^^^^^^^^^^^^^^^^^^^^^^^^^^^
  File "C:\Users\y.djemai\pam-testdrive\MARK_I\backend_python\agents\venv\Lib\site-packages\aiohttp\connector.py", line 1179, in _resolve_host_with_throttle
    addrs = await self._resolver.resolve(host, port, family=self._family)
            ^^^^^^^^^^^^^^^^^^^^^^^^^^^^^^^^^^^^^^^^^^^^^^^^^^^^^^^^^^^^^
  File "C:\Users\y.djemai\pam-testdrive\MARK_I\backend_python\agents\venv\Lib\site-packages\aiohttp\resolver.py", line 40, in resolve
    infos = await self._loop.getaddrinfo(
            ^^^^^^^^^^^^^^^^^^^^^^^^^^^^^
  File "C:\Program Files\Python312\Lib\asyncio\base_events.py", line 901, in getaddrinfo
    return await self.run_in_executor(
           ^^^^^^^^^^^^^^^^^^^^^^^^^^^
  File "C:\Program Files\Python312\Lib\concurrent\futures\thread.py", line 58, in run
    result = self.fn(*self.args, **self.kwargs)
             ^^^^^^^^^^^^^^^^^^^^^^^^^^^^^^^^^^
  File "C:\Program Files\Python312\Lib\socket.py", line 963, in getaddrinfo
    for res in _socket.getaddrinfo(host, port, family, type, proto, flags):
               ^^^^^^^^^^^^^^^^^^^^^^^^^^^^^^^^^^^^^^^^^^^^^^^^^^^^^^^^^^^
socket.gaierror: [Errno 11001] getaddrinfo failed

The above exception was the direct cause of the following exception:

Traceback (most recent call last):
  File "C:\Users\y.djemai\pam-testdrive\MARK_I\backend_python\agents\venv\Lib\site-packages\livekit\agents\worker.py", line 653, in _connection_task
    ws = await self._http_session.ws_connect(
         ^^^^^^^^^^^^^^^^^^^^^^^^^^^^^^^^^^^^
  File "C:\Users\y.djemai\pam-testdrive\MARK_I\backend_python\agents\venv\Lib\site-packages\aiohttp\client.py", line 1067, in _ws_connect
    resp = await self.request(
           ^^^^^^^^^^^^^^^^^^^
  File "C:\Users\y.djemai\pam-testdrive\MARK_I\backend_python\agents\venv\Lib\site-packages\aiohttp\client.py", line 770, in _request
    resp = await handler(req)
           ^^^^^^^^^^^^^^^^^^
  File "C:\Users\y.djemai\pam-testdrive\MARK_I\backend_python\agents\venv\Lib\site-packages\aiohttp\client.py", line 725, in _connect_and_send_request
    conn = await self._connector.connect(
           ^^^^^^^^^^^^^^^^^^^^^^^^^^^^^^
  File "C:\Users\y.djemai\pam-testdrive\MARK_I\backend_python\agents\venv\Lib\site-packages\aiohttp\connector.py", line 642, in connect
    proto = await self._create_connection(req, traces, timeout)
            ^^^^^^^^^^^^^^^^^^^^^^^^^^^^^^^^^^^^^^^^^^^^^^^^^^^
  File "C:\Users\y.djemai\pam-testdrive\MARK_I\backend_python\agents\venv\Lib\site-packages\aiohttp\connector.py", line 1209, in _create_connection
    _, proto = await self._create_direct_connection(req, traces, timeout)
               ^^^^^^^^^^^^^^^^^^^^^^^^^^^^^^^^^^^^^^^^^^^^^^^^^^^^^^^^^^
  File "C:\Users\y.djemai\pam-testdrive\MARK_I\backend_python\agents\venv\Lib\site-packages\aiohttp\connector.py", line 1538, in _create_direct_connection
    raise ClientConnectorDNSError(req.connection_key, exc) from exc
aiohttp.client_exceptions.ClientConnectorDNSError: Cannot connect to host pamtestdrive-euxn3osq.livekit.cloud:443 ssl:default [getaddrinfo failed]
2025-08-05 09:00:15,058 - livekit.agents - WARNING - failed to connect to livekit, retrying in 6s
Traceback (most recent call last):
  File "C:\Users\y.djemai\pam-testdrive\MARK_I\backend_python\agents\venv\Lib\site-packages\aiohttp\connector.py", line 1532, in _create_direct_connection
    hosts = await self._resolve_host(host, port, traces=traces)
            ^^^^^^^^^^^^^^^^^^^^^^^^^^^^^^^^^^^^^^^^^^^^^^^^^^^
  File "C:\Users\y.djemai\pam-testdrive\MARK_I\backend_python\agents\venv\Lib\site-packages\aiohttp\connector.py", line 1148, in _resolve_host
    return await asyncio.shield(resolved_host_task)
           ^^^^^^^^^^^^^^^^^^^^^^^^^^^^^^^^^^^^^^^^
  File "C:\Users\y.djemai\pam-testdrive\MARK_I\backend_python\agents\venv\Lib\site-packages\aiohttp\connector.py", line 1179, in _resolve_host_with_throttle
    addrs = await self._resolver.resolve(host, port, family=self._family)
            ^^^^^^^^^^^^^^^^^^^^^^^^^^^^^^^^^^^^^^^^^^^^^^^^^^^^^^^^^^^^^
  File "C:\Users\y.djemai\pam-testdrive\MARK_I\backend_python\agents\venv\Lib\site-packages\aiohttp\resolver.py", line 40, in resolve
    infos = await self._loop.getaddrinfo(
            ^^^^^^^^^^^^^^^^^^^^^^^^^^^^^
  File "C:\Program Files\Python312\Lib\asyncio\base_events.py", line 901, in getaddrinfo
    return await self.run_in_executor(
           ^^^^^^^^^^^^^^^^^^^^^^^^^^^
  File "C:\Program Files\Python312\Lib\concurrent\futures\thread.py", line 58, in run
    result = self.fn(*self.args, **self.kwargs)
             ^^^^^^^^^^^^^^^^^^^^^^^^^^^^^^^^^^
  File "C:\Program Files\Python312\Lib\socket.py", line 963, in getaddrinfo
    for res in _socket.getaddrinfo(host, port, family, type, proto, flags):
               ^^^^^^^^^^^^^^^^^^^^^^^^^^^^^^^^^^^^^^^^^^^^^^^^^^^^^^^^^^^
socket.gaierror: [Errno 11001] getaddrinfo failed

The above exception was the direct cause of the following exception:

Traceback (most recent call last):
  File "C:\Users\y.djemai\pam-testdrive\MARK_I\backend_python\agents\venv\Lib\site-packages\livekit\agents\worker.py", line 653, in _connection_task
    ws = await self._http_session.ws_connect(
         ^^^^^^^^^^^^^^^^^^^^^^^^^^^^^^^^^^^^
  File "C:\Users\y.djemai\pam-testdrive\MARK_I\backend_python\agents\venv\Lib\site-packages\aiohttp\client.py", line 1067, in _ws_connect
    resp = await self.request(
           ^^^^^^^^^^^^^^^^^^^
  File "C:\Users\y.djemai\pam-testdrive\MARK_I\backend_python\agents\venv\Lib\site-packages\aiohttp\client.py", line 770, in _request
    resp = await handler(req)
           ^^^^^^^^^^^^^^^^^^
  File "C:\Users\y.djemai\pam-testdrive\MARK_I\backend_python\agents\venv\Lib\site-packages\aiohttp\client.py", line 725, in _connect_and_send_request
    conn = await self._connector.connect(
           ^^^^^^^^^^^^^^^^^^^^^^^^^^^^^^
  File "C:\Users\y.djemai\pam-testdrive\MARK_I\backend_python\agents\venv\Lib\site-packages\aiohttp\connector.py", line 642, in connect
    proto = await self._create_connection(req, traces, timeout)
            ^^^^^^^^^^^^^^^^^^^^^^^^^^^^^^^^^^^^^^^^^^^^^^^^^^^
  File "C:\Users\y.djemai\pam-testdrive\MARK_I\backend_python\agents\venv\Lib\site-packages\aiohttp\connector.py", line 1209, in _create_connection
    _, proto = await self._create_direct_connection(req, traces, timeout)
               ^^^^^^^^^^^^^^^^^^^^^^^^^^^^^^^^^^^^^^^^^^^^^^^^^^^^^^^^^^
  File "C:\Users\y.djemai\pam-testdrive\MARK_I\backend_python\agents\venv\Lib\site-packages\aiohttp\connector.py", line 1538, in _create_direct_connection
    raise ClientConnectorDNSError(req.connection_key, exc) from exc
aiohttp.client_exceptions.ClientConnectorDNSError: Cannot connect to host pamtestdrive-euxn3osq.livekit.cloud:443 ssl:default [getaddrinfo failed]
2025-08-05 09:40:20,468 - livekit.agents - WARNING - failed to connect to livekit, retrying in 0s
Traceback (most recent call last):
  File "C:\Users\y.djemai\pam-testdrive\MARK_I\backend_python\agents\venv\Lib\site-packages\livekit\agents\worker.py", line 692, in _connection_task
    await self._run_ws(ws)
  File "C:\Users\y.djemai\pam-testdrive\MARK_I\backend_python\agents\venv\Lib\site-packages\livekit\agents\worker.py", line 773, in _run_ws
    await asyncio.gather(*tasks)
  File "C:\Users\y.djemai\pam-testdrive\MARK_I\backend_python\agents\venv\Lib\site-packages\livekit\agents\worker.py", line 745, in _recv_task
    raise Exception("worker connection closed unexpectedly")
Exception: worker connection closed unexpectedly
2025-08-05 09:40:41,529 - livekit.agents - WARNING - failed to connect to livekit, retrying in 2s
Traceback (most recent call last):
  File "C:\Users\y.djemai\pam-testdrive\MARK_I\backend_python\agents\venv\Lib\site-packages\aiohttp\connector.py", line 1268, in _wrap_create_connection
    sock = await aiohappyeyeballs.start_connection(
           ^^^^^^^^^^^^^^^^^^^^^^^^^^^^^^^^^^^^^^^^
  File "C:\Users\y.djemai\pam-testdrive\MARK_I\backend_python\agents\venv\Lib\site-packages\aiohappyeyeballs\impl.py", line 122, in start_connection
    raise first_exception
  File "C:\Users\y.djemai\pam-testdrive\MARK_I\backend_python\agents\venv\Lib\site-packages\aiohappyeyeballs\impl.py", line 73, in start_connection
    sock = await _connect_sock(
           ^^^^^^^^^^^^^^^^^^^^
  File "C:\Users\y.djemai\pam-testdrive\MARK_I\backend_python\agents\venv\Lib\site-packages\aiohappyeyeballs\impl.py", line 208, in _connect_sock
    await loop.sock_connect(sock, address)
  File "C:\Program Files\Python312\Lib\asyncio\proactor_events.py", line 727, in sock_connect
    return await self._proactor.connect(sock, address)
           ^^^^^^^^^^^^^^^^^^^^^^^^^^^^^^^^^^^^^^^^^^^
  File "C:\Program Files\Python312\Lib\asyncio\windows_events.py", line 803, in _poll
    value = callback(transferred, key, ov)
            ^^^^^^^^^^^^^^^^^^^^^^^^^^^^^^
  File "C:\Program Files\Python312\Lib\asyncio\windows_events.py", line 599, in finish_connect
    ov.getresult()
OSError: [WinError 121] Le d√©lai de temporisation de s√©maphore a expir√©

The above exception was the direct cause of the following exception:

Traceback (most recent call last):
  File "C:\Users\y.djemai\pam-testdrive\MARK_I\backend_python\agents\venv\Lib\site-packages\livekit\agents\worker.py", line 653, in _connection_task
    ws = await self._http_session.ws_connect(
         ^^^^^^^^^^^^^^^^^^^^^^^^^^^^^^^^^^^^
  File "C:\Users\y.djemai\pam-testdrive\MARK_I\backend_python\agents\venv\Lib\site-packages\aiohttp\client.py", line 1067, in _ws_connect
    resp = await self.request(
           ^^^^^^^^^^^^^^^^^^^
  File "C:\Users\y.djemai\pam-testdrive\MARK_I\backend_python\agents\venv\Lib\site-packages\aiohttp\client.py", line 770, in _request
    resp = await handler(req)
           ^^^^^^^^^^^^^^^^^^
  File "C:\Users\y.djemai\pam-testdrive\MARK_I\backend_python\agents\venv\Lib\site-packages\aiohttp\client.py", line 725, in _connect_and_send_request
    conn = await self._connector.connect(
           ^^^^^^^^^^^^^^^^^^^^^^^^^^^^^^
  File "C:\Users\y.djemai\pam-testdrive\MARK_I\backend_python\agents\venv\Lib\site-packages\aiohttp\connector.py", line 642, in connect
    proto = await self._create_connection(req, traces, timeout)
            ^^^^^^^^^^^^^^^^^^^^^^^^^^^^^^^^^^^^^^^^^^^^^^^^^^^
  File "C:\Users\y.djemai\pam-testdrive\MARK_I\backend_python\agents\venv\Lib\site-packages\aiohttp\connector.py", line 1209, in _create_connection
    _, proto = await self._create_direct_connection(req, traces, timeout)
               ^^^^^^^^^^^^^^^^^^^^^^^^^^^^^^^^^^^^^^^^^^^^^^^^^^^^^^^^^^
  File "C:\Users\y.djemai\pam-testdrive\MARK_I\backend_python\agents\venv\Lib\site-packages\aiohttp\connector.py", line 1581, in _create_direct_connection
    raise last_exc
  File "C:\Users\y.djemai\pam-testdrive\MARK_I\backend_python\agents\venv\Lib\site-packages\aiohttp\connector.py", line 1550, in _create_direct_connection
    transp, proto = await self._wrap_create_connection(
                    ^^^^^^^^^^^^^^^^^^^^^^^^^^^^^^^^^^^
  File "C:\Users\y.djemai\pam-testdrive\MARK_I\backend_python\agents\venv\Lib\site-packages\aiohttp\connector.py", line 1291, in _wrap_create_connection
    raise client_error(req.connection_key, exc) from exc
aiohttp.client_exceptions.ClientConnectorError: Cannot connect to host pamtestdrive-euxn3osq.livekit.cloud:443 ssl:default [Le d√©lai de temporisation de s√©maphore a expir√©]
2025-08-05 09:41:04,587 - livekit.agents - WARNING - failed to connect to livekit, retrying in 4s
Traceback (most recent call last):
  File "C:\Users\y.djemai\pam-testdrive\MARK_I\backend_python\agents\venv\Lib\site-packages\aiohttp\connector.py", line 1268, in _wrap_create_connection
    sock = await aiohappyeyeballs.start_connection(
           ^^^^^^^^^^^^^^^^^^^^^^^^^^^^^^^^^^^^^^^^
  File "C:\Users\y.djemai\pam-testdrive\MARK_I\backend_python\agents\venv\Lib\site-packages\aiohappyeyeballs\impl.py", line 122, in start_connection
    raise first_exception
  File "C:\Users\y.djemai\pam-testdrive\MARK_I\backend_python\agents\venv\Lib\site-packages\aiohappyeyeballs\impl.py", line 73, in start_connection
    sock = await _connect_sock(
           ^^^^^^^^^^^^^^^^^^^^
  File "C:\Users\y.djemai\pam-testdrive\MARK_I\backend_python\agents\venv\Lib\site-packages\aiohappyeyeballs\impl.py", line 208, in _connect_sock
    await loop.sock_connect(sock, address)
  File "C:\Program Files\Python312\Lib\asyncio\proactor_events.py", line 727, in sock_connect
    return await self._proactor.connect(sock, address)
           ^^^^^^^^^^^^^^^^^^^^^^^^^^^^^^^^^^^^^^^^^^^
  File "C:\Program Files\Python312\Lib\asyncio\windows_events.py", line 803, in _poll
    value = callback(transferred, key, ov)
            ^^^^^^^^^^^^^^^^^^^^^^^^^^^^^^
  File "C:\Program Files\Python312\Lib\asyncio\windows_events.py", line 599, in finish_connect
    ov.getresult()
OSError: [WinError 121] Le d√©lai de temporisation de s√©maphore a expir√©

The above exception was the direct cause of the following exception:

Traceback (most recent call last):
  File "C:\Users\y.djemai\pam-testdrive\MARK_I\backend_python\agents\venv\Lib\site-packages\livekit\agents\worker.py", line 653, in _connection_task
    ws = await self._http_session.ws_connect(
         ^^^^^^^^^^^^^^^^^^^^^^^^^^^^^^^^^^^^
  File "C:\Users\y.djemai\pam-testdrive\MARK_I\backend_python\agents\venv\Lib\site-packages\aiohttp\client.py", line 1067, in _ws_connect
    resp = await self.request(
           ^^^^^^^^^^^^^^^^^^^
  File "C:\Users\y.djemai\pam-testdrive\MARK_I\backend_python\agents\venv\Lib\site-packages\aiohttp\client.py", line 770, in _request
    resp = await handler(req)
           ^^^^^^^^^^^^^^^^^^
  File "C:\Users\y.djemai\pam-testdrive\MARK_I\backend_python\agents\venv\Lib\site-packages\aiohttp\client.py", line 725, in _connect_and_send_request
    conn = await self._connector.connect(
           ^^^^^^^^^^^^^^^^^^^^^^^^^^^^^^
  File "C:\Users\y.djemai\pam-testdrive\MARK_I\backend_python\agents\venv\Lib\site-packages\aiohttp\connector.py", line 642, in connect
    proto = await self._create_connection(req, traces, timeout)
            ^^^^^^^^^^^^^^^^^^^^^^^^^^^^^^^^^^^^^^^^^^^^^^^^^^^
  File "C:\Users\y.djemai\pam-testdrive\MARK_I\backend_python\agents\venv\Lib\site-packages\aiohttp\connector.py", line 1209, in _create_connection
    _, proto = await self._create_direct_connection(req, traces, timeout)
               ^^^^^^^^^^^^^^^^^^^^^^^^^^^^^^^^^^^^^^^^^^^^^^^^^^^^^^^^^^
  File "C:\Users\y.djemai\pam-testdrive\MARK_I\backend_python\agents\venv\Lib\site-packages\aiohttp\connector.py", line 1581, in _create_direct_connection
    raise last_exc
  File "C:\Users\y.djemai\pam-testdrive\MARK_I\backend_python\agents\venv\Lib\site-packages\aiohttp\connector.py", line 1550, in _create_direct_connection
    transp, proto = await self._wrap_create_connection(
                    ^^^^^^^^^^^^^^^^^^^^^^^^^^^^^^^^^^^
  File "C:\Users\y.djemai\pam-testdrive\MARK_I\backend_python\agents\venv\Lib\site-packages\aiohttp\connector.py", line 1291, in _wrap_create_connection
    raise client_error(req.connection_key, exc) from exc
aiohttp.client_exceptions.ClientConnectorError: Cannot connect to host pamtestdrive-euxn3osq.livekit.cloud:443 ssl:default [Le d√©lai de temporisation de s√©maphore a expir√©]
2025-08-05 09:41:29,667 - livekit.agents - WARNING - failed to connect to livekit, retrying in 6s
Traceback (most recent call last):
  File "C:\Users\y.djemai\pam-testdrive\MARK_I\backend_python\agents\venv\Lib\site-packages\aiohttp\connector.py", line 1268, in _wrap_create_connection
    sock = await aiohappyeyeballs.start_connection(
           ^^^^^^^^^^^^^^^^^^^^^^^^^^^^^^^^^^^^^^^^
  File "C:\Users\y.djemai\pam-testdrive\MARK_I\backend_python\agents\venv\Lib\site-packages\aiohappyeyeballs\impl.py", line 122, in start_connection
    raise first_exception
  File "C:\Users\y.djemai\pam-testdrive\MARK_I\backend_python\agents\venv\Lib\site-packages\aiohappyeyeballs\impl.py", line 73, in start_connection
    sock = await _connect_sock(
           ^^^^^^^^^^^^^^^^^^^^
  File "C:\Users\y.djemai\pam-testdrive\MARK_I\backend_python\agents\venv\Lib\site-packages\aiohappyeyeballs\impl.py", line 208, in _connect_sock
    await loop.sock_connect(sock, address)
  File "C:\Program Files\Python312\Lib\asyncio\proactor_events.py", line 727, in sock_connect
    return await self._proactor.connect(sock, address)
           ^^^^^^^^^^^^^^^^^^^^^^^^^^^^^^^^^^^^^^^^^^^
  File "C:\Program Files\Python312\Lib\asyncio\windows_events.py", line 803, in _poll
    value = callback(transferred, key, ov)
            ^^^^^^^^^^^^^^^^^^^^^^^^^^^^^^
  File "C:\Program Files\Python312\Lib\asyncio\windows_events.py", line 599, in finish_connect
    ov.getresult()
OSError: [WinError 121] Le d√©lai de temporisation de s√©maphore a expir√©

The above exception was the direct cause of the following exception:

Traceback (most recent call last):
  File "C:\Users\y.djemai\pam-testdrive\MARK_I\backend_python\agents\venv\Lib\site-packages\livekit\agents\worker.py", line 653, in _connection_task
    ws = await self._http_session.ws_connect(
         ^^^^^^^^^^^^^^^^^^^^^^^^^^^^^^^^^^^^
  File "C:\Users\y.djemai\pam-testdrive\MARK_I\backend_python\agents\venv\Lib\site-packages\aiohttp\client.py", line 1067, in _ws_connect
    resp = await self.request(
           ^^^^^^^^^^^^^^^^^^^
  File "C:\Users\y.djemai\pam-testdrive\MARK_I\backend_python\agents\venv\Lib\site-packages\aiohttp\client.py", line 770, in _request
    resp = await handler(req)
           ^^^^^^^^^^^^^^^^^^
  File "C:\Users\y.djemai\pam-testdrive\MARK_I\backend_python\agents\venv\Lib\site-packages\aiohttp\client.py", line 725, in _connect_and_send_request
    conn = await self._connector.connect(
           ^^^^^^^^^^^^^^^^^^^^^^^^^^^^^^
  File "C:\Users\y.djemai\pam-testdrive\MARK_I\backend_python\agents\venv\Lib\site-packages\aiohttp\connector.py", line 642, in connect
    proto = await self._create_connection(req, traces, timeout)
            ^^^^^^^^^^^^^^^^^^^^^^^^^^^^^^^^^^^^^^^^^^^^^^^^^^^
  File "C:\Users\y.djemai\pam-testdrive\MARK_I\backend_python\agents\venv\Lib\site-packages\aiohttp\connector.py", line 1209, in _create_connection
    _, proto = await self._create_direct_connection(req, traces, timeout)
               ^^^^^^^^^^^^^^^^^^^^^^^^^^^^^^^^^^^^^^^^^^^^^^^^^^^^^^^^^^
  File "C:\Users\y.djemai\pam-testdrive\MARK_I\backend_python\agents\venv\Lib\site-packages\aiohttp\connector.py", line 1581, in _create_direct_connection
    raise last_exc
  File "C:\Users\y.djemai\pam-testdrive\MARK_I\backend_python\agents\venv\Lib\site-packages\aiohttp\connector.py", line 1550, in _create_direct_connection
    transp, proto = await self._wrap_create_connection(
                    ^^^^^^^^^^^^^^^^^^^^^^^^^^^^^^^^^^^
  File "C:\Users\y.djemai\pam-testdrive\MARK_I\backend_python\agents\venv\Lib\site-packages\aiohttp\connector.py", line 1291, in _wrap_create_connection
    raise client_error(req.connection_key, exc) from exc
aiohttp.client_exceptions.ClientConnectorError: Cannot connect to host pamtestdrive-euxn3osq.livekit.cloud:443 ssl:default [Le d√©lai de temporisation de s√©maphore a expir√©]
2025-08-05 09:41:56,734 - livekit.agents - WARNING - failed to connect to livekit, retrying in 8s
Traceback (most recent call last):
  File "C:\Users\y.djemai\pam-testdrive\MARK_I\backend_python\agents\venv\Lib\site-packages\aiohttp\connector.py", line 1268, in _wrap_create_connection
    sock = await aiohappyeyeballs.start_connection(
           ^^^^^^^^^^^^^^^^^^^^^^^^^^^^^^^^^^^^^^^^
  File "C:\Users\y.djemai\pam-testdrive\MARK_I\backend_python\agents\venv\Lib\site-packages\aiohappyeyeballs\impl.py", line 122, in start_connection
    raise first_exception
  File "C:\Users\y.djemai\pam-testdrive\MARK_I\backend_python\agents\venv\Lib\site-packages\aiohappyeyeballs\impl.py", line 73, in start_connection
    sock = await _connect_sock(
           ^^^^^^^^^^^^^^^^^^^^
  File "C:\Users\y.djemai\pam-testdrive\MARK_I\backend_python\agents\venv\Lib\site-packages\aiohappyeyeballs\impl.py", line 208, in _connect_sock
    await loop.sock_connect(sock, address)
  File "C:\Program Files\Python312\Lib\asyncio\proactor_events.py", line 727, in sock_connect
    return await self._proactor.connect(sock, address)
           ^^^^^^^^^^^^^^^^^^^^^^^^^^^^^^^^^^^^^^^^^^^
  File "C:\Program Files\Python312\Lib\asyncio\windows_events.py", line 803, in _poll
    value = callback(transferred, key, ov)
            ^^^^^^^^^^^^^^^^^^^^^^^^^^^^^^
  File "C:\Program Files\Python312\Lib\asyncio\windows_events.py", line 599, in finish_connect
    ov.getresult()
OSError: [WinError 121] Le d√©lai de temporisation de s√©maphore a expir√©

The above exception was the direct cause of the following exception:

Traceback (most recent call last):
  File "C:\Users\y.djemai\pam-testdrive\MARK_I\backend_python\agents\venv\Lib\site-packages\livekit\agents\worker.py", line 653, in _connection_task
    ws = await self._http_session.ws_connect(
         ^^^^^^^^^^^^^^^^^^^^^^^^^^^^^^^^^^^^
  File "C:\Users\y.djemai\pam-testdrive\MARK_I\backend_python\agents\venv\Lib\site-packages\aiohttp\client.py", line 1067, in _ws_connect
    resp = await self.request(
           ^^^^^^^^^^^^^^^^^^^
  File "C:\Users\y.djemai\pam-testdrive\MARK_I\backend_python\agents\venv\Lib\site-packages\aiohttp\client.py", line 770, in _request
    resp = await handler(req)
           ^^^^^^^^^^^^^^^^^^
  File "C:\Users\y.djemai\pam-testdrive\MARK_I\backend_python\agents\venv\Lib\site-packages\aiohttp\client.py", line 725, in _connect_and_send_request
    conn = await self._connector.connect(
           ^^^^^^^^^^^^^^^^^^^^^^^^^^^^^^
  File "C:\Users\y.djemai\pam-testdrive\MARK_I\backend_python\agents\venv\Lib\site-packages\aiohttp\connector.py", line 642, in connect
    proto = await self._create_connection(req, traces, timeout)
            ^^^^^^^^^^^^^^^^^^^^^^^^^^^^^^^^^^^^^^^^^^^^^^^^^^^
  File "C:\Users\y.djemai\pam-testdrive\MARK_I\backend_python\agents\venv\Lib\site-packages\aiohttp\connector.py", line 1209, in _create_connection
    _, proto = await self._create_direct_connection(req, traces, timeout)
               ^^^^^^^^^^^^^^^^^^^^^^^^^^^^^^^^^^^^^^^^^^^^^^^^^^^^^^^^^^
  File "C:\Users\y.djemai\pam-testdrive\MARK_I\backend_python\agents\venv\Lib\site-packages\aiohttp\connector.py", line 1581, in _create_direct_connection
    raise last_exc
  File "C:\Users\y.djemai\pam-testdrive\MARK_I\backend_python\agents\venv\Lib\site-packages\aiohttp\connector.py", line 1550, in _create_direct_connection
    transp, proto = await self._wrap_create_connection(
                    ^^^^^^^^^^^^^^^^^^^^^^^^^^^^^^^^^^^
  File "C:\Users\y.djemai\pam-testdrive\MARK_I\backend_python\agents\venv\Lib\site-packages\aiohttp\connector.py", line 1291, in _wrap_create_connection
    raise client_error(req.connection_key, exc) from exc
aiohttp.client_exceptions.ClientConnectorError: Cannot connect to host pamtestdrive-euxn3osq.livekit.cloud:443 ssl:default [Le d√©lai de temporisation de s√©maphore a expir√©]
2025-08-05 09:42:25,790 - livekit.agents - WARNING - failed to connect to livekit, retrying in 10s
Traceback (most recent call last):
  File "C:\Users\y.djemai\pam-testdrive\MARK_I\backend_python\agents\venv\Lib\site-packages\aiohttp\connector.py", line 1268, in _wrap_create_connection
    sock = await aiohappyeyeballs.start_connection(
           ^^^^^^^^^^^^^^^^^^^^^^^^^^^^^^^^^^^^^^^^
  File "C:\Users\y.djemai\pam-testdrive\MARK_I\backend_python\agents\venv\Lib\site-packages\aiohappyeyeballs\impl.py", line 122, in start_connection
    raise first_exception
  File "C:\Users\y.djemai\pam-testdrive\MARK_I\backend_python\agents\venv\Lib\site-packages\aiohappyeyeballs\impl.py", line 73, in start_connection
    sock = await _connect_sock(
           ^^^^^^^^^^^^^^^^^^^^
  File "C:\Users\y.djemai\pam-testdrive\MARK_I\backend_python\agents\venv\Lib\site-packages\aiohappyeyeballs\impl.py", line 208, in _connect_sock
    await loop.sock_connect(sock, address)
  File "C:\Program Files\Python312\Lib\asyncio\proactor_events.py", line 727, in sock_connect
    return await self._proactor.connect(sock, address)
           ^^^^^^^^^^^^^^^^^^^^^^^^^^^^^^^^^^^^^^^^^^^
  File "C:\Program Files\Python312\Lib\asyncio\windows_events.py", line 803, in _poll
    value = callback(transferred, key, ov)
            ^^^^^^^^^^^^^^^^^^^^^^^^^^^^^^
  File "C:\Program Files\Python312\Lib\asyncio\windows_events.py", line 599, in finish_connect
    ov.getresult()
OSError: [WinError 121] Le d√©lai de temporisation de s√©maphore a expir√©

The above exception was the direct cause of the following exception:

Traceback (most recent call last):
  File "C:\Users\y.djemai\pam-testdrive\MARK_I\backend_python\agents\venv\Lib\site-packages\livekit\agents\worker.py", line 653, in _connection_task
    ws = await self._http_session.ws_connect(
         ^^^^^^^^^^^^^^^^^^^^^^^^^^^^^^^^^^^^
  File "C:\Users\y.djemai\pam-testdrive\MARK_I\backend_python\agents\venv\Lib\site-packages\aiohttp\client.py", line 1067, in _ws_connect
    resp = await self.request(
           ^^^^^^^^^^^^^^^^^^^
  File "C:\Users\y.djemai\pam-testdrive\MARK_I\backend_python\agents\venv\Lib\site-packages\aiohttp\client.py", line 770, in _request
    resp = await handler(req)
           ^^^^^^^^^^^^^^^^^^
  File "C:\Users\y.djemai\pam-testdrive\MARK_I\backend_python\agents\venv\Lib\site-packages\aiohttp\client.py", line 725, in _connect_and_send_request
    conn = await self._connector.connect(
           ^^^^^^^^^^^^^^^^^^^^^^^^^^^^^^
  File "C:\Users\y.djemai\pam-testdrive\MARK_I\backend_python\agents\venv\Lib\site-packages\aiohttp\connector.py", line 642, in connect
    proto = await self._create_connection(req, traces, timeout)
            ^^^^^^^^^^^^^^^^^^^^^^^^^^^^^^^^^^^^^^^^^^^^^^^^^^^
  File "C:\Users\y.djemai\pam-testdrive\MARK_I\backend_python\agents\venv\Lib\site-packages\aiohttp\connector.py", line 1209, in _create_connection
    _, proto = await self._create_direct_connection(req, traces, timeout)
               ^^^^^^^^^^^^^^^^^^^^^^^^^^^^^^^^^^^^^^^^^^^^^^^^^^^^^^^^^^
  File "C:\Users\y.djemai\pam-testdrive\MARK_I\backend_python\agents\venv\Lib\site-packages\aiohttp\connector.py", line 1581, in _create_direct_connection
    raise last_exc
  File "C:\Users\y.djemai\pam-testdrive\MARK_I\backend_python\agents\venv\Lib\site-packages\aiohttp\connector.py", line 1550, in _create_direct_connection
    transp, proto = await self._wrap_create_connection(
                    ^^^^^^^^^^^^^^^^^^^^^^^^^^^^^^^^^^^
  File "C:\Users\y.djemai\pam-testdrive\MARK_I\backend_python\agents\venv\Lib\site-packages\aiohttp\connector.py", line 1291, in _wrap_create_connection
    raise client_error(req.connection_key, exc) from exc
aiohttp.client_exceptions.ClientConnectorError: Cannot connect to host pamtestdrive-euxn3osq.livekit.cloud:443 ssl:default [Le d√©lai de temporisation de s√©maphore a expir√©]
2025-08-05 09:42:56,816 - livekit.agents - WARNING - failed to connect to livekit, retrying in 10s
Traceback (most recent call last):
  File "C:\Users\y.djemai\pam-testdrive\MARK_I\backend_python\agents\venv\Lib\site-packages\aiohttp\connector.py", line 1268, in _wrap_create_connection
    sock = await aiohappyeyeballs.start_connection(
           ^^^^^^^^^^^^^^^^^^^^^^^^^^^^^^^^^^^^^^^^
  File "C:\Users\y.djemai\pam-testdrive\MARK_I\backend_python\agents\venv\Lib\site-packages\aiohappyeyeballs\impl.py", line 122, in start_connection
    raise first_exception
  File "C:\Users\y.djemai\pam-testdrive\MARK_I\backend_python\agents\venv\Lib\site-packages\aiohappyeyeballs\impl.py", line 73, in start_connection
    sock = await _connect_sock(
           ^^^^^^^^^^^^^^^^^^^^
  File "C:\Users\y.djemai\pam-testdrive\MARK_I\backend_python\agents\venv\Lib\site-packages\aiohappyeyeballs\impl.py", line 208, in _connect_sock
    await loop.sock_connect(sock, address)
  File "C:\Program Files\Python312\Lib\asyncio\proactor_events.py", line 727, in sock_connect
    return await self._proactor.connect(sock, address)
           ^^^^^^^^^^^^^^^^^^^^^^^^^^^^^^^^^^^^^^^^^^^
  File "C:\Program Files\Python312\Lib\asyncio\windows_events.py", line 803, in _poll
    value = callback(transferred, key, ov)
            ^^^^^^^^^^^^^^^^^^^^^^^^^^^^^^
  File "C:\Program Files\Python312\Lib\asyncio\windows_events.py", line 599, in finish_connect
    ov.getresult()
OSError: [WinError 121] Le d√©lai de temporisation de s√©maphore a expir√©

The above exception was the direct cause of the following exception:

Traceback (most recent call last):
  File "C:\Users\y.djemai\pam-testdrive\MARK_I\backend_python\agents\venv\Lib\site-packages\livekit\agents\worker.py", line 653, in _connection_task
    ws = await self._http_session.ws_connect(
         ^^^^^^^^^^^^^^^^^^^^^^^^^^^^^^^^^^^^
  File "C:\Users\y.djemai\pam-testdrive\MARK_I\backend_python\agents\venv\Lib\site-packages\aiohttp\client.py", line 1067, in _ws_connect
    resp = await self.request(
           ^^^^^^^^^^^^^^^^^^^
  File "C:\Users\y.djemai\pam-testdrive\MARK_I\backend_python\agents\venv\Lib\site-packages\aiohttp\client.py", line 770, in _request
    resp = await handler(req)
           ^^^^^^^^^^^^^^^^^^
  File "C:\Users\y.djemai\pam-testdrive\MARK_I\backend_python\agents\venv\Lib\site-packages\aiohttp\client.py", line 725, in _connect_and_send_request
    conn = await self._connector.connect(
           ^^^^^^^^^^^^^^^^^^^^^^^^^^^^^^
  File "C:\Users\y.djemai\pam-testdrive\MARK_I\backend_python\agents\venv\Lib\site-packages\aiohttp\connector.py", line 642, in connect
    proto = await self._create_connection(req, traces, timeout)
            ^^^^^^^^^^^^^^^^^^^^^^^^^^^^^^^^^^^^^^^^^^^^^^^^^^^
  File "C:\Users\y.djemai\pam-testdrive\MARK_I\backend_python\agents\venv\Lib\site-packages\aiohttp\connector.py", line 1209, in _create_connection
    _, proto = await self._create_direct_connection(req, traces, timeout)
               ^^^^^^^^^^^^^^^^^^^^^^^^^^^^^^^^^^^^^^^^^^^^^^^^^^^^^^^^^^
  File "C:\Users\y.djemai\pam-testdrive\MARK_I\backend_python\agents\venv\Lib\site-packages\aiohttp\connector.py", line 1581, in _create_direct_connection
    raise last_exc
  File "C:\Users\y.djemai\pam-testdrive\MARK_I\backend_python\agents\venv\Lib\site-packages\aiohttp\connector.py", line 1550, in _create_direct_connection
    transp, proto = await self._wrap_create_connection(
                    ^^^^^^^^^^^^^^^^^^^^^^^^^^^^^^^^^^^
  File "C:\Users\y.djemai\pam-testdrive\MARK_I\backend_python\agents\venv\Lib\site-packages\aiohttp\connector.py", line 1291, in _wrap_create_connection
    raise client_error(req.connection_key, exc) from exc
aiohttp.client_exceptions.ClientConnectorError: Cannot connect to host pamtestdrive-euxn3osq.livekit.cloud:443 ssl:default [Le d√©lai de temporisation de s√©maphore a expir√©]
2025-08-05 09:43:27,870 - livekit.agents - WARNING - failed to connect to livekit, retrying in 10s
Traceback (most recent call last):
  File "C:\Users\y.djemai\pam-testdrive\MARK_I\backend_python\agents\venv\Lib\site-packages\aiohttp\connector.py", line 1268, in _wrap_create_connection
    sock = await aiohappyeyeballs.start_connection(
           ^^^^^^^^^^^^^^^^^^^^^^^^^^^^^^^^^^^^^^^^
  File "C:\Users\y.djemai\pam-testdrive\MARK_I\backend_python\agents\venv\Lib\site-packages\aiohappyeyeballs\impl.py", line 122, in start_connection
    raise first_exception
  File "C:\Users\y.djemai\pam-testdrive\MARK_I\backend_python\agents\venv\Lib\site-packages\aiohappyeyeballs\impl.py", line 73, in start_connection
    sock = await _connect_sock(
           ^^^^^^^^^^^^^^^^^^^^
  File "C:\Users\y.djemai\pam-testdrive\MARK_I\backend_python\agents\venv\Lib\site-packages\aiohappyeyeballs\impl.py", line 208, in _connect_sock
    await loop.sock_connect(sock, address)
  File "C:\Program Files\Python312\Lib\asyncio\proactor_events.py", line 727, in sock_connect
    return await self._proactor.connect(sock, address)
           ^^^^^^^^^^^^^^^^^^^^^^^^^^^^^^^^^^^^^^^^^^^
  File "C:\Program Files\Python312\Lib\asyncio\windows_events.py", line 803, in _poll
    value = callback(transferred, key, ov)
            ^^^^^^^^^^^^^^^^^^^^^^^^^^^^^^
  File "C:\Program Files\Python312\Lib\asyncio\windows_events.py", line 599, in finish_connect
    ov.getresult()
OSError: [WinError 121] Le d√©lai de temporisation de s√©maphore a expir√©

The above exception was the direct cause of the following exception:

Traceback (most recent call last):
  File "C:\Users\y.djemai\pam-testdrive\MARK_I\backend_python\agents\venv\Lib\site-packages\livekit\agents\worker.py", line 653, in _connection_task
    ws = await self._http_session.ws_connect(
         ^^^^^^^^^^^^^^^^^^^^^^^^^^^^^^^^^^^^
  File "C:\Users\y.djemai\pam-testdrive\MARK_I\backend_python\agents\venv\Lib\site-packages\aiohttp\client.py", line 1067, in _ws_connect
    resp = await self.request(
           ^^^^^^^^^^^^^^^^^^^
  File "C:\Users\y.djemai\pam-testdrive\MARK_I\backend_python\agents\venv\Lib\site-packages\aiohttp\client.py", line 770, in _request
    resp = await handler(req)
           ^^^^^^^^^^^^^^^^^^
  File "C:\Users\y.djemai\pam-testdrive\MARK_I\backend_python\agents\venv\Lib\site-packages\aiohttp\client.py", line 725, in _connect_and_send_request
    conn = await self._connector.connect(
           ^^^^^^^^^^^^^^^^^^^^^^^^^^^^^^
  File "C:\Users\y.djemai\pam-testdrive\MARK_I\backend_python\agents\venv\Lib\site-packages\aiohttp\connector.py", line 642, in connect
    proto = await self._create_connection(req, traces, timeout)
            ^^^^^^^^^^^^^^^^^^^^^^^^^^^^^^^^^^^^^^^^^^^^^^^^^^^
  File "C:\Users\y.djemai\pam-testdrive\MARK_I\backend_python\agents\venv\Lib\site-packages\aiohttp\connector.py", line 1209, in _create_connection
    _, proto = await self._create_direct_connection(req, traces, timeout)
               ^^^^^^^^^^^^^^^^^^^^^^^^^^^^^^^^^^^^^^^^^^^^^^^^^^^^^^^^^^
  File "C:\Users\y.djemai\pam-testdrive\MARK_I\backend_python\agents\venv\Lib\site-packages\aiohttp\connector.py", line 1581, in _create_direct_connection
    raise last_exc
  File "C:\Users\y.djemai\pam-testdrive\MARK_I\backend_python\agents\venv\Lib\site-packages\aiohttp\connector.py", line 1550, in _create_direct_connection
    transp, proto = await self._wrap_create_connection(
                    ^^^^^^^^^^^^^^^^^^^^^^^^^^^^^^^^^^^
  File "C:\Users\y.djemai\pam-testdrive\MARK_I\backend_python\agents\venv\Lib\site-packages\aiohttp\connector.py", line 1291, in _wrap_create_connection
    raise client_error(req.connection_key, exc) from exc
aiohttp.client_exceptions.ClientConnectorError: Cannot connect to host pamtestdrive-euxn3osq.livekit.cloud:443 ssl:default [Le d√©lai de temporisation de s√©maphore a expir√©]
2025-08-05 09:43:58,959 - livekit.agents - WARNING - failed to connect to livekit, retrying in 10s
Traceback (most recent call last):
  File "C:\Users\y.djemai\pam-testdrive\MARK_I\backend_python\agents\venv\Lib\site-packages\aiohttp\connector.py", line 1268, in _wrap_create_connection
    sock = await aiohappyeyeballs.start_connection(
           ^^^^^^^^^^^^^^^^^^^^^^^^^^^^^^^^^^^^^^^^
  File "C:\Users\y.djemai\pam-testdrive\MARK_I\backend_python\agents\venv\Lib\site-packages\aiohappyeyeballs\impl.py", line 122, in start_connection
    raise first_exception
  File "C:\Users\y.djemai\pam-testdrive\MARK_I\backend_python\agents\venv\Lib\site-packages\aiohappyeyeballs\impl.py", line 73, in start_connection
    sock = await _connect_sock(
           ^^^^^^^^^^^^^^^^^^^^
  File "C:\Users\y.djemai\pam-testdrive\MARK_I\backend_python\agents\venv\Lib\site-packages\aiohappyeyeballs\impl.py", line 208, in _connect_sock
    await loop.sock_connect(sock, address)
  File "C:\Program Files\Python312\Lib\asyncio\proactor_events.py", line 727, in sock_connect
    return await self._proactor.connect(sock, address)
           ^^^^^^^^^^^^^^^^^^^^^^^^^^^^^^^^^^^^^^^^^^^
  File "C:\Program Files\Python312\Lib\asyncio\windows_events.py", line 803, in _poll
    value = callback(transferred, key, ov)
            ^^^^^^^^^^^^^^^^^^^^^^^^^^^^^^
  File "C:\Program Files\Python312\Lib\asyncio\windows_events.py", line 599, in finish_connect
    ov.getresult()
OSError: [WinError 121] Le d√©lai de temporisation de s√©maphore a expir√©

The above exception was the direct cause of the following exception:

Traceback (most recent call last):
  File "C:\Users\y.djemai\pam-testdrive\MARK_I\backend_python\agents\venv\Lib\site-packages\livekit\agents\worker.py", line 653, in _connection_task
    ws = await self._http_session.ws_connect(
         ^^^^^^^^^^^^^^^^^^^^^^^^^^^^^^^^^^^^
  File "C:\Users\y.djemai\pam-testdrive\MARK_I\backend_python\agents\venv\Lib\site-packages\aiohttp\client.py", line 1067, in _ws_connect
    resp = await self.request(
           ^^^^^^^^^^^^^^^^^^^
  File "C:\Users\y.djemai\pam-testdrive\MARK_I\backend_python\agents\venv\Lib\site-packages\aiohttp\client.py", line 770, in _request
    resp = await handler(req)
           ^^^^^^^^^^^^^^^^^^
  File "C:\Users\y.djemai\pam-testdrive\MARK_I\backend_python\agents\venv\Lib\site-packages\aiohttp\client.py", line 725, in _connect_and_send_request
    conn = await self._connector.connect(
           ^^^^^^^^^^^^^^^^^^^^^^^^^^^^^^
  File "C:\Users\y.djemai\pam-testdrive\MARK_I\backend_python\agents\venv\Lib\site-packages\aiohttp\connector.py", line 642, in connect
    proto = await self._create_connection(req, traces, timeout)
            ^^^^^^^^^^^^^^^^^^^^^^^^^^^^^^^^^^^^^^^^^^^^^^^^^^^
  File "C:\Users\y.djemai\pam-testdrive\MARK_I\backend_python\agents\venv\Lib\site-packages\aiohttp\connector.py", line 1209, in _create_connection
    _, proto = await self._create_direct_connection(req, traces, timeout)
               ^^^^^^^^^^^^^^^^^^^^^^^^^^^^^^^^^^^^^^^^^^^^^^^^^^^^^^^^^^
  File "C:\Users\y.djemai\pam-testdrive\MARK_I\backend_python\agents\venv\Lib\site-packages\aiohttp\connector.py", line 1581, in _create_direct_connection
    raise last_exc
  File "C:\Users\y.djemai\pam-testdrive\MARK_I\backend_python\agents\venv\Lib\site-packages\aiohttp\connector.py", line 1550, in _create_direct_connection
    transp, proto = await self._wrap_create_connection(
                    ^^^^^^^^^^^^^^^^^^^^^^^^^^^^^^^^^^^
  File "C:\Users\y.djemai\pam-testdrive\MARK_I\backend_python\agents\venv\Lib\site-packages\aiohttp\connector.py", line 1291, in _wrap_create_connection
    raise client_error(req.connection_key, exc) from exc
aiohttp.client_exceptions.ClientConnectorError: Cannot connect to host pamtestdrive-euxn3osq.livekit.cloud:443 ssl:default [Le d√©lai de temporisation de s√©maphore a expir√©]
2025-08-05 09:44:30,024 - livekit.agents - WARNING - failed to connect to livekit, retrying in 10s
Traceback (most recent call last):
  File "C:\Users\y.djemai\pam-testdrive\MARK_I\backend_python\agents\venv\Lib\site-packages\aiohttp\connector.py", line 1268, in _wrap_create_connection
    sock = await aiohappyeyeballs.start_connection(
           ^^^^^^^^^^^^^^^^^^^^^^^^^^^^^^^^^^^^^^^^
  File "C:\Users\y.djemai\pam-testdrive\MARK_I\backend_python\agents\venv\Lib\site-packages\aiohappyeyeballs\impl.py", line 122, in start_connection
    raise first_exception
  File "C:\Users\y.djemai\pam-testdrive\MARK_I\backend_python\agents\venv\Lib\site-packages\aiohappyeyeballs\impl.py", line 73, in start_connection
    sock = await _connect_sock(
           ^^^^^^^^^^^^^^^^^^^^
  File "C:\Users\y.djemai\pam-testdrive\MARK_I\backend_python\agents\venv\Lib\site-packages\aiohappyeyeballs\impl.py", line 208, in _connect_sock
    await loop.sock_connect(sock, address)
  File "C:\Program Files\Python312\Lib\asyncio\proactor_events.py", line 727, in sock_connect
    return await self._proactor.connect(sock, address)
           ^^^^^^^^^^^^^^^^^^^^^^^^^^^^^^^^^^^^^^^^^^^
  File "C:\Program Files\Python312\Lib\asyncio\windows_events.py", line 803, in _poll
    value = callback(transferred, key, ov)
            ^^^^^^^^^^^^^^^^^^^^^^^^^^^^^^
  File "C:\Program Files\Python312\Lib\asyncio\windows_events.py", line 599, in finish_connect
    ov.getresult()
OSError: [WinError 121] Le d√©lai de temporisation de s√©maphore a expir√©

The above exception was the direct cause of the following exception:

Traceback (most recent call last):
  File "C:\Users\y.djemai\pam-testdrive\MARK_I\backend_python\agents\venv\Lib\site-packages\livekit\agents\worker.py", line 653, in _connection_task
    ws = await self._http_session.ws_connect(
         ^^^^^^^^^^^^^^^^^^^^^^^^^^^^^^^^^^^^
  File "C:\Users\y.djemai\pam-testdrive\MARK_I\backend_python\agents\venv\Lib\site-packages\aiohttp\client.py", line 1067, in _ws_connect
    resp = await self.request(
           ^^^^^^^^^^^^^^^^^^^
  File "C:\Users\y.djemai\pam-testdrive\MARK_I\backend_python\agents\venv\Lib\site-packages\aiohttp\client.py", line 770, in _request
    resp = await handler(req)
           ^^^^^^^^^^^^^^^^^^
  File "C:\Users\y.djemai\pam-testdrive\MARK_I\backend_python\agents\venv\Lib\site-packages\aiohttp\client.py", line 725, in _connect_and_send_request
    conn = await self._connector.connect(
           ^^^^^^^^^^^^^^^^^^^^^^^^^^^^^^
  File "C:\Users\y.djemai\pam-testdrive\MARK_I\backend_python\agents\venv\Lib\site-packages\aiohttp\connector.py", line 642, in connect
    proto = await self._create_connection(req, traces, timeout)
            ^^^^^^^^^^^^^^^^^^^^^^^^^^^^^^^^^^^^^^^^^^^^^^^^^^^
  File "C:\Users\y.djemai\pam-testdrive\MARK_I\backend_python\agents\venv\Lib\site-packages\aiohttp\connector.py", line 1209, in _create_connection
    _, proto = await self._create_direct_connection(req, traces, timeout)
               ^^^^^^^^^^^^^^^^^^^^^^^^^^^^^^^^^^^^^^^^^^^^^^^^^^^^^^^^^^
  File "C:\Users\y.djemai\pam-testdrive\MARK_I\backend_python\agents\venv\Lib\site-packages\aiohttp\connector.py", line 1581, in _create_direct_connection
    raise last_exc
  File "C:\Users\y.djemai\pam-testdrive\MARK_I\backend_python\agents\venv\Lib\site-packages\aiohttp\connector.py", line 1550, in _create_direct_connection
    transp, proto = await self._wrap_create_connection(
                    ^^^^^^^^^^^^^^^^^^^^^^^^^^^^^^^^^^^
  File "C:\Users\y.djemai\pam-testdrive\MARK_I\backend_python\agents\venv\Lib\site-packages\aiohttp\connector.py", line 1291, in _wrap_create_connection
    raise client_error(req.connection_key, exc) from exc
aiohttp.client_exceptions.ClientConnectorError: Cannot connect to host pamtestdrive-euxn3osq.livekit.cloud:443 ssl:default [Le d√©lai de temporisation de s√©maphore a expir√©]
2025-08-05 09:45:01,095 - livekit.agents - WARNING - failed to connect to livekit, retrying in 10s
Traceback (most recent call last):
  File "C:\Users\y.djemai\pam-testdrive\MARK_I\backend_python\agents\venv\Lib\site-packages\aiohttp\connector.py", line 1268, in _wrap_create_connection
    sock = await aiohappyeyeballs.start_connection(
           ^^^^^^^^^^^^^^^^^^^^^^^^^^^^^^^^^^^^^^^^
  File "C:\Users\y.djemai\pam-testdrive\MARK_I\backend_python\agents\venv\Lib\site-packages\aiohappyeyeballs\impl.py", line 122, in start_connection
    raise first_exception
  File "C:\Users\y.djemai\pam-testdrive\MARK_I\backend_python\agents\venv\Lib\site-packages\aiohappyeyeballs\impl.py", line 73, in start_connection
    sock = await _connect_sock(
           ^^^^^^^^^^^^^^^^^^^^
  File "C:\Users\y.djemai\pam-testdrive\MARK_I\backend_python\agents\venv\Lib\site-packages\aiohappyeyeballs\impl.py", line 208, in _connect_sock
    await loop.sock_connect(sock, address)
  File "C:\Program Files\Python312\Lib\asyncio\proactor_events.py", line 727, in sock_connect
    return await self._proactor.connect(sock, address)
           ^^^^^^^^^^^^^^^^^^^^^^^^^^^^^^^^^^^^^^^^^^^
  File "C:\Program Files\Python312\Lib\asyncio\windows_events.py", line 803, in _poll
    value = callback(transferred, key, ov)
            ^^^^^^^^^^^^^^^^^^^^^^^^^^^^^^
  File "C:\Program Files\Python312\Lib\asyncio\windows_events.py", line 599, in finish_connect
    ov.getresult()
OSError: [WinError 121] Le d√©lai de temporisation de s√©maphore a expir√©

The above exception was the direct cause of the following exception:

Traceback (most recent call last):
  File "C:\Users\y.djemai\pam-testdrive\MARK_I\backend_python\agents\venv\Lib\site-packages\livekit\agents\worker.py", line 653, in _connection_task
    ws = await self._http_session.ws_connect(
         ^^^^^^^^^^^^^^^^^^^^^^^^^^^^^^^^^^^^
  File "C:\Users\y.djemai\pam-testdrive\MARK_I\backend_python\agents\venv\Lib\site-packages\aiohttp\client.py", line 1067, in _ws_connect
    resp = await self.request(
           ^^^^^^^^^^^^^^^^^^^
  File "C:\Users\y.djemai\pam-testdrive\MARK_I\backend_python\agents\venv\Lib\site-packages\aiohttp\client.py", line 770, in _request
    resp = await handler(req)
           ^^^^^^^^^^^^^^^^^^
  File "C:\Users\y.djemai\pam-testdrive\MARK_I\backend_python\agents\venv\Lib\site-packages\aiohttp\client.py", line 725, in _connect_and_send_request
    conn = await self._connector.connect(
           ^^^^^^^^^^^^^^^^^^^^^^^^^^^^^^
  File "C:\Users\y.djemai\pam-testdrive\MARK_I\backend_python\agents\venv\Lib\site-packages\aiohttp\connector.py", line 642, in connect
    proto = await self._create_connection(req, traces, timeout)
            ^^^^^^^^^^^^^^^^^^^^^^^^^^^^^^^^^^^^^^^^^^^^^^^^^^^
  File "C:\Users\y.djemai\pam-testdrive\MARK_I\backend_python\agents\venv\Lib\site-packages\aiohttp\connector.py", line 1209, in _create_connection
    _, proto = await self._create_direct_connection(req, traces, timeout)
               ^^^^^^^^^^^^^^^^^^^^^^^^^^^^^^^^^^^^^^^^^^^^^^^^^^^^^^^^^^
  File "C:\Users\y.djemai\pam-testdrive\MARK_I\backend_python\agents\venv\Lib\site-packages\aiohttp\connector.py", line 1581, in _create_direct_connection
    raise last_exc
  File "C:\Users\y.djemai\pam-testdrive\MARK_I\backend_python\agents\venv\Lib\site-packages\aiohttp\connector.py", line 1550, in _create_direct_connection
    transp, proto = await self._wrap_create_connection(
                    ^^^^^^^^^^^^^^^^^^^^^^^^^^^^^^^^^^^
  File "C:\Users\y.djemai\pam-testdrive\MARK_I\backend_python\agents\venv\Lib\site-packages\aiohttp\connector.py", line 1291, in _wrap_create_connection
    raise client_error(req.connection_key, exc) from exc
aiohttp.client_exceptions.ClientConnectorError: Cannot connect to host pamtestdrive-euxn3osq.livekit.cloud:443 ssl:default [Le d√©lai de temporisation de s√©maphore a expir√©]
2025-08-05 09:45:32,148 - livekit.agents - WARNING - failed to connect to livekit, retrying in 10s
Traceback (most recent call last):
  File "C:\Users\y.djemai\pam-testdrive\MARK_I\backend_python\agents\venv\Lib\site-packages\aiohttp\connector.py", line 1268, in _wrap_create_connection
    sock = await aiohappyeyeballs.start_connection(
           ^^^^^^^^^^^^^^^^^^^^^^^^^^^^^^^^^^^^^^^^
  File "C:\Users\y.djemai\pam-testdrive\MARK_I\backend_python\agents\venv\Lib\site-packages\aiohappyeyeballs\impl.py", line 122, in start_connection
    raise first_exception
  File "C:\Users\y.djemai\pam-testdrive\MARK_I\backend_python\agents\venv\Lib\site-packages\aiohappyeyeballs\impl.py", line 73, in start_connection
    sock = await _connect_sock(
           ^^^^^^^^^^^^^^^^^^^^
  File "C:\Users\y.djemai\pam-testdrive\MARK_I\backend_python\agents\venv\Lib\site-packages\aiohappyeyeballs\impl.py", line 208, in _connect_sock
    await loop.sock_connect(sock, address)
  File "C:\Program Files\Python312\Lib\asyncio\proactor_events.py", line 727, in sock_connect
    return await self._proactor.connect(sock, address)
           ^^^^^^^^^^^^^^^^^^^^^^^^^^^^^^^^^^^^^^^^^^^
  File "C:\Program Files\Python312\Lib\asyncio\windows_events.py", line 803, in _poll
    value = callback(transferred, key, ov)
            ^^^^^^^^^^^^^^^^^^^^^^^^^^^^^^
  File "C:\Program Files\Python312\Lib\asyncio\windows_events.py", line 599, in finish_connect
    ov.getresult()
OSError: [WinError 121] Le d√©lai de temporisation de s√©maphore a expir√©

The above exception was the direct cause of the following exception:

Traceback (most recent call last):
  File "C:\Users\y.djemai\pam-testdrive\MARK_I\backend_python\agents\venv\Lib\site-packages\livekit\agents\worker.py", line 653, in _connection_task
    ws = await self._http_session.ws_connect(
         ^^^^^^^^^^^^^^^^^^^^^^^^^^^^^^^^^^^^
  File "C:\Users\y.djemai\pam-testdrive\MARK_I\backend_python\agents\venv\Lib\site-packages\aiohttp\client.py", line 1067, in _ws_connect
    resp = await self.request(
           ^^^^^^^^^^^^^^^^^^^
  File "C:\Users\y.djemai\pam-testdrive\MARK_I\backend_python\agents\venv\Lib\site-packages\aiohttp\client.py", line 770, in _request
    resp = await handler(req)
           ^^^^^^^^^^^^^^^^^^
  File "C:\Users\y.djemai\pam-testdrive\MARK_I\backend_python\agents\venv\Lib\site-packages\aiohttp\client.py", line 725, in _connect_and_send_request
    conn = await self._connector.connect(
           ^^^^^^^^^^^^^^^^^^^^^^^^^^^^^^
  File "C:\Users\y.djemai\pam-testdrive\MARK_I\backend_python\agents\venv\Lib\site-packages\aiohttp\connector.py", line 642, in connect
    proto = await self._create_connection(req, traces, timeout)
            ^^^^^^^^^^^^^^^^^^^^^^^^^^^^^^^^^^^^^^^^^^^^^^^^^^^
  File "C:\Users\y.djemai\pam-testdrive\MARK_I\backend_python\agents\venv\Lib\site-packages\aiohttp\connector.py", line 1209, in _create_connection
    _, proto = await self._create_direct_connection(req, traces, timeout)
               ^^^^^^^^^^^^^^^^^^^^^^^^^^^^^^^^^^^^^^^^^^^^^^^^^^^^^^^^^^
  File "C:\Users\y.djemai\pam-testdrive\MARK_I\backend_python\agents\venv\Lib\site-packages\aiohttp\connector.py", line 1581, in _create_direct_connection
    raise last_exc
  File "C:\Users\y.djemai\pam-testdrive\MARK_I\backend_python\agents\venv\Lib\site-packages\aiohttp\connector.py", line 1550, in _create_direct_connection
    transp, proto = await self._wrap_create_connection(
                    ^^^^^^^^^^^^^^^^^^^^^^^^^^^^^^^^^^^
  File "C:\Users\y.djemai\pam-testdrive\MARK_I\backend_python\agents\venv\Lib\site-packages\aiohttp\connector.py", line 1291, in _wrap_create_connection
    raise client_error(req.connection_key, exc) from exc
aiohttp.client_exceptions.ClientConnectorError: Cannot connect to host pamtestdrive-euxn3osq.livekit.cloud:443 ssl:default [Le d√©lai de temporisation de s√©maphore a expir√©]
2025-08-05 09:46:03,205 - livekit.agents - WARNING - failed to connect to livekit, retrying in 10s
Traceback (most recent call last):
  File "C:\Users\y.djemai\pam-testdrive\MARK_I\backend_python\agents\venv\Lib\site-packages\aiohttp\connector.py", line 1268, in _wrap_create_connection
    sock = await aiohappyeyeballs.start_connection(
           ^^^^^^^^^^^^^^^^^^^^^^^^^^^^^^^^^^^^^^^^
  File "C:\Users\y.djemai\pam-testdrive\MARK_I\backend_python\agents\venv\Lib\site-packages\aiohappyeyeballs\impl.py", line 122, in start_connection
    raise first_exception
  File "C:\Users\y.djemai\pam-testdrive\MARK_I\backend_python\agents\venv\Lib\site-packages\aiohappyeyeballs\impl.py", line 73, in start_connection
    sock = await _connect_sock(
           ^^^^^^^^^^^^^^^^^^^^
  File "C:\Users\y.djemai\pam-testdrive\MARK_I\backend_python\agents\venv\Lib\site-packages\aiohappyeyeballs\impl.py", line 208, in _connect_sock
    await loop.sock_connect(sock, address)
  File "C:\Program Files\Python312\Lib\asyncio\proactor_events.py", line 727, in sock_connect
    return await self._proactor.connect(sock, address)
           ^^^^^^^^^^^^^^^^^^^^^^^^^^^^^^^^^^^^^^^^^^^
  File "C:\Program Files\Python312\Lib\asyncio\windows_events.py", line 803, in _poll
    value = callback(transferred, key, ov)
            ^^^^^^^^^^^^^^^^^^^^^^^^^^^^^^
  File "C:\Program Files\Python312\Lib\asyncio\windows_events.py", line 599, in finish_connect
    ov.getresult()
OSError: [WinError 121] Le d√©lai de temporisation de s√©maphore a expir√©

The above exception was the direct cause of the following exception:

Traceback (most recent call last):
  File "C:\Users\y.djemai\pam-testdrive\MARK_I\backend_python\agents\venv\Lib\site-packages\livekit\agents\worker.py", line 653, in _connection_task
    ws = await self._http_session.ws_connect(
         ^^^^^^^^^^^^^^^^^^^^^^^^^^^^^^^^^^^^
  File "C:\Users\y.djemai\pam-testdrive\MARK_I\backend_python\agents\venv\Lib\site-packages\aiohttp\client.py", line 1067, in _ws_connect
    resp = await self.request(
           ^^^^^^^^^^^^^^^^^^^
  File "C:\Users\y.djemai\pam-testdrive\MARK_I\backend_python\agents\venv\Lib\site-packages\aiohttp\client.py", line 770, in _request
    resp = await handler(req)
           ^^^^^^^^^^^^^^^^^^
  File "C:\Users\y.djemai\pam-testdrive\MARK_I\backend_python\agents\venv\Lib\site-packages\aiohttp\client.py", line 725, in _connect_and_send_request
    conn = await self._connector.connect(
           ^^^^^^^^^^^^^^^^^^^^^^^^^^^^^^
  File "C:\Users\y.djemai\pam-testdrive\MARK_I\backend_python\agents\venv\Lib\site-packages\aiohttp\connector.py", line 642, in connect
    proto = await self._create_connection(req, traces, timeout)
            ^^^^^^^^^^^^^^^^^^^^^^^^^^^^^^^^^^^^^^^^^^^^^^^^^^^
  File "C:\Users\y.djemai\pam-testdrive\MARK_I\backend_python\agents\venv\Lib\site-packages\aiohttp\connector.py", line 1209, in _create_connection
    _, proto = await self._create_direct_connection(req, traces, timeout)
               ^^^^^^^^^^^^^^^^^^^^^^^^^^^^^^^^^^^^^^^^^^^^^^^^^^^^^^^^^^
  File "C:\Users\y.djemai\pam-testdrive\MARK_I\backend_python\agents\venv\Lib\site-packages\aiohttp\connector.py", line 1581, in _create_direct_connection
    raise last_exc
  File "C:\Users\y.djemai\pam-testdrive\MARK_I\backend_python\agents\venv\Lib\site-packages\aiohttp\connector.py", line 1550, in _create_direct_connection
    transp, proto = await self._wrap_create_connection(
                    ^^^^^^^^^^^^^^^^^^^^^^^^^^^^^^^^^^^
  File "C:\Users\y.djemai\pam-testdrive\MARK_I\backend_python\agents\venv\Lib\site-packages\aiohttp\connector.py", line 1291, in _wrap_create_connection
    raise client_error(req.connection_key, exc) from exc
aiohttp.client_exceptions.ClientConnectorError: Cannot connect to host pamtestdrive-euxn3osq.livekit.cloud:443 ssl:default [Le d√©lai de temporisation de s√©maphore a expir√©]
2025-08-05 09:46:34,264 - livekit.agents - WARNING - failed to connect to livekit, retrying in 10s
Traceback (most recent call last):
  File "C:\Users\y.djemai\pam-testdrive\MARK_I\backend_python\agents\venv\Lib\site-packages\aiohttp\connector.py", line 1268, in _wrap_create_connection
    sock = await aiohappyeyeballs.start_connection(
           ^^^^^^^^^^^^^^^^^^^^^^^^^^^^^^^^^^^^^^^^
  File "C:\Users\y.djemai\pam-testdrive\MARK_I\backend_python\agents\venv\Lib\site-packages\aiohappyeyeballs\impl.py", line 122, in start_connection
    raise first_exception
  File "C:\Users\y.djemai\pam-testdrive\MARK_I\backend_python\agents\venv\Lib\site-packages\aiohappyeyeballs\impl.py", line 73, in start_connection
    sock = await _connect_sock(
           ^^^^^^^^^^^^^^^^^^^^
  File "C:\Users\y.djemai\pam-testdrive\MARK_I\backend_python\agents\venv\Lib\site-packages\aiohappyeyeballs\impl.py", line 208, in _connect_sock
    await loop.sock_connect(sock, address)
  File "C:\Program Files\Python312\Lib\asyncio\proactor_events.py", line 727, in sock_connect
    return await self._proactor.connect(sock, address)
           ^^^^^^^^^^^^^^^^^^^^^^^^^^^^^^^^^^^^^^^^^^^
  File "C:\Program Files\Python312\Lib\asyncio\windows_events.py", line 803, in _poll
    value = callback(transferred, key, ov)
            ^^^^^^^^^^^^^^^^^^^^^^^^^^^^^^
  File "C:\Program Files\Python312\Lib\asyncio\windows_events.py", line 599, in finish_connect
    ov.getresult()
OSError: [WinError 121] Le d√©lai de temporisation de s√©maphore a expir√©

The above exception was the direct cause of the following exception:

Traceback (most recent call last):
  File "C:\Users\y.djemai\pam-testdrive\MARK_I\backend_python\agents\venv\Lib\site-packages\livekit\agents\worker.py", line 653, in _connection_task
    ws = await self._http_session.ws_connect(
         ^^^^^^^^^^^^^^^^^^^^^^^^^^^^^^^^^^^^
  File "C:\Users\y.djemai\pam-testdrive\MARK_I\backend_python\agents\venv\Lib\site-packages\aiohttp\client.py", line 1067, in _ws_connect
    resp = await self.request(
           ^^^^^^^^^^^^^^^^^^^
  File "C:\Users\y.djemai\pam-testdrive\MARK_I\backend_python\agents\venv\Lib\site-packages\aiohttp\client.py", line 770, in _request
    resp = await handler(req)
           ^^^^^^^^^^^^^^^^^^
  File "C:\Users\y.djemai\pam-testdrive\MARK_I\backend_python\agents\venv\Lib\site-packages\aiohttp\client.py", line 725, in _connect_and_send_request
    conn = await self._connector.connect(
           ^^^^^^^^^^^^^^^^^^^^^^^^^^^^^^
  File "C:\Users\y.djemai\pam-testdrive\MARK_I\backend_python\agents\venv\Lib\site-packages\aiohttp\connector.py", line 642, in connect
    proto = await self._create_connection(req, traces, timeout)
            ^^^^^^^^^^^^^^^^^^^^^^^^^^^^^^^^^^^^^^^^^^^^^^^^^^^
  File "C:\Users\y.djemai\pam-testdrive\MARK_I\backend_python\agents\venv\Lib\site-packages\aiohttp\connector.py", line 1209, in _create_connection
    _, proto = await self._create_direct_connection(req, traces, timeout)
               ^^^^^^^^^^^^^^^^^^^^^^^^^^^^^^^^^^^^^^^^^^^^^^^^^^^^^^^^^^
  File "C:\Users\y.djemai\pam-testdrive\MARK_I\backend_python\agents\venv\Lib\site-packages\aiohttp\connector.py", line 1581, in _create_direct_connection
    raise last_exc
  File "C:\Users\y.djemai\pam-testdrive\MARK_I\backend_python\agents\venv\Lib\site-packages\aiohttp\connector.py", line 1550, in _create_direct_connection
    transp, proto = await self._wrap_create_connection(
                    ^^^^^^^^^^^^^^^^^^^^^^^^^^^^^^^^^^^
  File "C:\Users\y.djemai\pam-testdrive\MARK_I\backend_python\agents\venv\Lib\site-packages\aiohttp\connector.py", line 1291, in _wrap_create_connection
    raise client_error(req.connection_key, exc) from exc
aiohttp.client_exceptions.ClientConnectorError: Cannot connect to host pamtestdrive-euxn3osq.livekit.cloud:443 ssl:default [Le d√©lai de temporisation de s√©maphore a expir√©]
