2025-07-25 20:02:51,554 - outbound-caller - INFO - Outbound Agent script démarre, args: ['C:\\Users\\y.djemai\\pam-testdrive\\MARK_I\\backend_python\\agents\\outbound_agent.py', 'start']
2025-07-25 20:02:51,554 - outbound-caller - INFO - Python version: 3.12.3 (tags/v3.12.3:f6650f9, Apr  9 2024, 14:05:25) [MSC v.1938 64 bit (AMD64)]
2025-07-25 20:02:51,554 - outbound-caller - INFO - Répertoire courant: C:\Users\y.djemai\pam-testdrive\MARK_I\backend_python\agents
2025-07-25 20:02:51,554 - outbound-caller - INFO - Encodage par défaut: utf-8
2025-07-25 20:02:51,566 - outbound-caller - INFO - Locale système: ('fr_FR', 'UTF-8')
2025-07-25 20:02:51,573 - outbound-caller - INFO - PATIENT_NAME: Jayden
2025-07-25 20:02:51,573 - outbound-caller - INFO - APPOINTMENT_TIME: next Tuesday at 3pm
2025-07-25 20:02:51,573 - outbound-caller - INFO - LK_ROOM_NAME: agent-call-370
2025-07-25 20:02:51,573 - outbound-caller - INFO - LK_JOB_METADATA: {"firstName": "Valued Customer", "lastName": "", "dial_info": {"agent_id": 11, "call_direction": "outbound", "room_name": "agent-call-370", "supabase_call_id": 370, "telnyx_call_control_id": null, "default_pathway_id": "d5fc510b-7635-4715-9066-e522daa2336d", "user_id": "b55837c4-270f-4f1f-8023-7ab09ee5f44d", "phone_number": "+33661329235", "sip_trunk_id": "ST_6CYLZwTLMCe2", "agent_caller_id_number": "+33189311209"}, "system_prompt": null, "initial_greeting": null, "wait_for_greeting": false, "pam_tier": "core", "interruption_threshold": 100, "ai_models": {"vad": {"provider": "silero"}, "stt": {"provider": "deepgram", "language": "en", "model": "nova-2"}, "tts": {"provider": "cartesia", "model": "sonic-2", "voice_id": "f9836c6e-a0bd-460e-9d3c-f7299fa60f94"}, "llm": {"provider": "openai", "model": "gpt-4o-mini"}}}
2025-07-25 20:02:51,573 - outbound-caller - INFO - LIVEKIT_URL: wss://pamtestdrive-euxn3osq.livekit.cloud
2025-07-25 20:02:51,573 - outbound-caller - INFO - LIVEKIT_API_KEY présent: Oui
2025-07-25 20:02:52,498 - outbound-caller - INFO - \u2705 Supabase client imported successfully
2025-07-25 20:02:55,412 - outbound-caller - INFO - Pathway integration loaded successfully
2025-07-25 20:05:07,156 - outbound-caller - INFO - Starting entrypoint for supabase_call_id: 371
2025-07-25 20:05:08,834 - outbound-caller - INFO - \u2705 Connected to LiveKit room
--- Logging error ---
Traceback (most recent call last):
  File "C:\Program Files\Python312\Lib\logging\__init__.py", line 1163, in emit
    stream.write(msg + self.terminator)
  File "C:\Program Files\Python312\Lib\encodings\cp1252.py", line 19, in encode
    return codecs.charmap_encode(input,self.errors,encoding_table)[0]
           ^^^^^^^^^^^^^^^^^^^^^^^^^^^^^^^^^^^^^^^^^^^^^^^^^^^^^^^
UnicodeEncodeError: 'charmap' codec can't encode character '\u2705' in position 13: character maps to <undefined>
Call stack:
  File "C:\Program Files\Python312\Lib\threading.py", line 1030, in _bootstrap
    self._bootstrap_inner()
  File "C:\Program Files\Python312\Lib\threading.py", line 1073, in _bootstrap_inner
    self.run()
  File "C:\Program Files\Python312\Lib\threading.py", line 1010, in run
    self._target(*self._args, **self._kwargs)
  File "C:\Users\y.djemai\pam-testdrive\MARK_I\backend_python\agents\venv\Lib\site-packages\livekit\agents\ipc\job_proc_lazy_main.py", line 353, in thread_main
    client.run()
  File "C:\Users\y.djemai\pam-testdrive\MARK_I\backend_python\agents\venv\Lib\site-packages\livekit\agents\ipc\proc_client.py", line 86, in run
    loop.run_until_complete(self._task)
  File "C:\Program Files\Python312\Lib\asyncio\base_events.py", line 674, in run_until_complete
    self.run_forever()
  File "C:\Program Files\Python312\Lib\asyncio\windows_events.py", line 322, in run_forever
    super().run_forever()
  File "C:\Program Files\Python312\Lib\asyncio\base_events.py", line 641, in run_forever
    self._run_once()
  File "C:\Program Files\Python312\Lib\asyncio\base_events.py", line 1987, in _run_once
    handle._run()
  File "C:\Users\y.djemai\pam-testdrive\MARK_I\backend_python\agents\venv\Lib\site-packages\livekit\agents\utils\aio\debug.py", line 16, in instrumented
    val = _run(self)
  File "C:\Users\y.djemai\pam-testdrive\MARK_I\backend_python\agents\venv\Lib\site-packages\livekit\agents\utils\aio\debug.py", line 16, in instrumented
    val = _run(self)
  File "C:\Users\y.djemai\pam-testdrive\MARK_I\backend_python\agents\venv\Lib\site-packages\livekit\agents\utils\aio\debug.py", line 16, in instrumented
    val = _run(self)
  [Previous line repeated 11 more times]
  File "C:\Program Files\Python312\Lib\asyncio\events.py", line 88, in _run
    self._context.run(self._callback, *self._args)
  File "C:\Users\y.djemai\pam-testdrive\MARK_I\backend_python\agents\outbound_agent.py", line 604, in entrypoint
    logger.info("\u2705 Connected to LiveKit room")
Message: '\u2705 Connected to LiveKit room'
Arguments: ()
2025-07-25 20:05:08,846 - outbound-caller - ERROR - \u274c Error in auto-start pathway: auto_start_pathway_for_new_call() missing 1 required positional argument: 'agent_id'
--- Logging error ---
Traceback (most recent call last):
  File "C:\Users\y.djemai\pam-testdrive\MARK_I\backend_python\agents\outbound_agent.py", line 614, in entrypoint
    execution_id = await auto_start_pathway_for_new_call(call_id)
                         ^^^^^^^^^^^^^^^^^^^^^^^^^^^^^^^^^^^^^^^^
TypeError: auto_start_pathway_for_new_call() missing 1 required positional argument: 'agent_id'

During handling of the above exception, another exception occurred:

Traceback (most recent call last):
  File "C:\Program Files\Python312\Lib\logging\__init__.py", line 1163, in emit
    stream.write(msg + self.terminator)
  File "C:\Program Files\Python312\Lib\encodings\cp1252.py", line 19, in encode
    return codecs.charmap_encode(input,self.errors,encoding_table)[0]
           ^^^^^^^^^^^^^^^^^^^^^^^^^^^^^^^^^^^^^^^^^^^^^^^^^^^^^^^
UnicodeEncodeError: 'charmap' codec can't encode character '\u274c' in position 13: character maps to <undefined>
Call stack:
  File "C:\Program Files\Python312\Lib\threading.py", line 1030, in _bootstrap
    self._bootstrap_inner()
  File "C:\Program Files\Python312\Lib\threading.py", line 1073, in _bootstrap_inner
    self.run()
  File "C:\Program Files\Python312\Lib\threading.py", line 1010, in run
    self._target(*self._args, **self._kwargs)
  File "C:\Users\y.djemai\pam-testdrive\MARK_I\backend_python\agents\venv\Lib\site-packages\livekit\agents\ipc\job_proc_lazy_main.py", line 353, in thread_main
    client.run()
  File "C:\Users\y.djemai\pam-testdrive\MARK_I\backend_python\agents\venv\Lib\site-packages\livekit\agents\ipc\proc_client.py", line 86, in run
    loop.run_until_complete(self._task)
  File "C:\Program Files\Python312\Lib\asyncio\base_events.py", line 674, in run_until_complete
    self.run_forever()
  File "C:\Program Files\Python312\Lib\asyncio\windows_events.py", line 322, in run_forever
    super().run_forever()
  File "C:\Program Files\Python312\Lib\asyncio\base_events.py", line 641, in run_forever
    self._run_once()
  File "C:\Program Files\Python312\Lib\asyncio\base_events.py", line 1987, in _run_once
    handle._run()
  File "C:\Users\y.djemai\pam-testdrive\MARK_I\backend_python\agents\venv\Lib\site-packages\livekit\agents\utils\aio\debug.py", line 16, in instrumented
    val = _run(self)
  File "C:\Users\y.djemai\pam-testdrive\MARK_I\backend_python\agents\venv\Lib\site-packages\livekit\agents\utils\aio\debug.py", line 16, in instrumented
    val = _run(self)
  File "C:\Users\y.djemai\pam-testdrive\MARK_I\backend_python\agents\venv\Lib\site-packages\livekit\agents\utils\aio\debug.py", line 16, in instrumented
    val = _run(self)
  [Previous line repeated 11 more times]
  File "C:\Program Files\Python312\Lib\asyncio\events.py", line 88, in _run
    self._context.run(self._callback, *self._args)
  File "C:\Users\y.djemai\pam-testdrive\MARK_I\backend_python\agents\outbound_agent.py", line 621, in entrypoint
    logger.error(f"\u274c Error in auto-start pathway: {e}")
Message: "\u274c Error in auto-start pathway: auto_start_pathway_for_new_call() missing 1 required positional argument: 'agent_id'"
Arguments: ()
2025-07-25 20:05:08,849 - outbound-caller - INFO - Placeholder: Fetching pathway config for call_id 371 from backend...
2025-07-25 20:05:08,849 - outbound-caller - INFO - \U0001f50d Fetching call details for call_id: 371
--- Logging error ---
Traceback (most recent call last):
  File "C:\Program Files\Python312\Lib\logging\__init__.py", line 1163, in emit
    stream.write(msg + self.terminator)
  File "C:\Program Files\Python312\Lib\encodings\cp1252.py", line 19, in encode
    return codecs.charmap_encode(input,self.errors,encoding_table)[0]
           ^^^^^^^^^^^^^^^^^^^^^^^^^^^^^^^^^^^^^^^^^^^^^^^^^^^^^^^
UnicodeEncodeError: 'charmap' codec can't encode character '\U0001f50d' in position 13: character maps to <undefined>
Call stack:
  File "C:\Program Files\Python312\Lib\threading.py", line 1030, in _bootstrap
    self._bootstrap_inner()
  File "C:\Program Files\Python312\Lib\threading.py", line 1073, in _bootstrap_inner
    self.run()
  File "C:\Program Files\Python312\Lib\threading.py", line 1010, in run
    self._target(*self._args, **self._kwargs)
  File "C:\Users\y.djemai\pam-testdrive\MARK_I\backend_python\agents\venv\Lib\site-packages\livekit\agents\ipc\job_proc_lazy_main.py", line 353, in thread_main
    client.run()
  File "C:\Users\y.djemai\pam-testdrive\MARK_I\backend_python\agents\venv\Lib\site-packages\livekit\agents\ipc\proc_client.py", line 86, in run
    loop.run_until_complete(self._task)
  File "C:\Program Files\Python312\Lib\asyncio\base_events.py", line 674, in run_until_complete
    self.run_forever()
  File "C:\Program Files\Python312\Lib\asyncio\windows_events.py", line 322, in run_forever
    super().run_forever()
  File "C:\Program Files\Python312\Lib\asyncio\base_events.py", line 641, in run_forever
    self._run_once()
  File "C:\Program Files\Python312\Lib\asyncio\base_events.py", line 1987, in _run_once
    handle._run()
  File "C:\Users\y.djemai\pam-testdrive\MARK_I\backend_python\agents\venv\Lib\site-packages\livekit\agents\utils\aio\debug.py", line 16, in instrumented
    val = _run(self)
  File "C:\Users\y.djemai\pam-testdrive\MARK_I\backend_python\agents\venv\Lib\site-packages\livekit\agents\utils\aio\debug.py", line 16, in instrumented
    val = _run(self)
  File "C:\Users\y.djemai\pam-testdrive\MARK_I\backend_python\agents\venv\Lib\site-packages\livekit\agents\utils\aio\debug.py", line 16, in instrumented
    val = _run(self)
  [Previous line repeated 11 more times]
  File "C:\Program Files\Python312\Lib\asyncio\events.py", line 88, in _run
    self._context.run(self._callback, *self._args)
  File "C:\Users\y.djemai\pam-testdrive\MARK_I\backend_python\agents\outbound_agent.py", line 625, in entrypoint
    pathway_config, pathway_execution_id = await get_pathway_for_call(call_id)
  File "C:\Users\y.djemai\pam-testdrive\MARK_I\backend_python\agents\outbound_agent.py", line 734, in get_pathway_for_call
    call_details = await get_call_details_from_supabase(supabase_service_client, call_id)
  File "C:\Users\y.djemai\pam-testdrive\MARK_I\backend_python\agents\outbound_agent.py", line 759, in get_call_details_from_supabase
    logger.info(f"\U0001f50d Fetching call details for call_id: {call_id}")
Message: '\U0001f50d Fetching call details for call_id: 371'
Arguments: ()
2025-07-25 20:05:11,350 - outbound-caller - INFO - \U0001f4de Call 371 found with pathway_execution_id: None
--- Logging error ---
Traceback (most recent call last):
  File "C:\Program Files\Python312\Lib\logging\__init__.py", line 1163, in emit
    stream.write(msg + self.terminator)
  File "C:\Program Files\Python312\Lib\encodings\cp1252.py", line 19, in encode
    return codecs.charmap_encode(input,self.errors,encoding_table)[0]
           ^^^^^^^^^^^^^^^^^^^^^^^^^^^^^^^^^^^^^^^^^^^^^^^^^^^^^^^
UnicodeEncodeError: 'charmap' codec can't encode character '\U0001f4de' in position 13: character maps to <undefined>
Call stack:
  File "C:\Program Files\Python312\Lib\threading.py", line 1030, in _bootstrap
    self._bootstrap_inner()
  File "C:\Program Files\Python312\Lib\threading.py", line 1073, in _bootstrap_inner
    self.run()
  File "C:\Program Files\Python312\Lib\threading.py", line 1010, in run
    self._target(*self._args, **self._kwargs)
  File "C:\Users\y.djemai\pam-testdrive\MARK_I\backend_python\agents\venv\Lib\site-packages\livekit\agents\ipc\job_proc_lazy_main.py", line 353, in thread_main
    client.run()
  File "C:\Users\y.djemai\pam-testdrive\MARK_I\backend_python\agents\venv\Lib\site-packages\livekit\agents\ipc\proc_client.py", line 86, in run
    loop.run_until_complete(self._task)
  File "C:\Program Files\Python312\Lib\asyncio\base_events.py", line 674, in run_until_complete
    self.run_forever()
  File "C:\Program Files\Python312\Lib\asyncio\windows_events.py", line 322, in run_forever
    super().run_forever()
  File "C:\Program Files\Python312\Lib\asyncio\base_events.py", line 641, in run_forever
    self._run_once()
  File "C:\Program Files\Python312\Lib\asyncio\base_events.py", line 1987, in _run_once
    handle._run()
  File "C:\Users\y.djemai\pam-testdrive\MARK_I\backend_python\agents\venv\Lib\site-packages\livekit\agents\utils\aio\debug.py", line 16, in instrumented
    val = _run(self)
  File "C:\Users\y.djemai\pam-testdrive\MARK_I\backend_python\agents\venv\Lib\site-packages\livekit\agents\utils\aio\debug.py", line 16, in instrumented
    val = _run(self)
  File "C:\Users\y.djemai\pam-testdrive\MARK_I\backend_python\agents\venv\Lib\site-packages\livekit\agents\utils\aio\debug.py", line 16, in instrumented
    val = _run(self)
  [Previous line repeated 11 more times]
  File "C:\Program Files\Python312\Lib\asyncio\events.py", line 88, in _run
    self._context.run(self._callback, *self._args)
  File "C:\Users\y.djemai\pam-testdrive\MARK_I\backend_python\agents\outbound_agent.py", line 625, in entrypoint
    pathway_config, pathway_execution_id = await get_pathway_for_call(call_id)
  File "C:\Users\y.djemai\pam-testdrive\MARK_I\backend_python\agents\outbound_agent.py", line 734, in get_pathway_for_call
    call_details = await get_call_details_from_supabase(supabase_service_client, call_id)
  File "C:\Users\y.djemai\pam-testdrive\MARK_I\backend_python\agents\outbound_agent.py", line 773, in get_call_details_from_supabase
    logger.info(f"\U0001f4de Call {call_id} found with pathway_execution_id: {pathway_execution_id}")
Message: '\U0001f4de Call 371 found with pathway_execution_id: None'
Arguments: ()
2025-07-25 20:05:11,352 - outbound-caller - INFO - \u2139\ufe0f Call 371 has no pathway execution - returning basic call data
--- Logging error ---
Traceback (most recent call last):
  File "C:\Program Files\Python312\Lib\logging\__init__.py", line 1163, in emit
    stream.write(msg + self.terminator)
  File "C:\Program Files\Python312\Lib\encodings\cp1252.py", line 19, in encode
    return codecs.charmap_encode(input,self.errors,encoding_table)[0]
           ^^^^^^^^^^^^^^^^^^^^^^^^^^^^^^^^^^^^^^^^^^^^^^^^^^^^^^^
UnicodeEncodeError: 'charmap' codec can't encode characters in position 13-14: character maps to <undefined>
Call stack:
  File "C:\Program Files\Python312\Lib\threading.py", line 1030, in _bootstrap
    self._bootstrap_inner()
  File "C:\Program Files\Python312\Lib\threading.py", line 1073, in _bootstrap_inner
    self.run()
  File "C:\Program Files\Python312\Lib\threading.py", line 1010, in run
    self._target(*self._args, **self._kwargs)
  File "C:\Users\y.djemai\pam-testdrive\MARK_I\backend_python\agents\venv\Lib\site-packages\livekit\agents\ipc\job_proc_lazy_main.py", line 353, in thread_main
    client.run()
  File "C:\Users\y.djemai\pam-testdrive\MARK_I\backend_python\agents\venv\Lib\site-packages\livekit\agents\ipc\proc_client.py", line 86, in run
    loop.run_until_complete(self._task)
  File "C:\Program Files\Python312\Lib\asyncio\base_events.py", line 674, in run_until_complete
    self.run_forever()
  File "C:\Program Files\Python312\Lib\asyncio\windows_events.py", line 322, in run_forever
    super().run_forever()
  File "C:\Program Files\Python312\Lib\asyncio\base_events.py", line 641, in run_forever
    self._run_once()
  File "C:\Program Files\Python312\Lib\asyncio\base_events.py", line 1987, in _run_once
    handle._run()
  File "C:\Users\y.djemai\pam-testdrive\MARK_I\backend_python\agents\venv\Lib\site-packages\livekit\agents\utils\aio\debug.py", line 16, in instrumented
    val = _run(self)
  File "C:\Users\y.djemai\pam-testdrive\MARK_I\backend_python\agents\venv\Lib\site-packages\livekit\agents\utils\aio\debug.py", line 16, in instrumented
    val = _run(self)
  File "C:\Users\y.djemai\pam-testdrive\MARK_I\backend_python\agents\venv\Lib\site-packages\livekit\agents\utils\aio\debug.py", line 16, in instrumented
    val = _run(self)
  [Previous line repeated 11 more times]
  File "C:\Program Files\Python312\Lib\asyncio\events.py", line 88, in _run
    self._context.run(self._callback, *self._args)
  File "C:\Users\y.djemai\pam-testdrive\MARK_I\backend_python\agents\outbound_agent.py", line 625, in entrypoint
    pathway_config, pathway_execution_id = await get_pathway_for_call(call_id)
  File "C:\Users\y.djemai\pam-testdrive\MARK_I\backend_python\agents\outbound_agent.py", line 734, in get_pathway_for_call
    call_details = await get_call_details_from_supabase(supabase_service_client, call_id)
  File "C:\Users\y.djemai\pam-testdrive\MARK_I\backend_python\agents\outbound_agent.py", line 777, in get_call_details_from_supabase
    logger.info(f"\u2139\ufe0f Call {call_id} has no pathway execution - returning basic call data")
Message: '\u2139\ufe0f Call 371 has no pathway execution - returning basic call data'
Arguments: ()
2025-07-25 20:05:11,354 - outbound-caller - WARNING - No pathway config found for call_id 371 in Supabase.
2025-07-25 20:05:11,354 - outbound-caller - ERROR - No pathway configuration found for call_id 371. Aborting.
2025-07-25 20:05:11,354 - outbound-caller - ERROR - No pathway configuration found for call_id 371. Aborting.
2025-07-25 20:05:11,355 - livekit.agents - WARNING - Running <Task finished name='job_user_entrypoint' coro=<entrypoint() done, defined at C:\Users\y.djemai\pam-testdrive\MARK_I\backend_python\agents\outbound_agent.py:590> result=None> took too long: 2.52 seconds
2025-07-25 20:05:11,355 - livekit.agents - WARNING - Running <Task finished name='job_user_entrypoint' coro=<entrypoint() done, defined at C:\Users\y.djemai\pam-testdrive\MARK_I\backend_python\agents\outbound_agent.py:590> result=None> took too long: 2.52 seconds
2025-07-25 20:05:11,355 - livekit.agents - WARNING - Running <Task finished name='job_user_entrypoint' coro=<entrypoint() done, defined at C:\Users\y.djemai\pam-testdrive\MARK_I\backend_python\agents\outbound_agent.py:590> result=None> took too long: 2.52 seconds
2025-07-25 20:05:11,355 - livekit.agents - WARNING - Running <Task finished name='job_user_entrypoint' coro=<entrypoint() done, defined at C:\Users\y.djemai\pam-testdrive\MARK_I\backend_python\agents\outbound_agent.py:590> result=None> took too long: 2.52 seconds
2025-07-25 20:05:11,356 - livekit.agents - WARNING - Running <Task finished name='job_user_entrypoint' coro=<entrypoint() done, defined at C:\Users\y.djemai\pam-testdrive\MARK_I\backend_python\agents\outbound_agent.py:590> result=None> took too long: 2.53 seconds
2025-07-25 20:05:11,356 - livekit.agents - WARNING - Running <Task finished name='job_user_entrypoint' coro=<entrypoint() done, defined at C:\Users\y.djemai\pam-testdrive\MARK_I\backend_python\agents\outbound_agent.py:590> result=None> took too long: 2.53 seconds
2025-07-25 20:05:11,356 - livekit.agents - WARNING - Running <Task finished name='job_user_entrypoint' coro=<entrypoint() done, defined at C:\Users\y.djemai\pam-testdrive\MARK_I\backend_python\agents\outbound_agent.py:590> result=None> took too long: 2.53 seconds
2025-07-25 20:05:11,357 - livekit.agents - WARNING - Running <Task finished name='job_user_entrypoint' coro=<entrypoint() done, defined at C:\Users\y.djemai\pam-testdrive\MARK_I\backend_python\agents\outbound_agent.py:590> result=None> took too long: 2.53 seconds
2025-07-25 20:05:11,357 - livekit.agents - WARNING - Running <Task finished name='job_user_entrypoint' coro=<entrypoint() done, defined at C:\Users\y.djemai\pam-testdrive\MARK_I\backend_python\agents\outbound_agent.py:590> result=None> took too long: 2.53 seconds
2025-07-25 20:05:11,357 - livekit.agents - WARNING - Running <Task finished name='job_user_entrypoint' coro=<entrypoint() done, defined at C:\Users\y.djemai\pam-testdrive\MARK_I\backend_python\agents\outbound_agent.py:590> result=None> took too long: 2.53 seconds
2025-07-25 20:05:11,357 - livekit.agents - WARNING - Running <Task finished name='job_user_entrypoint' coro=<entrypoint() done, defined at C:\Users\y.djemai\pam-testdrive\MARK_I\backend_python\agents\outbound_agent.py:590> result=None> took too long: 2.53 seconds
2025-07-25 20:05:11,357 - livekit.agents - WARNING - Running <Task finished name='job_user_entrypoint' coro=<entrypoint() done, defined at C:\Users\y.djemai\pam-testdrive\MARK_I\backend_python\agents\outbound_agent.py:590> result=None> took too long: 2.53 seconds
2025-07-25 20:05:11,358 - livekit.agents - WARNING - Running <Task finished name='job_user_entrypoint' coro=<entrypoint() done, defined at C:\Users\y.djemai\pam-testdrive\MARK_I\backend_python\agents\outbound_agent.py:590> result=None> took too long: 2.53 seconds
2025-07-25 20:05:11,358 - livekit.agents - WARNING - Running <Task finished name='job_user_entrypoint' coro=<entrypoint() done, defined at C:\Users\y.djemai\pam-testdrive\MARK_I\backend_python\agents\outbound_agent.py:590> result=None> took too long: 2.53 seconds
2025-07-25 20:17:25,589 - livekit - ERROR - livekit::rtc_engine::rtc_session:787:livekit::rtc_engine::rtc_session - Subscriber pc state failed
2025-07-25 20:17:25,592 - livekit - WARNING - livekit::rtc_engine:453:livekit::rtc_engine - received session close: "pc_state failed" UnknownReason Resume
2025-07-25 20:17:25,594 - livekit - ERROR - livekit::rtc_engine:729:livekit::rtc_engine - resuming connection... attempt: 0
2025-07-25 20:17:25,602 - livekit - ERROR - livekit_api::signal_client::signal_stream:413:livekit_api::signal_client::signal_stream - unhandled websocket message Err(Io(Os { code: 10054, kind: ConnectionReset, message: "Une connexion existante a dÃ» Ãªtre fermÃ©e par lâhÃ´te distant." }))
2025-07-25 20:17:25,618 - livekit.agents - WARNING - failed to connect to livekit, retrying in 0s
Traceback (most recent call last):
  File "C:\Users\y.djemai\pam-testdrive\MARK_I\backend_python\agents\venv\Lib\site-packages\livekit\agents\worker.py", line 692, in _connection_task
    await self._run_ws(ws)
  File "C:\Users\y.djemai\pam-testdrive\MARK_I\backend_python\agents\venv\Lib\site-packages\livekit\agents\worker.py", line 773, in _run_ws
    await asyncio.gather(*tasks)
  File "C:\Users\y.djemai\pam-testdrive\MARK_I\backend_python\agents\venv\Lib\site-packages\livekit\agents\worker.py", line 728, in _send_task
    await ws.send_bytes(msg.SerializeToString())
  File "C:\Users\y.djemai\pam-testdrive\MARK_I\backend_python\agents\venv\Lib\site-packages\aiohttp\client_ws.py", line 252, in send_bytes
    await self._writer.send_frame(data, WSMsgType.BINARY, compress=compress)
  File "C:\Users\y.djemai\pam-testdrive\MARK_I\backend_python\agents\venv\Lib\site-packages\aiohttp\_websocket\writer.py", line 126, in send_frame
    raise ClientConnectionResetError("Cannot write to closing transport")
aiohttp.client_exceptions.ClientConnectionResetError: Cannot write to closing transport
2025-07-25 20:17:25,626 - livekit - WARNING - livekit::rtc_engine:453:livekit::rtc_engine - received session close: "signal client closed: \"stream closed\"" UnknownReason Resume
2025-07-25 20:17:25,692 - livekit.agents - WARNING - failed to connect to livekit, retrying in 2s
Traceback (most recent call last):
  File "C:\Users\y.djemai\pam-testdrive\MARK_I\backend_python\agents\venv\Lib\site-packages\aiohttp\connector.py", line 1532, in _create_direct_connection
    hosts = await self._resolve_host(host, port, traces=traces)
            ^^^^^^^^^^^^^^^^^^^^^^^^^^^^^^^^^^^^^^^^^^^^^^^^^^^
  File "C:\Users\y.djemai\pam-testdrive\MARK_I\backend_python\agents\venv\Lib\site-packages\aiohttp\connector.py", line 1148, in _resolve_host
    return await asyncio.shield(resolved_host_task)
           ^^^^^^^^^^^^^^^^^^^^^^^^^^^^^^^^^^^^^^^^
  File "C:\Users\y.djemai\pam-testdrive\MARK_I\backend_python\agents\venv\Lib\site-packages\aiohttp\connector.py", line 1179, in _resolve_host_with_throttle
    addrs = await self._resolver.resolve(host, port, family=self._family)
            ^^^^^^^^^^^^^^^^^^^^^^^^^^^^^^^^^^^^^^^^^^^^^^^^^^^^^^^^^^^^^
  File "C:\Users\y.djemai\pam-testdrive\MARK_I\backend_python\agents\venv\Lib\site-packages\aiohttp\resolver.py", line 40, in resolve
    infos = await self._loop.getaddrinfo(
            ^^^^^^^^^^^^^^^^^^^^^^^^^^^^^
  File "C:\Program Files\Python312\Lib\asyncio\base_events.py", line 901, in getaddrinfo
    return await self.run_in_executor(
           ^^^^^^^^^^^^^^^^^^^^^^^^^^^
  File "C:\Program Files\Python312\Lib\concurrent\futures\thread.py", line 58, in run
    result = self.fn(*self.args, **self.kwargs)
             ^^^^^^^^^^^^^^^^^^^^^^^^^^^^^^^^^^
  File "C:\Program Files\Python312\Lib\socket.py", line 963, in getaddrinfo
    for res in _socket.getaddrinfo(host, port, family, type, proto, flags):
               ^^^^^^^^^^^^^^^^^^^^^^^^^^^^^^^^^^^^^^^^^^^^^^^^^^^^^^^^^^^
socket.gaierror: [Errno 11001] getaddrinfo failed

The above exception was the direct cause of the following exception:

Traceback (most recent call last):
  File "C:\Users\y.djemai\pam-testdrive\MARK_I\backend_python\agents\venv\Lib\site-packages\livekit\agents\worker.py", line 653, in _connection_task
    ws = await self._http_session.ws_connect(
         ^^^^^^^^^^^^^^^^^^^^^^^^^^^^^^^^^^^^
  File "C:\Users\y.djemai\pam-testdrive\MARK_I\backend_python\agents\venv\Lib\site-packages\aiohttp\client.py", line 1067, in _ws_connect
    resp = await self.request(
           ^^^^^^^^^^^^^^^^^^^
  File "C:\Users\y.djemai\pam-testdrive\MARK_I\backend_python\agents\venv\Lib\site-packages\aiohttp\client.py", line 770, in _request
    resp = await handler(req)
           ^^^^^^^^^^^^^^^^^^
  File "C:\Users\y.djemai\pam-testdrive\MARK_I\backend_python\agents\venv\Lib\site-packages\aiohttp\client.py", line 725, in _connect_and_send_request
    conn = await self._connector.connect(
           ^^^^^^^^^^^^^^^^^^^^^^^^^^^^^^
  File "C:\Users\y.djemai\pam-testdrive\MARK_I\backend_python\agents\venv\Lib\site-packages\aiohttp\connector.py", line 642, in connect
    proto = await self._create_connection(req, traces, timeout)
            ^^^^^^^^^^^^^^^^^^^^^^^^^^^^^^^^^^^^^^^^^^^^^^^^^^^
  File "C:\Users\y.djemai\pam-testdrive\MARK_I\backend_python\agents\venv\Lib\site-packages\aiohttp\connector.py", line 1209, in _create_connection
    _, proto = await self._create_direct_connection(req, traces, timeout)
               ^^^^^^^^^^^^^^^^^^^^^^^^^^^^^^^^^^^^^^^^^^^^^^^^^^^^^^^^^^
  File "C:\Users\y.djemai\pam-testdrive\MARK_I\backend_python\agents\venv\Lib\site-packages\aiohttp\connector.py", line 1538, in _create_direct_connection
    raise ClientConnectorDNSError(req.connection_key, exc) from exc
aiohttp.client_exceptions.ClientConnectorDNSError: Cannot connect to host pamtestdrive-euxn3osq.livekit.cloud:443 ssl:default [getaddrinfo failed]
2025-07-25 20:17:26,313 - livekit - ERROR - livekit::rtc_engine:731:livekit::rtc_engine - resuming connection failed: signal failure: ws failure: IO error: HÃ´te inconnu. (os error 11001)
2025-07-25 20:17:26,314 - livekit - ERROR - livekit::rtc_engine:729:livekit::rtc_engine - resuming connection... attempt: 1
2025-07-25 20:17:26,314 - livekit - ERROR - livekit::rtc_engine:731:livekit::rtc_engine - resuming connection failed: signal failure: ws failure: IO error: HÃ´te inconnu. (os error 11001)
2025-07-25 20:17:26,315 - livekit - ERROR - livekit::rtc_engine:729:livekit::rtc_engine - resuming connection... attempt: 2
2025-07-25 20:17:26,315 - livekit - ERROR - livekit::rtc_engine:731:livekit::rtc_engine - resuming connection failed: signal failure: ws failure: IO error: HÃ´te inconnu. (os error 11001)
2025-07-25 20:17:26,316 - livekit - ERROR - livekit::rtc_engine:729:livekit::rtc_engine - resuming connection... attempt: 3
2025-07-25 20:17:26,317 - livekit - ERROR - livekit::rtc_engine:731:livekit::rtc_engine - resuming connection failed: signal failure: ws failure: IO error: HÃ´te inconnu. (os error 11001)
2025-07-25 20:17:26,318 - livekit - ERROR - livekit::rtc_engine:729:livekit::rtc_engine - resuming connection... attempt: 4
2025-07-25 20:17:26,318 - livekit - ERROR - livekit::rtc_engine:731:livekit::rtc_engine - resuming connection failed: signal failure: ws failure: IO error: HÃ´te inconnu. (os error 11001)
2025-07-25 20:17:26,319 - livekit - ERROR - livekit::rtc_engine:729:livekit::rtc_engine - resuming connection... attempt: 5
2025-07-25 20:17:26,319 - livekit - ERROR - livekit::rtc_engine:731:livekit::rtc_engine - resuming connection failed: signal failure: ws failure: IO error: HÃ´te inconnu. (os error 11001)
2025-07-25 20:17:26,320 - livekit - ERROR - livekit::rtc_engine:729:livekit::rtc_engine - resuming connection... attempt: 6
2025-07-25 20:17:26,320 - livekit - ERROR - livekit::rtc_engine:731:livekit::rtc_engine - resuming connection failed: signal failure: ws failure: IO error: HÃ´te inconnu. (os error 11001)
2025-07-25 20:17:26,321 - livekit - ERROR - livekit::rtc_engine:729:livekit::rtc_engine - resuming connection... attempt: 7
2025-07-25 20:17:26,321 - livekit - ERROR - livekit::rtc_engine:731:livekit::rtc_engine - resuming connection failed: signal failure: ws failure: IO error: HÃ´te inconnu. (os error 11001)
2025-07-25 20:17:26,321 - livekit - ERROR - livekit::rtc_engine:729:livekit::rtc_engine - resuming connection... attempt: 8
2025-07-25 20:17:26,322 - livekit - ERROR - livekit::rtc_engine:731:livekit::rtc_engine - resuming connection failed: signal failure: ws failure: IO error: HÃ´te inconnu. (os error 11001)
2025-07-25 20:17:26,322 - livekit - ERROR - livekit::rtc_engine:729:livekit::rtc_engine - resuming connection... attempt: 9
2025-07-25 20:17:26,324 - livekit - ERROR - livekit::rtc_engine:731:livekit::rtc_engine - resuming connection failed: signal failure: ws failure: IO error: HÃ´te inconnu. (os error 11001)
2025-07-25 20:17:26,324 - livekit - ERROR - livekit::rtc_engine:663:livekit::rtc_engine - failed to reconnect to the livekit room
2025-07-25 20:17:27,733 - livekit.agents - WARNING - failed to connect to livekit, retrying in 4s
Traceback (most recent call last):
  File "C:\Users\y.djemai\pam-testdrive\MARK_I\backend_python\agents\venv\Lib\site-packages\aiohttp\connector.py", line 1532, in _create_direct_connection
    hosts = await self._resolve_host(host, port, traces=traces)
            ^^^^^^^^^^^^^^^^^^^^^^^^^^^^^^^^^^^^^^^^^^^^^^^^^^^
  File "C:\Users\y.djemai\pam-testdrive\MARK_I\backend_python\agents\venv\Lib\site-packages\aiohttp\connector.py", line 1148, in _resolve_host
    return await asyncio.shield(resolved_host_task)
           ^^^^^^^^^^^^^^^^^^^^^^^^^^^^^^^^^^^^^^^^
  File "C:\Users\y.djemai\pam-testdrive\MARK_I\backend_python\agents\venv\Lib\site-packages\aiohttp\connector.py", line 1179, in _resolve_host_with_throttle
    addrs = await self._resolver.resolve(host, port, family=self._family)
            ^^^^^^^^^^^^^^^^^^^^^^^^^^^^^^^^^^^^^^^^^^^^^^^^^^^^^^^^^^^^^
  File "C:\Users\y.djemai\pam-testdrive\MARK_I\backend_python\agents\venv\Lib\site-packages\aiohttp\resolver.py", line 40, in resolve
    infos = await self._loop.getaddrinfo(
            ^^^^^^^^^^^^^^^^^^^^^^^^^^^^^
  File "C:\Program Files\Python312\Lib\asyncio\base_events.py", line 901, in getaddrinfo
    return await self.run_in_executor(
           ^^^^^^^^^^^^^^^^^^^^^^^^^^^
  File "C:\Program Files\Python312\Lib\concurrent\futures\thread.py", line 58, in run
    result = self.fn(*self.args, **self.kwargs)
             ^^^^^^^^^^^^^^^^^^^^^^^^^^^^^^^^^^
  File "C:\Program Files\Python312\Lib\socket.py", line 963, in getaddrinfo
    for res in _socket.getaddrinfo(host, port, family, type, proto, flags):
               ^^^^^^^^^^^^^^^^^^^^^^^^^^^^^^^^^^^^^^^^^^^^^^^^^^^^^^^^^^^
socket.gaierror: [Errno 11001] getaddrinfo failed

The above exception was the direct cause of the following exception:

Traceback (most recent call last):
  File "C:\Users\y.djemai\pam-testdrive\MARK_I\backend_python\agents\venv\Lib\site-packages\livekit\agents\worker.py", line 653, in _connection_task
    ws = await self._http_session.ws_connect(
         ^^^^^^^^^^^^^^^^^^^^^^^^^^^^^^^^^^^^
  File "C:\Users\y.djemai\pam-testdrive\MARK_I\backend_python\agents\venv\Lib\site-packages\aiohttp\client.py", line 1067, in _ws_connect
    resp = await self.request(
           ^^^^^^^^^^^^^^^^^^^
  File "C:\Users\y.djemai\pam-testdrive\MARK_I\backend_python\agents\venv\Lib\site-packages\aiohttp\client.py", line 770, in _request
    resp = await handler(req)
           ^^^^^^^^^^^^^^^^^^
  File "C:\Users\y.djemai\pam-testdrive\MARK_I\backend_python\agents\venv\Lib\site-packages\aiohttp\client.py", line 725, in _connect_and_send_request
    conn = await self._connector.connect(
           ^^^^^^^^^^^^^^^^^^^^^^^^^^^^^^
  File "C:\Users\y.djemai\pam-testdrive\MARK_I\backend_python\agents\venv\Lib\site-packages\aiohttp\connector.py", line 642, in connect
    proto = await self._create_connection(req, traces, timeout)
            ^^^^^^^^^^^^^^^^^^^^^^^^^^^^^^^^^^^^^^^^^^^^^^^^^^^
  File "C:\Users\y.djemai\pam-testdrive\MARK_I\backend_python\agents\venv\Lib\site-packages\aiohttp\connector.py", line 1209, in _create_connection
    _, proto = await self._create_direct_connection(req, traces, timeout)
               ^^^^^^^^^^^^^^^^^^^^^^^^^^^^^^^^^^^^^^^^^^^^^^^^^^^^^^^^^^
  File "C:\Users\y.djemai\pam-testdrive\MARK_I\backend_python\agents\venv\Lib\site-packages\aiohttp\connector.py", line 1538, in _create_direct_connection
    raise ClientConnectorDNSError(req.connection_key, exc) from exc
aiohttp.client_exceptions.ClientConnectorDNSError: Cannot connect to host pamtestdrive-euxn3osq.livekit.cloud:443 ssl:default [getaddrinfo failed]
2025-07-25 22:40:07,769 - livekit.agents - WARNING - failed to connect to livekit, retrying in 6s
Traceback (most recent call last):
  File "C:\Users\y.djemai\pam-testdrive\MARK_I\backend_python\agents\venv\Lib\site-packages\aiohttp\connector.py", line 1532, in _create_direct_connection
    hosts = await self._resolve_host(host, port, traces=traces)
            ^^^^^^^^^^^^^^^^^^^^^^^^^^^^^^^^^^^^^^^^^^^^^^^^^^^
  File "C:\Users\y.djemai\pam-testdrive\MARK_I\backend_python\agents\venv\Lib\site-packages\aiohttp\connector.py", line 1148, in _resolve_host
    return await asyncio.shield(resolved_host_task)
           ^^^^^^^^^^^^^^^^^^^^^^^^^^^^^^^^^^^^^^^^
  File "C:\Users\y.djemai\pam-testdrive\MARK_I\backend_python\agents\venv\Lib\site-packages\aiohttp\connector.py", line 1179, in _resolve_host_with_throttle
    addrs = await self._resolver.resolve(host, port, family=self._family)
            ^^^^^^^^^^^^^^^^^^^^^^^^^^^^^^^^^^^^^^^^^^^^^^^^^^^^^^^^^^^^^
  File "C:\Users\y.djemai\pam-testdrive\MARK_I\backend_python\agents\venv\Lib\site-packages\aiohttp\resolver.py", line 40, in resolve
    infos = await self._loop.getaddrinfo(
            ^^^^^^^^^^^^^^^^^^^^^^^^^^^^^
  File "C:\Program Files\Python312\Lib\asyncio\base_events.py", line 901, in getaddrinfo
    return await self.run_in_executor(
           ^^^^^^^^^^^^^^^^^^^^^^^^^^^
  File "C:\Program Files\Python312\Lib\concurrent\futures\thread.py", line 58, in run
    result = self.fn(*self.args, **self.kwargs)
             ^^^^^^^^^^^^^^^^^^^^^^^^^^^^^^^^^^
  File "C:\Program Files\Python312\Lib\socket.py", line 963, in getaddrinfo
    for res in _socket.getaddrinfo(host, port, family, type, proto, flags):
               ^^^^^^^^^^^^^^^^^^^^^^^^^^^^^^^^^^^^^^^^^^^^^^^^^^^^^^^^^^^
socket.gaierror: [Errno 11001] getaddrinfo failed

The above exception was the direct cause of the following exception:

Traceback (most recent call last):
  File "C:\Users\y.djemai\pam-testdrive\MARK_I\backend_python\agents\venv\Lib\site-packages\livekit\agents\worker.py", line 653, in _connection_task
    ws = await self._http_session.ws_connect(
         ^^^^^^^^^^^^^^^^^^^^^^^^^^^^^^^^^^^^
  File "C:\Users\y.djemai\pam-testdrive\MARK_I\backend_python\agents\venv\Lib\site-packages\aiohttp\client.py", line 1067, in _ws_connect
    resp = await self.request(
           ^^^^^^^^^^^^^^^^^^^
  File "C:\Users\y.djemai\pam-testdrive\MARK_I\backend_python\agents\venv\Lib\site-packages\aiohttp\client.py", line 770, in _request
    resp = await handler(req)
           ^^^^^^^^^^^^^^^^^^
  File "C:\Users\y.djemai\pam-testdrive\MARK_I\backend_python\agents\venv\Lib\site-packages\aiohttp\client.py", line 725, in _connect_and_send_request
    conn = await self._connector.connect(
           ^^^^^^^^^^^^^^^^^^^^^^^^^^^^^^
  File "C:\Users\y.djemai\pam-testdrive\MARK_I\backend_python\agents\venv\Lib\site-packages\aiohttp\connector.py", line 642, in connect
    proto = await self._create_connection(req, traces, timeout)
            ^^^^^^^^^^^^^^^^^^^^^^^^^^^^^^^^^^^^^^^^^^^^^^^^^^^
  File "C:\Users\y.djemai\pam-testdrive\MARK_I\backend_python\agents\venv\Lib\site-packages\aiohttp\connector.py", line 1209, in _create_connection
    _, proto = await self._create_direct_connection(req, traces, timeout)
               ^^^^^^^^^^^^^^^^^^^^^^^^^^^^^^^^^^^^^^^^^^^^^^^^^^^^^^^^^^
  File "C:\Users\y.djemai\pam-testdrive\MARK_I\backend_python\agents\venv\Lib\site-packages\aiohttp\connector.py", line 1538, in _create_direct_connection
    raise ClientConnectorDNSError(req.connection_key, exc) from exc
aiohttp.client_exceptions.ClientConnectorDNSError: Cannot connect to host pamtestdrive-euxn3osq.livekit.cloud:443 ssl:default [getaddrinfo failed]
2025-07-25 22:40:13,782 - livekit.agents - WARNING - failed to connect to livekit, retrying in 8s
Traceback (most recent call last):
  File "C:\Users\y.djemai\pam-testdrive\MARK_I\backend_python\agents\venv\Lib\site-packages\aiohttp\connector.py", line 1532, in _create_direct_connection
    hosts = await self._resolve_host(host, port, traces=traces)
            ^^^^^^^^^^^^^^^^^^^^^^^^^^^^^^^^^^^^^^^^^^^^^^^^^^^
  File "C:\Users\y.djemai\pam-testdrive\MARK_I\backend_python\agents\venv\Lib\site-packages\aiohttp\connector.py", line 1148, in _resolve_host
    return await asyncio.shield(resolved_host_task)
           ^^^^^^^^^^^^^^^^^^^^^^^^^^^^^^^^^^^^^^^^
  File "C:\Users\y.djemai\pam-testdrive\MARK_I\backend_python\agents\venv\Lib\site-packages\aiohttp\connector.py", line 1179, in _resolve_host_with_throttle
    addrs = await self._resolver.resolve(host, port, family=self._family)
            ^^^^^^^^^^^^^^^^^^^^^^^^^^^^^^^^^^^^^^^^^^^^^^^^^^^^^^^^^^^^^
  File "C:\Users\y.djemai\pam-testdrive\MARK_I\backend_python\agents\venv\Lib\site-packages\aiohttp\resolver.py", line 40, in resolve
    infos = await self._loop.getaddrinfo(
            ^^^^^^^^^^^^^^^^^^^^^^^^^^^^^
  File "C:\Program Files\Python312\Lib\asyncio\base_events.py", line 901, in getaddrinfo
    return await self.run_in_executor(
           ^^^^^^^^^^^^^^^^^^^^^^^^^^^
  File "C:\Program Files\Python312\Lib\concurrent\futures\thread.py", line 58, in run
    result = self.fn(*self.args, **self.kwargs)
             ^^^^^^^^^^^^^^^^^^^^^^^^^^^^^^^^^^
  File "C:\Program Files\Python312\Lib\socket.py", line 963, in getaddrinfo
    for res in _socket.getaddrinfo(host, port, family, type, proto, flags):
               ^^^^^^^^^^^^^^^^^^^^^^^^^^^^^^^^^^^^^^^^^^^^^^^^^^^^^^^^^^^
socket.gaierror: [Errno 11001] getaddrinfo failed

The above exception was the direct cause of the following exception:

Traceback (most recent call last):
  File "C:\Users\y.djemai\pam-testdrive\MARK_I\backend_python\agents\venv\Lib\site-packages\livekit\agents\worker.py", line 653, in _connection_task
    ws = await self._http_session.ws_connect(
         ^^^^^^^^^^^^^^^^^^^^^^^^^^^^^^^^^^^^
  File "C:\Users\y.djemai\pam-testdrive\MARK_I\backend_python\agents\venv\Lib\site-packages\aiohttp\client.py", line 1067, in _ws_connect
    resp = await self.request(
           ^^^^^^^^^^^^^^^^^^^
  File "C:\Users\y.djemai\pam-testdrive\MARK_I\backend_python\agents\venv\Lib\site-packages\aiohttp\client.py", line 770, in _request
    resp = await handler(req)
           ^^^^^^^^^^^^^^^^^^
  File "C:\Users\y.djemai\pam-testdrive\MARK_I\backend_python\agents\venv\Lib\site-packages\aiohttp\client.py", line 725, in _connect_and_send_request
    conn = await self._connector.connect(
           ^^^^^^^^^^^^^^^^^^^^^^^^^^^^^^
  File "C:\Users\y.djemai\pam-testdrive\MARK_I\backend_python\agents\venv\Lib\site-packages\aiohttp\connector.py", line 642, in connect
    proto = await self._create_connection(req, traces, timeout)
            ^^^^^^^^^^^^^^^^^^^^^^^^^^^^^^^^^^^^^^^^^^^^^^^^^^^
  File "C:\Users\y.djemai\pam-testdrive\MARK_I\backend_python\agents\venv\Lib\site-packages\aiohttp\connector.py", line 1209, in _create_connection
    _, proto = await self._create_direct_connection(req, traces, timeout)
               ^^^^^^^^^^^^^^^^^^^^^^^^^^^^^^^^^^^^^^^^^^^^^^^^^^^^^^^^^^
  File "C:\Users\y.djemai\pam-testdrive\MARK_I\backend_python\agents\venv\Lib\site-packages\aiohttp\connector.py", line 1538, in _create_direct_connection
    raise ClientConnectorDNSError(req.connection_key, exc) from exc
aiohttp.client_exceptions.ClientConnectorDNSError: Cannot connect to host pamtestdrive-euxn3osq.livekit.cloud:443 ssl:default [getaddrinfo failed]
2025-07-25 22:40:21,784 - livekit.agents - WARNING - failed to connect to livekit, retrying in 10s
Traceback (most recent call last):
  File "C:\Users\y.djemai\pam-testdrive\MARK_I\backend_python\agents\venv\Lib\site-packages\aiohttp\connector.py", line 1532, in _create_direct_connection
    hosts = await self._resolve_host(host, port, traces=traces)
            ^^^^^^^^^^^^^^^^^^^^^^^^^^^^^^^^^^^^^^^^^^^^^^^^^^^
  File "C:\Users\y.djemai\pam-testdrive\MARK_I\backend_python\agents\venv\Lib\site-packages\aiohttp\connector.py", line 1148, in _resolve_host
    return await asyncio.shield(resolved_host_task)
           ^^^^^^^^^^^^^^^^^^^^^^^^^^^^^^^^^^^^^^^^
  File "C:\Users\y.djemai\pam-testdrive\MARK_I\backend_python\agents\venv\Lib\site-packages\aiohttp\connector.py", line 1179, in _resolve_host_with_throttle
    addrs = await self._resolver.resolve(host, port, family=self._family)
            ^^^^^^^^^^^^^^^^^^^^^^^^^^^^^^^^^^^^^^^^^^^^^^^^^^^^^^^^^^^^^
  File "C:\Users\y.djemai\pam-testdrive\MARK_I\backend_python\agents\venv\Lib\site-packages\aiohttp\resolver.py", line 40, in resolve
    infos = await self._loop.getaddrinfo(
            ^^^^^^^^^^^^^^^^^^^^^^^^^^^^^
  File "C:\Program Files\Python312\Lib\asyncio\base_events.py", line 901, in getaddrinfo
    return await self.run_in_executor(
           ^^^^^^^^^^^^^^^^^^^^^^^^^^^
  File "C:\Program Files\Python312\Lib\concurrent\futures\thread.py", line 58, in run
    result = self.fn(*self.args, **self.kwargs)
             ^^^^^^^^^^^^^^^^^^^^^^^^^^^^^^^^^^
  File "C:\Program Files\Python312\Lib\socket.py", line 963, in getaddrinfo
    for res in _socket.getaddrinfo(host, port, family, type, proto, flags):
               ^^^^^^^^^^^^^^^^^^^^^^^^^^^^^^^^^^^^^^^^^^^^^^^^^^^^^^^^^^^
socket.gaierror: [Errno 11001] getaddrinfo failed

The above exception was the direct cause of the following exception:

Traceback (most recent call last):
  File "C:\Users\y.djemai\pam-testdrive\MARK_I\backend_python\agents\venv\Lib\site-packages\livekit\agents\worker.py", line 653, in _connection_task
    ws = await self._http_session.ws_connect(
         ^^^^^^^^^^^^^^^^^^^^^^^^^^^^^^^^^^^^
  File "C:\Users\y.djemai\pam-testdrive\MARK_I\backend_python\agents\venv\Lib\site-packages\aiohttp\client.py", line 1067, in _ws_connect
    resp = await self.request(
           ^^^^^^^^^^^^^^^^^^^
  File "C:\Users\y.djemai\pam-testdrive\MARK_I\backend_python\agents\venv\Lib\site-packages\aiohttp\client.py", line 770, in _request
    resp = await handler(req)
           ^^^^^^^^^^^^^^^^^^
  File "C:\Users\y.djemai\pam-testdrive\MARK_I\backend_python\agents\venv\Lib\site-packages\aiohttp\client.py", line 725, in _connect_and_send_request
    conn = await self._connector.connect(
           ^^^^^^^^^^^^^^^^^^^^^^^^^^^^^^
  File "C:\Users\y.djemai\pam-testdrive\MARK_I\backend_python\agents\venv\Lib\site-packages\aiohttp\connector.py", line 642, in connect
    proto = await self._create_connection(req, traces, timeout)
            ^^^^^^^^^^^^^^^^^^^^^^^^^^^^^^^^^^^^^^^^^^^^^^^^^^^
  File "C:\Users\y.djemai\pam-testdrive\MARK_I\backend_python\agents\venv\Lib\site-packages\aiohttp\connector.py", line 1209, in _create_connection
    _, proto = await self._create_direct_connection(req, traces, timeout)
               ^^^^^^^^^^^^^^^^^^^^^^^^^^^^^^^^^^^^^^^^^^^^^^^^^^^^^^^^^^
  File "C:\Users\y.djemai\pam-testdrive\MARK_I\backend_python\agents\venv\Lib\site-packages\aiohttp\connector.py", line 1538, in _create_direct_connection
    raise ClientConnectorDNSError(req.connection_key, exc) from exc
aiohttp.client_exceptions.ClientConnectorDNSError: Cannot connect to host pamtestdrive-euxn3osq.livekit.cloud:443 ssl:default [getaddrinfo failed]
2025-07-27 22:02:48,605 - livekit.agents - WARNING - failed to connect to livekit, retrying in 10s
Traceback (most recent call last):
  File "C:\Users\y.djemai\pam-testdrive\MARK_I\backend_python\agents\venv\Lib\site-packages\aiohttp\connector.py", line 1532, in _create_direct_connection
    hosts = await self._resolve_host(host, port, traces=traces)
            ^^^^^^^^^^^^^^^^^^^^^^^^^^^^^^^^^^^^^^^^^^^^^^^^^^^
  File "C:\Users\y.djemai\pam-testdrive\MARK_I\backend_python\agents\venv\Lib\site-packages\aiohttp\connector.py", line 1148, in _resolve_host
    return await asyncio.shield(resolved_host_task)
           ^^^^^^^^^^^^^^^^^^^^^^^^^^^^^^^^^^^^^^^^
  File "C:\Users\y.djemai\pam-testdrive\MARK_I\backend_python\agents\venv\Lib\site-packages\aiohttp\connector.py", line 1179, in _resolve_host_with_throttle
    addrs = await self._resolver.resolve(host, port, family=self._family)
            ^^^^^^^^^^^^^^^^^^^^^^^^^^^^^^^^^^^^^^^^^^^^^^^^^^^^^^^^^^^^^
  File "C:\Users\y.djemai\pam-testdrive\MARK_I\backend_python\agents\venv\Lib\site-packages\aiohttp\resolver.py", line 40, in resolve
    infos = await self._loop.getaddrinfo(
            ^^^^^^^^^^^^^^^^^^^^^^^^^^^^^
  File "C:\Program Files\Python312\Lib\asyncio\base_events.py", line 901, in getaddrinfo
    return await self.run_in_executor(
           ^^^^^^^^^^^^^^^^^^^^^^^^^^^
  File "C:\Program Files\Python312\Lib\concurrent\futures\thread.py", line 58, in run
    result = self.fn(*self.args, **self.kwargs)
             ^^^^^^^^^^^^^^^^^^^^^^^^^^^^^^^^^^
  File "C:\Program Files\Python312\Lib\socket.py", line 963, in getaddrinfo
    for res in _socket.getaddrinfo(host, port, family, type, proto, flags):
               ^^^^^^^^^^^^^^^^^^^^^^^^^^^^^^^^^^^^^^^^^^^^^^^^^^^^^^^^^^^
socket.gaierror: [Errno 11001] getaddrinfo failed

The above exception was the direct cause of the following exception:

Traceback (most recent call last):
  File "C:\Users\y.djemai\pam-testdrive\MARK_I\backend_python\agents\venv\Lib\site-packages\livekit\agents\worker.py", line 653, in _connection_task
    ws = await self._http_session.ws_connect(
         ^^^^^^^^^^^^^^^^^^^^^^^^^^^^^^^^^^^^
  File "C:\Users\y.djemai\pam-testdrive\MARK_I\backend_python\agents\venv\Lib\site-packages\aiohttp\client.py", line 1067, in _ws_connect
    resp = await self.request(
           ^^^^^^^^^^^^^^^^^^^
  File "C:\Users\y.djemai\pam-testdrive\MARK_I\backend_python\agents\venv\Lib\site-packages\aiohttp\client.py", line 770, in _request
    resp = await handler(req)
           ^^^^^^^^^^^^^^^^^^
  File "C:\Users\y.djemai\pam-testdrive\MARK_I\backend_python\agents\venv\Lib\site-packages\aiohttp\client.py", line 725, in _connect_and_send_request
    conn = await self._connector.connect(
           ^^^^^^^^^^^^^^^^^^^^^^^^^^^^^^
  File "C:\Users\y.djemai\pam-testdrive\MARK_I\backend_python\agents\venv\Lib\site-packages\aiohttp\connector.py", line 642, in connect
    proto = await self._create_connection(req, traces, timeout)
            ^^^^^^^^^^^^^^^^^^^^^^^^^^^^^^^^^^^^^^^^^^^^^^^^^^^
  File "C:\Users\y.djemai\pam-testdrive\MARK_I\backend_python\agents\venv\Lib\site-packages\aiohttp\connector.py", line 1209, in _create_connection
    _, proto = await self._create_direct_connection(req, traces, timeout)
               ^^^^^^^^^^^^^^^^^^^^^^^^^^^^^^^^^^^^^^^^^^^^^^^^^^^^^^^^^^
  File "C:\Users\y.djemai\pam-testdrive\MARK_I\backend_python\agents\venv\Lib\site-packages\aiohttp\connector.py", line 1538, in _create_direct_connection
    raise ClientConnectorDNSError(req.connection_key, exc) from exc
aiohttp.client_exceptions.ClientConnectorDNSError: Cannot connect to host pamtestdrive-euxn3osq.livekit.cloud:443 ssl:default [getaddrinfo failed]
2025-07-27 22:03:11,641 - livekit.agents - WARNING - failed to connect to livekit, retrying in 10s
Traceback (most recent call last):
  File "C:\Users\y.djemai\pam-testdrive\MARK_I\backend_python\agents\venv\Lib\site-packages\aiohttp\connector.py", line 1532, in _create_direct_connection
    hosts = await self._resolve_host(host, port, traces=traces)
            ^^^^^^^^^^^^^^^^^^^^^^^^^^^^^^^^^^^^^^^^^^^^^^^^^^^
  File "C:\Users\y.djemai\pam-testdrive\MARK_I\backend_python\agents\venv\Lib\site-packages\aiohttp\connector.py", line 1148, in _resolve_host
    return await asyncio.shield(resolved_host_task)
           ^^^^^^^^^^^^^^^^^^^^^^^^^^^^^^^^^^^^^^^^
  File "C:\Users\y.djemai\pam-testdrive\MARK_I\backend_python\agents\venv\Lib\site-packages\aiohttp\connector.py", line 1179, in _resolve_host_with_throttle
    addrs = await self._resolver.resolve(host, port, family=self._family)
            ^^^^^^^^^^^^^^^^^^^^^^^^^^^^^^^^^^^^^^^^^^^^^^^^^^^^^^^^^^^^^
  File "C:\Users\y.djemai\pam-testdrive\MARK_I\backend_python\agents\venv\Lib\site-packages\aiohttp\resolver.py", line 40, in resolve
    infos = await self._loop.getaddrinfo(
            ^^^^^^^^^^^^^^^^^^^^^^^^^^^^^
  File "C:\Program Files\Python312\Lib\asyncio\base_events.py", line 901, in getaddrinfo
    return await self.run_in_executor(
           ^^^^^^^^^^^^^^^^^^^^^^^^^^^
  File "C:\Program Files\Python312\Lib\concurrent\futures\thread.py", line 58, in run
    result = self.fn(*self.args, **self.kwargs)
             ^^^^^^^^^^^^^^^^^^^^^^^^^^^^^^^^^^
  File "C:\Program Files\Python312\Lib\socket.py", line 963, in getaddrinfo
    for res in _socket.getaddrinfo(host, port, family, type, proto, flags):
               ^^^^^^^^^^^^^^^^^^^^^^^^^^^^^^^^^^^^^^^^^^^^^^^^^^^^^^^^^^^
socket.gaierror: [Errno 11001] getaddrinfo failed

The above exception was the direct cause of the following exception:

Traceback (most recent call last):
  File "C:\Users\y.djemai\pam-testdrive\MARK_I\backend_python\agents\venv\Lib\site-packages\livekit\agents\worker.py", line 653, in _connection_task
    ws = await self._http_session.ws_connect(
         ^^^^^^^^^^^^^^^^^^^^^^^^^^^^^^^^^^^^
  File "C:\Users\y.djemai\pam-testdrive\MARK_I\backend_python\agents\venv\Lib\site-packages\aiohttp\client.py", line 1067, in _ws_connect
    resp = await self.request(
           ^^^^^^^^^^^^^^^^^^^
  File "C:\Users\y.djemai\pam-testdrive\MARK_I\backend_python\agents\venv\Lib\site-packages\aiohttp\client.py", line 770, in _request
    resp = await handler(req)
           ^^^^^^^^^^^^^^^^^^
  File "C:\Users\y.djemai\pam-testdrive\MARK_I\backend_python\agents\venv\Lib\site-packages\aiohttp\client.py", line 725, in _connect_and_send_request
    conn = await self._connector.connect(
           ^^^^^^^^^^^^^^^^^^^^^^^^^^^^^^
  File "C:\Users\y.djemai\pam-testdrive\MARK_I\backend_python\agents\venv\Lib\site-packages\aiohttp\connector.py", line 642, in connect
    proto = await self._create_connection(req, traces, timeout)
            ^^^^^^^^^^^^^^^^^^^^^^^^^^^^^^^^^^^^^^^^^^^^^^^^^^^
  File "C:\Users\y.djemai\pam-testdrive\MARK_I\backend_python\agents\venv\Lib\site-packages\aiohttp\connector.py", line 1209, in _create_connection
    _, proto = await self._create_direct_connection(req, traces, timeout)
               ^^^^^^^^^^^^^^^^^^^^^^^^^^^^^^^^^^^^^^^^^^^^^^^^^^^^^^^^^^
  File "C:\Users\y.djemai\pam-testdrive\MARK_I\backend_python\agents\venv\Lib\site-packages\aiohttp\connector.py", line 1538, in _create_direct_connection
    raise ClientConnectorDNSError(req.connection_key, exc) from exc
aiohttp.client_exceptions.ClientConnectorDNSError: Cannot connect to host pamtestdrive-euxn3osq.livekit.cloud:443 ssl:default [getaddrinfo failed]
